Workbook

Sheet CARTEIRA
C2: 呪術廻戦 | L2: GUILDA DE FEITICEIROS | AH2: ="Nº M-"&SUBSTITUTE(DADOS!$B$1,".","")&"-"&IF(FICHA!D3="","····",UPPER(LEFT(FICHA!D3,4)))
L3: carteira de registro · documento oficial | AH3: ="emitida "&TEXT(TODAY(),"dd.mm.yyyy")
O8: PORTADOR
O17: CAMINHO | Z17: TRILHA | AK17: ORIGEM
O18: =IF(FICHA!D11="","—",FICHA!D11) | Z18: =IF(FICHA!N11="","—",FICHA!N11) | AK18: =IF(FICHA!X11="","—",FICHA!X11)
O21: NÍVEL | Z21: MESA DE ORIGEM | AK21: REGISTRADO POR
O22: =IF(FICHA!AH11="","—",FICHA!AH11)
O26: TÉCNICA DECLARADA
O32: uma linha sobre o que a técnica é. o resto está na aba TÉCNICA.
D33: cole a sua foto por cima desta moldura
AK34: SELO REGISTRADO
C38: esta carteira acompanha o portador entre mesas. a ficha completa está nas páginas seguintes. | AH38: =IF(FICHA!D11="","—",UPPER(LEFT(FICHA!D11,3))&"-"&TEXT(FICHA!AH11,"00"))

Sheet FICHA
D2: GUILDA · FICHA DE REGISTRO | AH2: CATÁLOGO
D3: =IF(CARTEIRA!O9="","",CARTEIRA!O9) | AH3: =IF(DADOS!$B$1=DADOS!$D$1,"v"&DADOS!$B$1&" · em dia","⚠ v"&DADOS!$B$1&" · a atual é a v"&DADOS!$D$1)
D5: o nome do portador vai na CARTEIRA e cai aqui sozinho
A8: PROJETO M | D8: 01 | G8: QUEM É
D10: CAMINHO | N10: TRILHA | X10: ORIGEM | AH10: NÍVEL | AN10: XP · NA MÃO
AH11: 2 | AN11: 0
D14: 02 | G14: O CORPO
D16: FOR | L16: DES | T16: CON | AB16: INT | AJ16: ESS
D17: 0 | L17: 0 | T17: 0 | AB17: 0 | AJ17: 0
D19: Força | L19: Destreza | T19: Constituição | AB19: Inteligência | AJ19: Essência
D22: VIDA | AF22: TEMP | AM22: ±
D23: 0 | J23: =IF($D$11="","",(VLOOKUP($D$11,DADOS!$N$5:$U$9,3,FALSE)+$T$17)+(VLOOKUP($D$11,DADOS!$N$5:$U$9,4,FALSE)+$T$17)*($AH$11-1)) | P23: =IFERROR(SPARKLINE($D$23,{"charttype","bar";"max",$J$23;"color1",IF(N($J$23)=0,"#E8DCD4",IF($D$23/$J$23<=0.25,"#C2334D",IF($D$23/$J$23<=0.5,"#D89B3A","#E8DCD4")))}),"") | AF23: 0
D26: ENERGIA | AF26: TEMP | AM26: ±
D27: 0 | J27: =IF($D$11="","",VLOOKUP($D$11,DADOS!$N$5:$U$9,5,FALSE)*$AH$11) | P27: =IFERROR(SPARKLINE($D$27,{"charttype","bar";"max",$J$27;"color1",IF(N($J$27)=0,"#E8DCD4",IF($D$27/$J$27<=0.25,"#C2334D",IF($D$27/$J$27<=0.5,"#D89B3A","#E8DCD4")))}),"") | AF27: 0
A30: FICHA DE REGISTRO | D30: INTEGRIDADE | AF30: TEMP | AM30: ±
D31: 0 | J31: =20+($AJ$17+5)*($AH$11-1) | P31: =IFERROR(SPARKLINE($D$31,{"charttype","bar";"max",$J$31;"color1",IF(N($J$31)=0,"#E8DCD4",IF($D$31/$J$31<=0.25,"#C2334D",IF($D$31/$J$31<=0.5,"#D89B3A","#E8DCD4")))}),"") | AF31: 0
D34: =IF($D$31=""," ",IF($D$31<=0,"estágio 4 · você não é mais você",IF($D$31<=$J$31/4,"estágio 3 · desvantagem em ataques e TRs",IF($D$31<=$J$31/2,"estágio 2 · metade do deslocamento, +1 PE por Classe",IF($D$31<=$J$31*3/4,"estágio 1 · desvantagem em perícias","alma inteira")))))
D37: 03 | G37: O QUE CAI SOZINHO
D39: DEFESA | O39: PROTEÇÃO | Z39: EQUIPAMENTO | AK39: INICIATIVA
D40: =10+$L$17+$O$40 | O40: =IF($Z$40="",FLOOR((1+COUNTIF(DADOS!$W$5:$W$11,"<="&$AH$11))/3,1)+1,$Z$40) | AK40: ="d20 + "&$L$17
D43: CD DE FEITIÇO | O43: CONJURAÇÃO | Z43: CORPO A CORPO | AK43: À DISTÂNCIA
D44: =10+2+(1+COUNTIF(DADOS!$X$5:$X$7,"<="&$AH$11)) | O44: ="d20 + "&(2+(1+COUNTIF(DADOS!$X$5:$X$7,"<="&$AH$11))) | Z44: ="d20 + "&$D$17 | AK44: ="d20 + "&$L$17
D47: MAESTRIA | O47: DESLOCAMENTO | Z47: BLOQUEAR
D48: =(1+COUNTIF(DADOS!$X$5:$X$7,"<="&$AH$11)) | O48: 9 m | Z48: ="2d10 + "&($D$40-11)
D51: 04 | G51: PROGRESSÃO · você só digita o nível
D53: ESPAÇOS DE FEITIÇO | O53: REFINO DE GRAÇA | Z53: CLASSE MÁXIMA | AK53: CLASSE 0 GRÁTIS
D54: =2+INT($AH$11/2)+COUNTIF(DADOS!$W$5:$W$11,"<="&$AH$11) | O54: =(1+COUNTIF(DADOS!$W$5:$W$11,"<="&$AH$11)) | Z54: =COUNTIF(DADOS!$Y$5:$Y$11,"<="&$AH$11) | AK54: =2+COUNTIF(DADOS!$Z$5:$Z$7,"<="&$AH$11)
D57: 05 | G57: PERÍCIAS · marque as 8 ou 9 treinadas
D59: T | E59: E | R59: T | S59: E
F60: Atletismo | M60: For | O60: =$D$17+IF($E$60=TRUE,(1+COUNTIF(DADOS!$X$5:$X$7,"<="&$AH$11))+INT((1+COUNTIF(DADOS!$X$5:$X$7,"<="&$AH$11))/2),IF($D$60=TRUE,(1+COUNTIF(DADOS!$X$5:$X$7,"<="&$AH$11)),0)) | T60: Sobrevivência | AA60: Int | AC60: =$AB$17+IF($S$60=TRUE,(1+COUNTIF(DADOS!$X$5:$X$7,"<="&$AH$11))+INT((1+COUNTIF(DADOS!$X$5:$X$7,"<="&$AH$11))/2),IF($R$60=TRUE,(1+COUNTIF(DADOS!$X$5:$X$7,"<="&$AH$11)),0))
F61: Acrobacia | M61: Des | O61: =$L$17+IF($E$61=TRUE,(1+COUNTIF(DADOS!$X$5:$X$7,"<="&$AH$11))+INT((1+COUNTIF(DADOS!$X$5:$X$7,"<="&$AH$11))/2),IF($D$61=TRUE,(1+COUNTIF(DADOS!$X$5:$X$7,"<="&$AH$11)),0)) | T61: Natureza | AA61: Int | AC61: =$AB$17+IF($S$61=TRUE,(1+COUNTIF(DADOS!$X$5:$X$7,"<="&$AH$11))+INT((1+COUNTIF(DADOS!$X$5:$X$7,"<="&$AH$11))/2),IF($R$61=TRUE,(1+COUNTIF(DADOS!$X$5:$X$7,"<="&$AH$11)),0))
F62: Furtividade | M62: Des | O62: =$L$17+IF($E$62=TRUE,(1+COUNTIF(DADOS!$X$5:$X$7,"<="&$AH$11))+INT((1+COUNTIF(DADOS!$X$5:$X$7,"<="&$AH$11))/2),IF($D$62=TRUE,(1+COUNTIF(DADOS!$X$5:$X$7,"<="&$AH$11)),0)) | T62: Lidar com Animais | AA62: Int | AC62: =$AB$17+IF($S$62=TRUE,(1+COUNTIF(DADOS!$X$5:$X$7,"<="&$AH$11))+INT((1+COUNTIF(DADOS!$X$5:$X$7,"<="&$AH$11))/2),IF($R$62=TRUE,(1+COUNTIF(DADOS!$X$5:$X$7,"<="&$AH$11)),0))
F63: Pontaria | M63: Des | O63: =$L$17+IF($E$63=TRUE,(1+COUNTIF(DADOS!$X$5:$X$7,"<="&$AH$11))+INT((1+COUNTIF(DADOS!$X$5:$X$7,"<="&$AH$11))/2),IF($D$63=TRUE,(1+COUNTIF(DADOS!$X$5:$X$7,"<="&$AH$11)),0)) | T63: Tecnologia | AA63: Int | AC63: =$AB$17+IF($S$63=TRUE,(1+COUNTIF(DADOS!$X$5:$X$7,"<="&$AH$11))+INT((1+COUNTIF(DADOS!$X$5:$X$7,"<="&$AH$11))/2),IF($R$63=TRUE,(1+COUNTIF(DADOS!$X$5:$X$7,"<="&$AH$11)),0))
F64: Prestidigitação | M64: Des | O64: =$L$17+IF($E$64=TRUE,(1+COUNTIF(DADOS!$X$5:$X$7,"<="&$AH$11))+INT((1+COUNTIF(DADOS!$X$5:$X$7,"<="&$AH$11))/2),IF($D$64=TRUE,(1+COUNTIF(DADOS!$X$5:$X$7,"<="&$AH$11)),0)) | T64: Sentir Energia | AA64: Ess | AC64: =$AJ$17+IF($S$64=TRUE,(1+COUNTIF(DADOS!$X$5:$X$7,"<="&$AH$11))+INT((1+COUNTIF(DADOS!$X$5:$X$7,"<="&$AH$11))/2),IF($R$64=TRUE,(1+COUNTIF(DADOS!$X$5:$X$7,"<="&$AH$11)),0))
F65: Investigação | M65: Int | O65: =$AB$17+IF($E$65=TRUE,(1+COUNTIF(DADOS!$X$5:$X$7,"<="&$AH$11))+INT((1+COUNTIF(DADOS!$X$5:$X$7,"<="&$AH$11))/2),IF($D$65=TRUE,(1+COUNTIF(DADOS!$X$5:$X$7,"<="&$AH$11)),0)) | T65: Percepção | AA65: Ess | AC65: =$AJ$17+IF($S$65=TRUE,(1+COUNTIF(DADOS!$X$5:$X$7,"<="&$AH$11))+INT((1+COUNTIF(DADOS!$X$5:$X$7,"<="&$AH$11))/2),IF($R$65=TRUE,(1+COUNTIF(DADOS!$X$5:$X$7,"<="&$AH$11)),0))
F66: Intuição | M66: Int | O66: =$AB$17+IF($E$66=TRUE,(1+COUNTIF(DADOS!$X$5:$X$7,"<="&$AH$11))+INT((1+COUNTIF(DADOS!$X$5:$X$7,"<="&$AH$11))/2),IF($D$66=TRUE,(1+COUNTIF(DADOS!$X$5:$X$7,"<="&$AH$11)),0)) | T66: Persuasão | AA66: Ess | AC66: =$AJ$17+IF($S$66=TRUE,(1+COUNTIF(DADOS!$X$5:$X$7,"<="&$AH$11))+INT((1+COUNTIF(DADOS!$X$5:$X$7,"<="&$AH$11))/2),IF($R$66=TRUE,(1+COUNTIF(DADOS!$X$5:$X$7,"<="&$AH$11)),0))
F67: Ocultismo | M67: Int | O67: =$AB$17+IF($E$67=TRUE,(1+COUNTIF(DADOS!$X$5:$X$7,"<="&$AH$11))+INT((1+COUNTIF(DADOS!$X$5:$X$7,"<="&$AH$11))/2),IF($D$67=TRUE,(1+COUNTIF(DADOS!$X$5:$X$7,"<="&$AH$11)),0)) | T67: Enganação | AA67: Ess | AC67: =$AJ$17+IF($S$67=TRUE,(1+COUNTIF(DADOS!$X$5:$X$7,"<="&$AH$11))+INT((1+COUNTIF(DADOS!$X$5:$X$7,"<="&$AH$11))/2),IF($R$67=TRUE,(1+COUNTIF(DADOS!$X$5:$X$7,"<="&$AH$11)),0))
F68: Religião | M68: Int | O68: =$AB$17+IF($E$68=TRUE,(1+COUNTIF(DADOS!$X$5:$X$7,"<="&$AH$11))+INT((1+COUNTIF(DADOS!$X$5:$X$7,"<="&$AH$11))/2),IF($D$68=TRUE,(1+COUNTIF(DADOS!$X$5:$X$7,"<="&$AH$11)),0)) | T68: Intimidação | AA68: Ess | AC68: =$AJ$17+IF($S$68=TRUE,(1+COUNTIF(DADOS!$X$5:$X$7,"<="&$AH$11))+INT((1+COUNTIF(DADOS!$X$5:$X$7,"<="&$AH$11))/2),IF($R$68=TRUE,(1+COUNTIF(DADOS!$X$5:$X$7,"<="&$AH$11)),0))
F69: História | M69: Int | O69: =$AB$17+IF($E$69=TRUE,(1+COUNTIF(DADOS!$X$5:$X$7,"<="&$AH$11))+INT((1+COUNTIF(DADOS!$X$5:$X$7,"<="&$AH$11))/2),IF($D$69=TRUE,(1+COUNTIF(DADOS!$X$5:$X$7,"<="&$AH$11)),0)) | T69: Atuação | AA69: Ess | AC69: =$AJ$17+IF($S$69=TRUE,(1+COUNTIF(DADOS!$X$5:$X$7,"<="&$AH$11))+INT((1+COUNTIF(DADOS!$X$5:$X$7,"<="&$AH$11))/2),IF($R$69=TRUE,(1+COUNTIF(DADOS!$X$5:$X$7,"<="&$AH$11)),0))
F70: Hierarquia | M70: Int | O70: =$AB$17+IF($E$70=TRUE,(1+COUNTIF(DADOS!$X$5:$X$7,"<="&$AH$11))+INT((1+COUNTIF(DADOS!$X$5:$X$7,"<="&$AH$11))/2),IF($D$70=TRUE,(1+COUNTIF(DADOS!$X$5:$X$7,"<="&$AH$11)),0)) | T70: Provocar | AA70: Ess | AC70: =$AJ$17+IF($S$70=TRUE,(1+COUNTIF(DADOS!$X$5:$X$7,"<="&$AH$11))+INT((1+COUNTIF(DADOS!$X$5:$X$7,"<="&$AH$11))/2),IF($R$70=TRUE,(1+COUNTIF(DADOS!$X$5:$X$7,"<="&$AH$11)),0))
...

Sheet MESA
A1: =FICHA!D3
A4: VIDA | G4: ENERGIA
A5: =FICHA!D23 | G5: =FICHA!D27
A8: ="de "&FICHA!J23 | G8: ="de "&FICHA!J27
A10: DEFESA | G10: INICIATIVA
A11: =FICHA!D40 | G11: =FICHA!AK40
A13: CORPO A CORPO | G13: À DISTÂNCIA
A14: =FICHA!Z44 | G14: =FICHA!AK44
A16: CONJURAÇÃO | G16: CD DE FEITIÇO
A17: =FICHA!O44 | G17: =FICHA!D44
A19: DESLOCAMENTO | G19: MAESTRIA
A20: =FICHA!O48 | G20: =FICHA!D48
A23: ESTADO DA ALMA
A24: =FICHA!D34
A26: FEITIÇOS
A27: NOME | E27: CL | F27: DANO | H27: PE | I27: ALCANCE | K27: RESOLVE

Sheet QUEM É
A1: QUEM É · a ficção
C4: APARÊNCIA
C12: HISTÓRIA
C24: LAÇOS
C32: O QUE ELE QUER
C38: O QUE ELE ESCONDE
C44: NOTAS DE MESA

Sheet DADOS
A1: VERSÃO DO CATÁLOGO | B1: 0.104 | C1: versão corrente (puxada da central) | D1: 0.104
A2: cole aqui o IMPORTRANGE da central em D1 quando ela existir; enquanto não existir, D1 fica igual a B1 e o aviso some
A3: Caminhos | B3: Perícias | C3: Ofícios | D3: Famílias | E3: Formas | F3: Melhorias | G3: Restrições | H3: Condições | I3: Origens | J3: Testes | K3: Atributos | L3: Trilhas | N3: tabela dos Caminhos
A4: Bastião | B4: Atletismo | C4: Condução | D4: Alcance | E4: Projétil | F4: Longe | G4: Corpo a Corpo | H4: Lento | I4: Latente | J4: Físico | K4: Força | L4: Muro | N4: Caminho | O4: dado | P4: vida inicial | Q4: vida por nível | R4: PE por nível | S4: perícia fixa 1 | T4: perícia fixa 2 | U4: ofício fixo | W4: marcos | X4: maestria | Y4: classe | Z4: classe 0 | AB4: perícia | AC4: atributo | BA4: campo | BB4: célula
A5: Vanguarda | B5: Acrobacia | C5: Arrombamento | D5: Área | E5: Toque | F5: Muito Longe | G5: Lento | H5: Incapacitado | I5: Receptáculo | J5: Vigor | K5: Destreza | L5: Punho | N5: Bastião | O5: d12 | P5: 12 | Q5: 7 | R5: 4 | S5: Atletismo | T5: Intimidação | U5: Forja | W5: 6 | X5: 10 | Y5: 1 | Z5: 5 | AB5: Atletismo | AC5: Força | BA5: nome | BB5: D3
A6: Guia | B6: Furtividade | C6: Herbalismo | D6: Mira | E6: Explosão | F6: Sem Ver | G6: Parado | H6: Derrubado | I6: Descendente | J6: Intelecto | K6: Constituição | L6: Brasa | N6: Vanguarda | O6: d8 | P6: 8 | Q6: 5 | R6: 5 | S6: Acrobacia | T6: Percepção | U6: Arrombamento | W6: 10 | X6: 18 | Y6: 5 | Z6: 11 | AB6: Acrobacia | AC6: Destreza | BA6: caminho | BB6: D11
A7: Emanador | B7: Pontaria | C7: Forja | D7: Controle | E7: Aura | F7: Passo | G7: Gesto | H7: Agarrado | I7: Reencarnado | J7: Espírito | K7: Inteligência | L7: Estocada | N7: Guia | O7: d8 | P7: 8 | Q7: 5 | R7: 5 | S7: Persuasão | T7: Medicina | U7: Herbalismo | W7: 14 | X7: 26 | Y7: 9 | Z7: 17 | AB7: Furtividade | AC7: Destreza | BA7: trilha | BB7: N11
B8: Prestidigitação | C8: Caligrafia | D8: Auxiliares | E8: Cone | F8: Empurrão | G8: Sangra | H8: Desarmado | I8: Feto | K8: Essência | L8: Batedor | N8: Evocador | O8: d6 | P8: 6 | Q8: 4 | R8: 6 | S8: Religião | T8: Lidar com Animais | U8: Entalhador | W8: 18 | Y8: 13 | AB8: Pontaria | AC8: Destreza | BA8: origem | BB8: X11
B9: Investigação | C9: Burocracia | D9: Castigo | E9: Linha | F9: Troca | G9: Recuo | H9: Surdo | I9: Corpo Amaldiçoado | L9: Executor | N9: Emanador | O9: d6 | P9: 6 | Q9: 4 | R9: 6 | S9: Ocultismo | T9: Investigação | U9: Caligrafia | W9: 22 | Y9: 17 | AB9: Prestidigitação | AC9: Destreza | BA9: nivel | BB9: AH11
B10: Intuição | C10: Entalhador | D10: Tempo | E10: Cura | F10: Perseguir | G10: Carregar | H10: Calado | I10: Restrição Celestial | L10: Elo | W10: 26 | Y10: 21 | AB10: Investigação | AC10: Inteligência | BA10: xp | BB10: AN11
B11: Ocultismo | C11: Alfaiate | D11: Marca | E11: Apoio | F11: Maior | G11: Tudo ou Nada | H11: Enfeitiçado | L11: Sutura | W11: 30 | Y11: 26 | AB11: Intuição | AC11: Inteligência | BA11: atr_Força | BB11: D17
B12: Religião | C12: Culinária | D12: Amparo | E12: Onda | F12: Muito Maior | G12: Uma Vez | H12: Petrificado | L12: Perímetro | AB12: Ocultismo | AC12: Inteligência | BA12: atr_Destreza | BB12: L17
B13: História | C13: Instrumento | E13: Efeito | F13: Escolher | G13: Condicional | H13: Impedido | L13: Torrente | AB13: Religião | AC13: Inteligência | BA13: atr_Constituição | BB13: T17
B14: Hierarquia | C14: Jogatina | F14: Fica | G14: Fraqueza | H14: Cego | L14: Explosivo | AB14: História | AC14: Inteligência | BA14: atr_Inteligência | BB14: AB17
B15: Medicina | F15: Mais Um | G15: Frágil | H15: Amedrontado | L15: Arremate | AB15: Hierarquia | AC15: Inteligência | BA15: atr_Essência | BB15: AJ17
B16: Sobrevivência | F16: Rajada | G16: Barulho | H16: Envenenado | L16: Servo | AB16: Medicina | AC16: Inteligência | BA16: vida | BB16: D23
B17: Natureza | F17: Salto | G17: Assinatura | H17: Atordoado | L17: Matilha | AB17: Sobrevivência | AC17: Inteligência | BA17: vida_max | BB17: J23
B18: Lidar com Animais | F18: Contorno | G18: Aquecer | L18: Coro | AB18: Natureza | AC18: Inteligência | BA18: vida_temp | BB18: AF23
B19: Tecnologia | F19: Precisão | G19: Dívida | AB19: Lidar com Animais | AC19: Inteligência | BA19: vida_delta | BB19: AM23
B20: Sentir Energia | F20: Certeiro | G20: Peso Morto | AB20: Tecnologia | AC20: Inteligência | BA20: energia | BB20: D27
B21: Percepção | F21: Inescapável | G21: Sem Volta | AB21: Sentir Energia | AC21: Essência | BA21: energia_max | BB21: J27
B22: Persuasão | F22: Fura | G22: Restrição Própria | AB22: Percepção | AC22: Essência | BA22: energia_temp | BB22: AF27
B23: Enganação | F23: Corrói | AB23: Persuasão | AC23: Essência | BA23: energia_delta | BB23: AM27
B24: Intimidação | F24: Sem Cobertura | AB24: Enganação | AC24: Essência | BA24: integridade | BB24: D31
B25: Atuação | F25: De Novo | AB25: Intimidação | AC25: Essência | BA25: integridade_max | BB25: J31
B26: Provocar | F26: Toca a Alma | AB26: Atuação | AC26: Essência | BA26: integridade_temp | BB26: AF31
F27: Terreno | AB27: Provocar | AC27: Essência | BA27: integridade_delta | BB27: AM31
F28: Anteparo | BA28: estagio_alma | BB28: D34
F29: Prende | BA29: defesa | BB29: D40
F30: Cerca | BA30: proteção | BB30: O40
F31: Puxa | BA31: equipamento | BB31: Z40
F32: Desarma o Feitiço | BA32: iniciativa | BB32: AK40
F33: Nível | BA33: cd de feitiço | BB33: D44
F34: Impulso | BA34: conjuração | BB34: O44
F35: Trava | BA35: corpo a corpo | BB35: Z44
F36: Abre Ferida | BA36: à distância | BB36: AK44
F37: Sobrecarga | BA37: maestria | BB37: D48
F38: Firmeza | BA38: deslocamento | BB38: O48
F39: Guarda | BA39: bloquear | BB39: Z48
... F43: Queima | BA43: classe 0 grátis | BB43: AK54
...
