Workbook

Sheet CARTEIRA
C2: 呪術廻戦 | L2: =UPPER(DADOS!$F$1) | AH2: ="Nº M-"&DADOS!$B$1&"-"&IF(FICHA!$AB$2="","····",UPPER(LEFT(FICHA!$AB$2,4)))
L3: Carteira de registro · Documento oficial | AH3: ="Emitida "&TEXT(TODAY(),"dd.mm.yyyy")
C8: FOTO 顔 | O8: PORTADOR
O9: Coloque o nome do personagem aqui
O17: CAMINHO | Z17: TRILHA | AK17: ORIGEM
O18: =IF(OR(FICHA!D11="",FICHA!D11="Escolha seu Caminho"),"—",FICHA!D11) | Z18: =IF(OR(FICHA!N11="",FICHA!N11="Escolha sua Trilha"),"—",FICHA!N11) | AK18: =IF(FICHA!X11="","—",FICHA!X11)
O21: NÍVEL | Z21: SERVIDOR USADO | AK21: REGISTRADO POR
O22: =IF(FICHA!AH11="","—",FICHA!AH11) | AK22: Nick do jogador
O26: =IF(DADOS!$AK$32=1,"TÉCNICA MARCIAL DECLARADA",IF(DADOS!$AK$31=1,"ESTILO DECLARADO","TÉCNICA AMALDIÇOADA DECLARADA"))
AK34: SELO REGISTRADO
AH38: =IF(OR(FICHA!D11="",FICHA!D11="Escolha seu Caminho"),"—",UPPER(LEFT(FICHA!D11,3))&"-"&TEXT(FICHA!AH11,"00"))

Sheet FICHA
D2: 呪術 | H2: FICHA DE REGISTRO | AB2: =IF(OR(CARTEIRA!$O$9="",CARTEIRA!$O$9="Coloque o nome do personagem aqui"),"",CARTEIRA!$O$9)
H4: =DADOS!$F$1&" · "&IF(DADOS!$B$1=DADOS!$D$1,"v"&DADOS!$B$1&" · em dia","⚠ v"&DADOS!$B$1&" · a atual é a v"&DADOS!$D$1) | AB4: =IF(OR($D$11="",$D$11="Escolha seu Caminho"),"",$D$11&IF(OR($N$11="",$N$11="Escolha sua Trilha"),""," · "&$N$11)&" · nível "&$AH$11)
A8: CICLO MALDITO | D8: 1 | G8: PERFIL AMALDIÇOADO
AW9: SUA ORIGEM · O QUE VOCÊ ESCOLHEU
D10: CAMINHO | N10: TRILHA | X10: ORIGEM | AH10: NÍVEL | AN10: XP | AW10: ="MARCANTE · "&$D$52&IF($D$53="",""," · "&$D$53)&CHAR(10)&IF('FICHA PESSOAL'!$D$45="","(o texto é escrito na FICHA PESSOAL)",'FICHA PESSOAL'!$D$45)&IF('FICHA PESSOAL'!$D$58="","",CHAR(10)&CHAR(10)&"Talento de Categoria de Efeito 4: "&'FICHA PESSOAL'!$D$58)&CHAR(10)&CHAR(10)&"MENOR 1 · "&$S$52&IF($S$53="",""," · "&$S$53)&CHAR(10)&IF('FICHA PESSOAL'!$R$45="","(o texto é escrito na FICHA PESSOAL)",'FICHA PESSOAL'!$R$45)&CHAR(10)&CHAR(10)&"MENOR 2 · "&$AG$52&IF($AG$53="",""," · "&$AG$53)&CHAR(10)&IF('FICHA PESSOAL'!$AH$45="","(o texto é escrito na FICHA PESSOAL)",'FICHA PESSOAL'!$AH$45)&CHAR(10)&CHAR(10)&"LEGADOS DE HISTÓRIA"&CHAR(10)&IF('FICHA PESSOAL'!$D$54="","(nenhum escrito)",'FICHA PESSOAL'!$D$54)
D11: Escolha seu Caminho | N11: Escolha sua Trilha | X11: Latente | AH11: =DADOS_CONFIG!$S$2 | AN11: =DADOS!$CZ$47
Z14: Pontos Disponíveis | AK14: ="Pontos de Marco de Corpo Disponíveis - "&IF(DADOS!$AK$11>DADOS!$AK$10,DADOS!$AK$11-DADOS!$AK$10&" a mais",DADOS!$AK$10-DADOS!$AK$11&" de "&DADOS!$AK$10)
D15: 2 | G15: VALORES | Z15: =IF(DADOS!$AK$7>DADOS!$AK$6,DADOS!$AK$7-DADOS!$AK$6&" a mais",IF(DADOS!$AK$8>DADOS_CONFIG!$S$5,"Um atributo passou de "&DADOS_CONFIG!$S$5,IF(AND(DADOS!$AK$5=0,DADOS!$AK$9>DADOS_CONFIG!$S$4),"Na criação, nenhum acima de "&DADOS_CONFIG!$S$4,DADOS!$AK$6-DADOS!$AK$7&" de "&DADOS!$AK$6))) | AK15: 0 | AM15: 0 | AO15: 0 | AQ15: 0 | AS15: 0
AK16: FOR | AM16: DEX | AO16: CON | AQ16: INT | AS16: ESS
D18: FOR | L18: DES | T18: CON | AB18: INT | AJ18: ESS
D19: =IFERROR(VALUE($D$21&""),0)+IFERROR(VALUE($AK$15&""),0) | L19: =IFERROR(VALUE($L$21&""),0)+IFERROR(VALUE($AM$15&""),0) | T19: =IFERROR(VALUE($T$21&""),0)+IFERROR(VALUE($AO$15&""),0) | AB19: =IFERROR(VALUE($AB$21&""),0)+IFERROR(VALUE($AQ$15&""),0) | AJ19: =IFERROR(VALUE($AJ$21&""),0)+IFERROR(VALUE($AS$15&""),0)
D21: 0 | L21: 0 | T21: 0 | AB21: 0 | AJ21: 0
D22: Força | L22: Destreza | T22: Constituição | AB22: Inteligência | AJ22: Essência
D25: VIDA - Atual/Máxima | P25: Buff/Debuff | AF25: TEMPORÁRIO | AM25: ± PERDA &/ou GANHO
D26: =J26 | J26: =IF(DADOS_CONFIG!$E$2<>"",NA(),IF(DADOS_CONFIG!$C$2=1,DADOS_CONFIG!$D$2,IF(DADOS_CONFIG!$B$2=0,IF(DADOS_CONFIG!$S$15="Não",IFERROR((IFERROR(IF($D$11="","",(VLOOKUP($D$11,'DADOS_PROGRESSAO'!$M$2:$T$8,3,FALSE)+$T$19)+(VLOOKUP($D$11,'DADOS_PROGRESSAO'!$M$2:$T$8,4,FALSE)+$T$19)*($AH$11-1)),""))+IFERROR(VALUE($P$26&""),0),""),IF(DADOS_CONFIG!$AF$32<>"",NA(),SUM(DADOS_CONFIG!$AF$2:$AF$31)+IFERROR(VALUE('FICHA'!$P$26&""),0))),IF((IF(DADOS_CONFIG!$S$15="Não",IFERROR((IFERROR(IF($D$11="","",(VLOOKUP($D$11,'DADOS_PROGRESSAO'!$M$2:$T$8,3,FALSE)+$T$19)+(VLOOKUP($D$11,'DADOS_PROGRESSAO'!$M$2:$T$8,4,FALSE)+$T$19)*($AH$11-1)),""))+IFERROR(VALUE($P$26&""),0),""),IF(DADOS_CONFIG!$AF$32<>"",NA(),SUM(DADOS_CONFIG!$AF$2:$AF$31)+IFERROR(VALUE('FICHA'!$P$26&""),0))))="","",(IF(DADOS_CONFIG!$S$15="Não",IFERROR((IFERROR(IF($D$11="","",(VLOOKUP($D$11,'DADOS_PROGRESSAO'!$M$2:$T$8,3,FALSE)+$T$19)+(VLOOKUP($D$11,'DADOS_PROGRESSAO'!$M$2:$T$8,4,FALSE)+$T$19)*($AH$11-1)),""))+IFERROR(VALUE($P$26&""),0),""),IF(DADOS_CONFIG!$AF$32<>"",NA(),SUM(DADOS_CONFIG!$AF$2:$AF$31)+IFERROR(VALUE('FICHA'!$P$26&""),0))))+DADOS_CONFIG!$B$2)))) | P26: 0 | S26: =IFERROR(__xludf.DUMMYFUNCTION("IFERROR(SPARKLINE($D$26,{""charttype"",""bar"";""max"",$J$26;""color1"",IF(N($J$26)=0,DADOS!$CZ$51,IF($D$26/$J$26<=0.25,""#C2334D"",IF($D$26/$J$26<=0.5,""#D89B3A"",DADOS!$CZ$51)))}),"""")"),"") | AF26: 0
D29: ENERGIA - Atual/Máxima | P29: Buff/Debuff | AF29: TEMPORÁRIO | AM29: ± PERDA &/ou GANHO
D30: =J30 | J30: =IF(DADOS_CONFIG!$E$3<>"",NA(),IF(DADOS_CONFIG!$C$3=1,DADOS_CONFIG!$D$3,IF(DADOS_CONFIG!$B$3=0,IFERROR((IFERROR(IF($D$11="","",VLOOKUP($D$11,'DADOS_PROGRESSAO'!$M$2:$T$8,5,FALSE)*$AH$11),""))+IFERROR(VALUE($P$30&""),0),""),IF((IFERROR((IFERROR(IF($D$11="","",VLOOKUP($D$11,'DADOS_PROGRESSAO'!$M$2:$T$8,5,FALSE)*$AH$11),""))+IFERROR(VALUE($P$30&""),0),""))="","",(IFERROR((IFERROR(IF($D$11="","",VLOOKUP($D$11,'DADOS_PROGRESSAO'!$M$2:$T$8,5,FALSE)*$AH$11),""))+IFERROR(VALUE($P$30&""),0),""))+DADOS_CONFIG!$B$3)))) | P30: 0 | S30: =IFERROR(__xludf.DUMMYFUNCTION("IFERROR(SPARKLINE($D$30,{""charttype"",""bar"";""max"",$J$30;""color1"",IF(N($J$30)=0,DADOS!$CZ$51,IF($D$30/$J$30<=0.25,""#C2334D"",IF($D$30/$J$30<=0.5,""#D89B3A"",DADOS!$CZ$51)))}),"""")"),"") | AF30: 0
A33: FICHA DE REGISTRO | D33: INTEGRIDADE - Atual/Máxima | P33: Buff/Debuff | AF33: TEMPORÁRIO | AM33: ± PERDA &/ou GANHO
D34: =J34 | J34: =IF(DADOS_CONFIG!$E$4<>"",NA(),IF(DADOS_CONFIG!$C$4=1,DADOS_CONFIG!$D$4,IF(DADOS_CONFIG!$B$4=0,IFERROR((20+(AJ19+5)*($AH$11-1))+IFERROR(VALUE($P$34&""),0),""),IF((IFERROR((20+(AJ19+5)*($AH$11-1))+IFERROR(VALUE($P$34&""),0),""))="","",(IFERROR((20+(AJ19+5)*($AH$11-1))+IFERROR(VALUE($P$34&""),0),""))+DADOS_CONFIG!$B$4)))) | P34: 0 | S34: =IFERROR(__xludf.DUMMYFUNCTION("IFERROR(SPARKLINE($D$34,{""charttype"",""bar"";""max"",$J$34;""color1"",IF(N($J$34)=0,DADOS!$CZ$51,IF($D$34/$J$34<=0.25,""#C2334D"",IF($D$34/$J$34<=0.5,""#D89B3A"",DADOS!$CZ$51)))}),"""")"),"") | AF34: 0
D37: =IF($D$34=""," ",IF($D$34<=0,"Estágio 4 · Você não é mais você mesmo",IF($D$34<=$J$34/4,"Estágio 3 · Desvantagem em ataques e TRs",IF($D$34<=$J$34/2,"Estágio 2 · Metade do deslocamento, +1 PE por Classe",IF($D$34<=$J$34*3/4,"Estágio 1 · Desvantagem em perícias","Alma Inteira")))))
D39: SE A VIDA CHEGAR A 0 · MORRENDO · a cura que você precisa receber para levantar, e o prazo para recebê-la
D40: AGUENTAR · FICA INCONSCIENTE | O40: INSISTIR · 1ª VEZ NA CENA | Z40: INSISTIR · 2ª VEZ EM DIANTE | AK40: PRAZO ATÉ SER DERROTADO
D41: =ROUNDUP(ROUND(N('FICHA'!$J$26)*DADOS_CONFIG!$S$10,10),0) | O41: =MIN(ROUNDUP(ROUND(N('FICHA'!$J$26)*DADOS_CONFIG!$S$11,10),0),DADOS_CONFIG!$S$13*N('FICHA'!$Z$73)) | Z41: =MIN(ROUNDUP(ROUND(N('FICHA'!$J$26)*DADOS_CONFIG!$S$12,10),0),DADOS_CONFIG!$S$13*N('FICHA'!$Z$73)) | AK41: =IF(MAX(0,DADOS_CONFIG!$S$14-(N('FICHA'!$F$48)+N('FICHA'!$H$48)+N('FICHA'!$J$48)+IF(ISBLANK('FICHA'!$J$50),0,IF(IFERROR(AND(ISNUMBER('FICHA'!$J$50),'FICHA'!$J$50>=0,INT('FICHA'!$J$50)='FICHA'!$J$50),FALSE),'FICHA'!$J$50,NA()))))=0,"Derrotado na hora",MAX(0,DADOS_CONFIG!$S$14-(N('FICHA'!$F$48)+N('FICHA'!$H$48)+N('FICHA'!$J$48)+IF(ISBLANK('FICHA'!$J$50),0,IF(IFERROR(AND(ISNUMBER('FICHA'!$J$50),'FICHA'!$J$50>=0,INT('FICHA'!$J$50)='FICHA'!$J$50),FALSE),'FICHA'!$J$50,NA()))))&IF(MAX(0,DADOS_CONFIG!$S$14-(N('FICHA'!$F$48)+N('FICHA'!$H$48)+N('FICHA'!$J$48)+IF(ISBLANK('FICHA'!$J$50),0,IF(IFERROR(AND(ISNUMBER('FICHA'!$J$50),'FICHA'!$J$50>=0,INT('FICHA'!$J$50)='FICHA'!$J$50),FALSE),'FICHA'!$J$50,NA()))))=1," rodada"," rodadas"))
D42: =IF(ISBLANK('CONFIGURAÇÃO'!$F$54),"¼ da vida máxima, para cima",TEXT(DADOS_CONFIG!$S$10,"# ?/?")&" da vida máxima, para cima") | O42: =IF(AND(ISBLANK('CONFIGURAÇÃO'!$F$55),ISBLANK('CONFIGURAÇÃO'!$F$57)),IF(ROUNDUP(N(FICHA!$J$26)/3,0)>15*N(FICHA!$Z$73),"⅓ da vida máxima, no teto de 15 × Classe","⅓ da vida máxima, para cima"),TEXT(DADOS_CONFIG!$S$11,"# ?/?")&" da vida máxima, para cima"&" · teto "&DADOS_CONFIG!$S$13&" × Classe") | Z42: =IF(AND(ISBLANK('CONFIGURAÇÃO'!$F$56),ISBLANK('CONFIGURAÇÃO'!$F$57)),IF(ROUNDUP(N(FICHA!$J$26)/2,0)>15*N(FICHA!$Z$73),"½ da vida máxima, no teto de 15 × Classe","½ da vida máxima, para cima"),TEXT(DADOS_CONFIG!$S$12,"# ?/?")&" da vida máxima, para cima"&" · teto "&DADOS_CONFIG!$S$13&" × Classe") | AK42: =DADOS_CONFIG!$S$14&" rodadas, menos 1 por Sequela marcada"
D44: DESCANSO | O44: O ÚLTIMO DESCANSO
D45: Escolha o descanso
D47: SEQUELAS | O47: EXAUSTÃO | Z47: RESISTÊNCIAS | AK47: IMUNIDADES
F48: 0 | H48: 0 | J48: 0 | O48: 0
D49: ="Próxima queda: "&IF(MAX(0,DADOS_CONFIG!$S$14-(N('FICHA'!$F$48)+N('FICHA'!$H$48)+N('FICHA'!$J$48)+IF(ISBLANK('FICHA'!$J$50),0,IF(IFERROR(AND(ISNUMBER('FICHA'!$J$50),'FICHA'!$J$50>=0,INT('FICHA'!$J$50)='FICHA'!$J$50),FALSE),'FICHA'!$J$50,NA()))))=0,"Derrotado na hora",MAX(0,DADOS_CONFIG!$S$14-(N('FICHA'!$F$48)+N('FICHA'!$H$48)+N('FICHA'!$J$48)+IF(ISBLANK('FICHA'!$J$50),0,IF(IFERROR(AND(ISNUMBER('FICHA'!$J$50),'FICHA'!$J$50>=0,INT('FICHA'!$J$50)='FICHA'!$J$50),FALSE),'FICHA'!$J$50,NA()))))&IF(MAX(0,DADOS_CONFIG!$S$14-(N('FICHA'!$F$48)+N('FICHA'!$H$48)+N('FICHA'!$J$48)+IF(ISBLANK('FICHA'!$J$50),0,IF(IFERROR(AND(ISNUMBER('FICHA'!$J$50),'FICHA'!$J$50>=0,INT('FICHA'!$J$50)='FICHA'!$J$50),FALSE),'FICHA'!$J$50,NA()))))=1," rodada de janela"," rodadas de janela")) | O49: =IF(N($O$48)<=0,"Sem penalidade",IF(N($O$48)=1,"Desvantagem em perícias e ofícios",IF(N($O$48)=2,"Desv. em perícias e ofícios · até 4,5 m","Desv. em perícias, ofícios, ataques e TRs · até 4,5 m")))
D50: SEQUELAS EXTRAS | J50: 0
D51: MARCANTE | S51: MENOR 1 | AG51: MENOR 2
D52: =IF('FICHA PESSOAL'!$D$44="","—",IF('FICHA PESSOAL'!$D$44="✎ Criada com o mestre","Criada com o mestre",'FICHA PESSOAL'!$D$44)) | S52: =IF('FICHA PESSOAL'!$R$44="","—",IF('FICHA PESSOAL'!$R$44="✎ Criada com o mestre","Criada com o mestre",'FICHA PESSOAL'!$R$44)) | AG52: =IF('FICHA PESSOAL'!$AH$44="","—",IF('FICHA PESSOAL'!$AH$44="✎ Criada com o mestre","Criada com o mestre",'FICHA PESSOAL'!$AH$44))
D53: =IF('FICHA PESSOAL'!$D$44="","escolha na FICHA PESSOAL",IFERROR(VLOOKUP('FICHA PESSOAL'!$D$44,'DADOS_CUSTOM'!$AZ$2:$BE$107,5,FALSE),"criada com o mestre")) | S53: =IF('FICHA PESSOAL'!$R$44="","escolha na FICHA PESSOAL",IFERROR(VLOOKUP('FICHA PESSOAL'!$R$44,'DADOS_CUSTOM'!$AZ$2:$BE$107,5,FALSE),"criada com o mestre")) | AG53: =IF('FICHA PESSOAL'!$AH$44="","escolha na FICHA PESSOAL",IFERROR(VLOOKUP('FICHA PESSOAL'!$AH$44,'DADOS_CUSTOM'!$AZ$2:$BE$107,5,FALSE),"criada com o mestre"))
Z55: BLOQUEAR | AK55: Marco Escolhido | AO55: Refino | AQ55: Corpo | AS55: Leque
D56: 3 | G56: REGISTRO | Z56: ="2d10 + " & D59-11 | AK56: =IF(DADOS!$AK$12>DADOS!$AK$5,DADOS!$AK$12-DADOS!$AK$5&" a mais",IF(DADOS!$AK$5=0,"Escolha 1 a cada 4 Nv",DADOS!$AK$5-DADOS!$AK$12&" de "&DADOS!$AK$5&" para escolher")) | AO56: 0 | AQ56: 0 | AS56: 0
D58: DEFESA | L58: Buff/Debuff | O58: PROTEÇÃO | W58: Buff/Debuff | Z58: EQUIPAMENTO | AK58: INICIATIVA | AS58: Buff/Debuff
D59: =IF(DADOS_CONFIG!$E$5<>"",NA(),IF(DADOS_CONFIG!$C$5=1,DADOS_CONFIG!$D$5,IF(DADOS_CONFIG!$B$5=0,IF(OR(COUNTIF('DADOS_CUSTOM'!$C$2:$C$26,'FICHA PESSOAL'!$AH$64)>0,AND(DADOS!$CZ$19=1,COUNTIF('DADOS_CUSTOM'!$C$2:$C$26,'FICHA PESSOAL'!$S$64)>0)),10+MIN('FICHA'!$L$19,MIN(IFERROR(VALUE(DADOS!$CZ$29&""),9999),IF(DADOS!$CZ$19=1,IFERROR(VALUE(VLOOKUP('FICHA PESSOAL'!$S$64,'DADOS_CUSTOM'!$BM$2:$BU$125,4,FALSE)&""),9999),9999)))+'FICHA'!$O$59+IFERROR(VALUE('FICHA'!$L$59&""),0),10+IF($Z$59="",$L$19,MIN($L$19,IFERROR(VALUE(VLOOKUP($Z$59,DADOS!$AE$5:$AH$31,3,FALSE)&""),$L$19)))+$O$59+IFERROR(VALUE($L$59&""),0)),IF((IF(OR(COUNTIF('DADOS_CUSTOM'!$C$2:$C$26,'FICHA PESSOAL'!$AH$64)>0,AND(DADOS!$CZ$19=1,COUNTIF('DADOS_CUSTOM'!$C$2:$C$26,'FICHA PESSOAL'!$S$64)>0)),10+MIN('FICHA'!$L$19,MIN(IFERROR(VALUE(DADOS!$CZ$29&""),9999),IF(DADOS!$CZ$19=1,IFERROR(VALUE(VLOOKUP('FICHA PESSOAL'!$S$64,'DADOS_CUSTOM'!$BM$2:$BU$125,4,FALSE)&""),9999),9999)))+'FICHA'!$O$59+IFERROR(VALUE('FICHA'!$L$59&""),0),10+IF($Z$59="",$L$19,MIN($L$19,IFERROR(VALUE(VLOOKUP($Z$59,DADOS!$AE$5:$AH$31,3,FALSE)&""),$L$19)))+$O$59+IFERROR(VALUE($L$59&""),0)))="","",(IF(OR(COUNTIF('DADOS_CUSTOM'!$C$2:$C$26,'FICHA PESSOAL'!$AH$64)>0,AND(DADOS!$CZ$19=1,COUNTIF('DADOS_CUSTOM'!$C$2:$C$26,'FICHA PESSOAL'!$S$64)>0)),10+MIN('FICHA'!$L$19,MIN(IFERROR(VALUE(DADOS!$CZ$29&""),9999),IF(DADOS!$CZ$19=1,IFERROR(VALUE(VLOOKUP('FICHA PESSOAL'!$S$64,'DADOS_CUSTOM'!$BM$2:$BU$125,4,FALSE)&""),9999),9999)))+'FICHA'!$O$59+IFERROR(VALUE('FICHA'!$L$59&""),0),10+IF($Z$59="",$L$19,MIN($L$19,IFERROR(VALUE(VLOOKUP($Z$59,DADOS!$AE$5:$AH$31,3,FALSE)&""),$L$19)))+$O$59+IFERROR(VALUE($L$59&""),0)))+DADOS_CONFIG!$B$5)))) | L59: 0 | O59: =IF(DADOS_CONFIG!$E$6<>"",NA(),IF(DADOS_CONFIG!$C$6=1,DADOS_CONFIG!$D$6,IF(DADOS_CONFIG!$B$6=0,IF(OR(COUNTIF('DADOS_CUSTOM'!$C$2:$C$26,'FICHA PESSOAL'!$AH$64)>0,AND(DADOS!$CZ$19=1,COUNTIF('DADOS_CUSTOM'!$C$2:$C$26,'FICHA PESSOAL'!$S$64)>0)),IF(DADOS!$CZ$27=1,DADOS!$CZ$28,FLOOR(MIN(10,$O$73+MIN($O$73-1,IFERROR(VALUE($AO$56&""),0)))/3,1)+1)+IF(DADOS!$CZ$19=1,IFERROR(VLOOKUP('FICHA PESSOAL'!$S$64,'DADOS_CUSTOM'!$BM$2:$BU$125,3,FALSE),0),0)+IFERROR(VALUE($W$59&""),0),IF($Z$59="",FLOOR(MIN(10,$O$73+MIN($O$73-1,IFERROR(VALUE($AO$56&""),0)))/3,1)+1,IF(VLOOKUP($Z$59,DADOS!$AE$5:$AH$31,4,FALSE)="sim",0,FLOOR(MIN(10,$O$73+MIN($O$73-1,IFERROR(VALUE($AO$56&""),0)))/3,1)+1)+VLOOKUP($Z$59,DADOS!$AE$5:$AH$31,2,FALSE))+IFERROR(VALUE($W$59&""),0)),IF((IF(OR(COUNTIF('DADOS_CUSTOM'!$C$2:$C$26,'FICHA PESSOAL'!$AH$64)>0,AND(DADOS!$CZ$19=1,COUNTIF('DADOS_CUSTOM'!$C$2:$C$26,'FICHA PESSOAL'!$S$64)>0)),IF(DADOS!$CZ$27=1,DADOS!$CZ$28,FLOOR(MIN(10,$O$73+MIN($O$73-1,IFERROR(VALUE($AO$56&""),0)))/3,1)+1)+IF(DADOS!$CZ$19=1,IFERROR(VLOOKUP('FICHA PESSOAL'!$S$64,'DADOS_CUSTOM'!$BM$2:$BU$125,3,FALSE),0),0)+IFERROR(VALUE($W$59&""),0),IF($Z$59="",FLOOR(MIN(10,$O$73+MIN($O$73-1,IFERROR(VALUE($AO$56&""),0)))/3,1)+1,IF(VLOOKUP($Z$59,DADOS!$AE$5:$AH$31,4,FALSE)="sim",0,FLOOR(MIN(10,$O$73+MIN($O$73-1,IFERROR(VALUE($AO$56&""),0)))/3,1)+1)+VLOOKUP($Z$59,DADOS!$AE$5:$AH$31,2,FALSE))+IFERROR(VALUE($W$59&""),0)))="","",(IF(OR(COUNTIF('DADOS_CUSTOM'!$C$2:$C$26,'FICHA PESSOAL'!$AH$64)>0,AND(DADOS!$CZ$19=1,COUNTIF('DADOS_CUSTOM'!$C$2:$C$26,'FICHA PESSOAL'!$S$64)>0)),IF(DADOS!$CZ$27=1,DADOS!$CZ$28,FLOOR(MIN(10,$O$73+MIN($O$73-1,IFERROR(VALUE($AO$56&""),0)))/3,1)+1)+IF(DADOS!$CZ$19=1,IFERROR(VLOOKUP('FICHA PESSOAL'!$S$64,'DADOS_CUSTOM'!$BM$2:$BU$125,3,FALSE),0),0)+IFERROR(VALUE($W$59&""),0),IF($Z$59="",FLOOR(MIN(10,$O$73+MIN($O$73-1,IFERROR(VALUE($AO$56&""),0)))/3,1)+1,IF(VLOOKUP($Z$59,DADOS!$AE$5:$AH$31,4,FALSE)="sim",0,FLOOR(MIN(10,$O$73+MIN($O$73-1,IFERROR(VALUE($AO$56&""),0)))/3,1)+1)+VLOOKUP($Z$59,DADOS!$AE$5:$AH$31,2,FALSE))+IFERROR(VALUE($W$59&""),0)))+DADOS_CONFIG!$B$6)))) | W59: 0 | Z59: =IF(DADOS!$CZ$27=1,'FICHA PESSOAL'!$AH$64&IF(DADOS!$CZ$19=1," + "&'FICHA PESSOAL'!$S$64,""),IF(DADOS!$CZ$19=1,'FICHA PESSOAL'!$S$64,"")) | AK59: =IF(DADOS_CONFIG!$E$7<>"",NA(),IF(DADOS_CONFIG!$C$7=1,"d20 + "&(DADOS_CONFIG!$D$7),IF(DADOS_CONFIG!$B$7=0,"d20 + "&($L$19+IFERROR(VALUE($AS$59&""),0)),"d20 + "&(IF((($L$19+IFERROR(VALUE($AS$59&""),0)))="","",(($L$19+IFERROR(VALUE($AS$59&""),0)))+DADOS_CONFIG!$B$7))))) | AS59: 0
D62: CD DE FEITIÇO | L62: Buff/Debuff | O62: CONJURAÇÃO | W62: Buff/Debuff | Z62: CORPO A CORPO | AH62: Buff/Debuff | AK62: À DISTÂNCIA | AS62: Buff/Debuff
D63: =IF(DADOS_CONFIG!$E$8<>"",NA(),IF(DADOS_CONFIG!$C$8=1,DADOS_CONFIG!$D$8,IF(DADOS_CONFIG!$B$8=0,8+D67+IFS(Z67="FORÇA",$D$19, Z67="DESTREZA",$L$19, Z67="CONSTITUIÇÃO",$T$19, Z67="INTELIGÊNCIA",$AB$19, Z67="ESSÊNCIA",$AJ$19)+IFERROR(VALUE($L$63&""),0),IF((8+D67+IFS(Z67="FORÇA",$D$19, Z67="DESTREZA",$L$19, Z67="CONSTITUIÇÃO",$T$19, Z67="INTELIGÊNCIA",$AB$19, Z67="ESSÊNCIA",$AJ$19)+IFERROR(VALUE($L$63&""),0))="","",(8+D67+IFS(Z67="FORÇA",$D$19, Z67="DESTREZA",$L$19, Z67="CONSTITUIÇÃO",$T$19, Z67="INTELIGÊNCIA",$AB$19, Z67="ESSÊNCIA",$AJ$19)+IFERROR(VALUE($L$63&""),0))+DADOS_CONFIG!$B$8)))) | L63: 0 | O63: =IF(DADOS_CONFIG!$E$9<>"",NA(),IF(DADOS_CONFIG!$C$9=1,"d20 + "&(DADOS_CONFIG!$D$9),IF(DADOS_CONFIG!$B$9=0,"d20 + "&(D67+IFS(Z67="FORÇA",$D$19, Z67="DESTREZA",$L$19, Z67="CONSTITUIÇÃO",$T$19, Z67="INTELIGÊNCIA",$AB$19, Z67="ESSÊNCIA",$AJ$19)+IFERROR(VALUE($W$63&""),0)),"d20 + "&(IF(((D67+IFS(Z67="FORÇA",$D$19, Z67="DESTREZA",$L$19, Z67="CONSTITUIÇÃO",$T$19, Z67="INTELIGÊNCIA",$AB$19, Z67="ESSÊNCIA",$AJ$19)+IFERROR(VALUE($W$63&""),0)))="","",((D67+IFS(Z67="FORÇA",$D$19, Z67="DESTREZA",$L$19, Z67="CONSTITUIÇÃO",$T$19, Z67="INTELIGÊNCIA",$AB$19, Z67="ESSÊNCIA",$AJ$19)+IFERROR(VALUE($W$63&""),0)))+DADOS_CONFIG!$B$9))))) | W63: 0 | Z63: =IF(DADOS_CONFIG!$E$10<>"",NA(),IF(DADOS_CONFIG!$C$10=1,"d20 + "&(DADOS_CONFIG!$D$10),IF(DADOS_CONFIG!$B$10=0,"d20 + "&(D67+IFS(AK67="FORÇA",$D$19, AK67="DESTREZA",$L$19, AK67="CONSTITUIÇÃO",$T$19, AK67="INTELIGÊNCIA",$AB$19, AK67="ESSÊNCIA",$AJ$19)+IFERROR(VALUE($AH$63&""),0)),"d20 + "&(IF(((D67+IFS(AK67="FORÇA",$D$19, AK67="DESTREZA",$L$19, AK67="CONSTITUIÇÃO",$T$19, AK67="INTELIGÊNCIA",$AB$19, AK67="ESSÊNCIA",$AJ$19)+IFERROR(VALUE($AH$63&""),0)))="","",((D67+IFS(AK67="FORÇA",$D$19, AK67="DESTREZA",$L$19, AK67="CONSTITUIÇÃO",$T$19, AK67="INTELIGÊNCIA",$AB$19, AK67="ESSÊNCIA",$AJ$19)+IFERROR(VALUE($AH$63&""),0)))+DADOS_CONFIG!$B$10))))) | AH63: 0 | AK63: =IF(DADOS_CONFIG!$E$11<>"",NA(),IF(DADOS_CONFIG!$C$11=1,"d20 + "&(DADOS_CONFIG!$D$11),IF(DADOS_CONFIG!$B$11=0,"d20 + "&(D67+IFS(AE70="FORÇA",$D$19, AE70="DESTREZA",$L$19, AE70="CONSTITUIÇÃO",$T$19, AE70="INTELIGÊNCIA",$AB$19, AE70="ESSÊNCIA",$AJ$19)+IFERROR(VALUE($AS$63&""),0)),"d20 + "&(IF(((D67+IFS(AE70="FORÇA",$D$19, AE70="DESTREZA",$L$19, AE70="CONSTITUIÇÃO",$T$19, AE70="INTELIGÊNCIA",$AB$19, AE70="ESSÊNCIA",$AJ$19)+IFERROR(VALUE($AS$63&""),0)))="","",((D67+IFS(AE70="FORÇA",$D$19, AE70="DESTREZA",$L$19, AE70="CONSTITUIÇÃO",$T$19, AE70="INTELIGÊNCIA",$AB$19, AE70="ESSÊNCIA",$AJ$19)+IFERROR(VALUE($AS$63&""),0)))+DADOS_CONFIG!$B$11))))) | AS63: 0
D66: MAESTRIA | O66: DESLOCAMENTO | W66: Buff/Debuff | Z66: ATRIBUTO DE CONJURAÇÃO | AK66: ATRIBUTO DE ATAQUE - CORPO A CORPO
...

Sheet FICHA AMALDIÇOADA
D2: 呪術 | E2: FICHA AMALDIÇOADA | J2: =FICHA!AB2
E4: =DADOS!$F$1&" · técnica, feitiços e aptidões" | J4: =FICHA!AB4
D7: Técnica | E7: Orçamento | F7: Feitiços | G7: Classe 0 | J7: Liberação | K7: T. Máxima | L7: Domínio | M7: Talentos | P7: Aptidões | Q7: Pactos | R7: ← Clique num nome para ir à seção
A8: CICLO MALDITO
D9: TÉCNICA
D11: NOME DA TÉCNICA | J11: TIPO DE DANO | L11: ATRIBUTO DA TÉCNICA | P11: CONJURAÇÃO | R11: CD
D12: =DADOS_AM!$KV$2 | L12: =DADOS_AM!$KV$3 | P12: =DADOS_AM!$KV$4 | R12: =DADOS_AM!$KV$5
D15: ROTA | J15: =DADOS_AM!$KV$6 | P15: =DADOS_AM!$KV$7
D16: =DADOS_AM!$KV$8 | P16: =DADOS_AM!$KV$9
D17: =DADOS_AM!$KV$10 | J17: =DADOS_AM!$KV$12 | P17: =DADOS_AM!$KV$14
D19: =DADOS_AM!$KV$11 | J19: =DADOS_AM!$KV$13 | P19: =DADOS_AM!$KV$15
D21: REGRA
D25: DESCRIÇÃO | L25: =DADOS_AM!$KV$16
L28: EXPRESSÃO DA TÉCNICA
D32: REGRA PRÓPRIA | P32: CATEGORIA | R32: ESPAÇOS
A33: FICHA AMALDIÇOADA | R33: =DADOS_AM!$KV$17
D36: ALCANCE | E36: ÁREA | F36: MIRA | G36: CONTROLE | J36: AUXILIARES | K36: CASTIGO | L36: TEMPO | M36: MARCA | P36: AMPARO | Q36: LIVRES · FECHADAS
D37: Neutra | E37: Neutra | F37: Neutra | G37: Neutra | J37: Neutra | K37: Neutra | L37: Neutra | M37: Neutra | P37: Neutra | Q37: =DADOS_AM!$KV$18
D38: FAMÍLIAS CUSTOM · CONFIGURAÇÃO
D39: =IF(COUNTIF('DADOS_CRIACAO'!$H$11:$H$20,"?*")=0,"","Escolha Livre, Neutra ou Fechada. Usa os mesmos limites e custos das Famílias do livro.")
D40: =IF(COUNTIF('DADOS_CRIACAO'!$H$11:$H$20,"?*")=0,"","FAMÍLIA") | O40: =IF(COUNTIF('DADOS_CRIACAO'!$H$11:$H$20,"?*")=0,"","ESTADO")
D41: ='DADOS_CRIACAO'!$H$11 | O41: =IF(AND(ISTEXT('DADOS_CRIACAO'!$B$2),'DADOS_CRIACAO'!$B$2<>"",TRIM('DADOS_CRIACAO'!$B$2)='DADOS_CRIACAO'!$B$2,COUNTIF('DADOS_CRIACAO'!$B$2:$B$11,SUBSTITUTE(SUBSTITUTE(SUBSTITUTE('DADOS_CRIACAO'!$B$2,"~","~~"),"*","~*"),"?","~?"))=1,COUNTIF('DADOS_CRIACAO'!$H$2:$H$10,SUBSTITUTE(SUBSTITUTE(SUBSTITUTE('DADOS_CRIACAO'!$B$2,"~","~~"),"*","~*"),"?","~?"))=0),"Neutra","")
D42: ='DADOS_CRIACAO'!$H$12 | O42: =IF(AND(ISTEXT('DADOS_CRIACAO'!$B$3),'DADOS_CRIACAO'!$B$3<>"",TRIM('DADOS_CRIACAO'!$B$3)='DADOS_CRIACAO'!$B$3,COUNTIF('DADOS_CRIACAO'!$B$2:$B$11,SUBSTITUTE(SUBSTITUTE(SUBSTITUTE('DADOS_CRIACAO'!$B$3,"~","~~"),"*","~*"),"?","~?"))=1,COUNTIF('DADOS_CRIACAO'!$H$2:$H$10,SUBSTITUTE(SUBSTITUTE(SUBSTITUTE('DADOS_CRIACAO'!$B$3,"~","~~"),"*","~*"),"?","~?"))=0),"Neutra","")
D43: ='DADOS_CRIACAO'!$H$13 | O43: =IF(AND(ISTEXT('DADOS_CRIACAO'!$B$4),'DADOS_CRIACAO'!$B$4<>"",TRIM('DADOS_CRIACAO'!$B$4)='DADOS_CRIACAO'!$B$4,COUNTIF('DADOS_CRIACAO'!$B$2:$B$11,SUBSTITUTE(SUBSTITUTE(SUBSTITUTE('DADOS_CRIACAO'!$B$4,"~","~~"),"*","~*"),"?","~?"))=1,COUNTIF('DADOS_CRIACAO'!$H$2:$H$10,SUBSTITUTE(SUBSTITUTE(SUBSTITUTE('DADOS_CRIACAO'!$B$4,"~","~~"),"*","~*"),"?","~?"))=0),"Neutra","")
D44: ='DADOS_CRIACAO'!$H$14 | O44: =IF(AND(ISTEXT('DADOS_CRIACAO'!$B$5),'DADOS_CRIACAO'!$B$5<>"",TRIM('DADOS_CRIACAO'!$B$5)='DADOS_CRIACAO'!$B$5,COUNTIF('DADOS_CRIACAO'!$B$2:$B$11,SUBSTITUTE(SUBSTITUTE(SUBSTITUTE('DADOS_CRIACAO'!$B$5,"~","~~"),"*","~*"),"?","~?"))=1,COUNTIF('DADOS_CRIACAO'!$H$2:$H$10,SUBSTITUTE(SUBSTITUTE(SUBSTITUTE('DADOS_CRIACAO'!$B$5,"~","~~"),"*","~*"),"?","~?"))=0),"Neutra","")
D45: ='DADOS_CRIACAO'!$H$15 | O45: =IF(AND(ISTEXT('DADOS_CRIACAO'!$B$6),'DADOS_CRIACAO'!$B$6<>"",TRIM('DADOS_CRIACAO'!$B$6)='DADOS_CRIACAO'!$B$6,COUNTIF('DADOS_CRIACAO'!$B$2:$B$11,SUBSTITUTE(SUBSTITUTE(SUBSTITUTE('DADOS_CRIACAO'!$B$6,"~","~~"),"*","~*"),"?","~?"))=1,COUNTIF('DADOS_CRIACAO'!$H$2:$H$10,SUBSTITUTE(SUBSTITUTE(SUBSTITUTE('DADOS_CRIACAO'!$B$6,"~","~~"),"*","~*"),"?","~?"))=0),"Neutra","")
D46: ='DADOS_CRIACAO'!$H$16 | O46: =IF(AND(ISTEXT('DADOS_CRIACAO'!$B$7),'DADOS_CRIACAO'!$B$7<>"",TRIM('DADOS_CRIACAO'!$B$7)='DADOS_CRIACAO'!$B$7,COUNTIF('DADOS_CRIACAO'!$B$2:$B$11,SUBSTITUTE(SUBSTITUTE(SUBSTITUTE('DADOS_CRIACAO'!$B$7,"~","~~"),"*","~*"),"?","~?"))=1,COUNTIF('DADOS_CRIACAO'!$H$2:$H$10,SUBSTITUTE(SUBSTITUTE(SUBSTITUTE('DADOS_CRIACAO'!$B$7,"~","~~"),"*","~*"),"?","~?"))=0),"Neutra","")
D47: ='DADOS_CRIACAO'!$H$17 | O47: =IF(AND(ISTEXT('DADOS_CRIACAO'!$B$8),'DADOS_CRIACAO'!$B$8<>"",TRIM('DADOS_CRIACAO'!$B$8)='DADOS_CRIACAO'!$B$8,COUNTIF('DADOS_CRIACAO'!$B$2:$B$11,SUBSTITUTE(SUBSTITUTE(SUBSTITUTE('DADOS_CRIACAO'!$B$8,"~","~~"),"*","~*"),"?","~?"))=1,COUNTIF('DADOS_CRIACAO'!$H$2:$H$10,SUBSTITUTE(SUBSTITUTE(SUBSTITUTE('DADOS_CRIACAO'!$B$8,"~","~~"),"*","~*"),"?","~?"))=0),"Neutra","")
D48: ='DADOS_CRIACAO'!$H$18 | O48: =IF(AND(ISTEXT('DADOS_CRIACAO'!$B$9),'DADOS_CRIACAO'!$B$9<>"",TRIM('DADOS_CRIACAO'!$B$9)='DADOS_CRIACAO'!$B$9,COUNTIF('DADOS_CRIACAO'!$B$2:$B$11,SUBSTITUTE(SUBSTITUTE(SUBSTITUTE('DADOS_CRIACAO'!$B$9,"~","~~"),"*","~*"),"?","~?"))=1,COUNTIF('DADOS_CRIACAO'!$H$2:$H$10,SUBSTITUTE(SUBSTITUTE(SUBSTITUTE('DADOS_CRIACAO'!$B$9,"~","~~"),"*","~*"),"?","~?"))=0),"Neutra","")
D49: ='DADOS_CRIACAO'!$H$19 | O49: =IF(AND(ISTEXT('DADOS_CRIACAO'!$B$10),'DADOS_CRIACAO'!$B$10<>"",TRIM('DADOS_CRIACAO'!$B$10)='DADOS_CRIACAO'!$B$10,COUNTIF('DADOS_CRIACAO'!$B$2:$B$11,SUBSTITUTE(SUBSTITUTE(SUBSTITUTE('DADOS_CRIACAO'!$B$10,"~","~~"),"*","~*"),"?","~?"))=1,COUNTIF('DADOS_CRIACAO'!$H$2:$H$10,SUBSTITUTE(SUBSTITUTE(SUBSTITUTE('DADOS_CRIACAO'!$B$10,"~","~~"),"*","~*"),"?","~?"))=0),"Neutra","")
D50: ='DADOS_CRIACAO'!$H$20 | O50: =IF(AND(ISTEXT('DADOS_CRIACAO'!$B$11),'DADOS_CRIACAO'!$B$11<>"",TRIM('DADOS_CRIACAO'!$B$11)='DADOS_CRIACAO'!$B$11,COUNTIF('DADOS_CRIACAO'!$B$2:$B$11,SUBSTITUTE(SUBSTITUTE(SUBSTITUTE('DADOS_CRIACAO'!$B$11,"~","~~"),"*","~*"),"?","~?"))=1,COUNTIF('DADOS_CRIACAO'!$H$2:$H$10,SUBSTITUTE(SUBSTITUTE(SUBSTITUTE('DADOS_CRIACAO'!$B$11,"~","~~"),"*","~*"),"?","~?"))=0),"Neutra","")
D52: ORÇAMENTO
D54: MAIOR CLASSE | F54: ESPAÇOS | J54: DO LEQUE | L54: =DADOS_AM!$KV$20 | P54: EM TALENTOS | Q54: NO DOMÍNIO | R54: EM INVOCAÇÕES | S54: LIVRES
D55: =DADOS_AM!$HM$4 | F55: =DADOS_AM!$HM$13 | J55: =DADOS_AM!$KV$19 | L55: =DADOS_AM!$HM$14 | P55: =DADOS_AM!$KV$21 | Q55: =DADOS_AM!$KV$22 | R55: =DADOS_AM!$KV$23 | S55: =DADOS_AM!$KV$24
D58: PREÇOS DA | E58: PONTOS E PE | F58: LEVE | G58: MÉDIA | J58: PESADA | K58: DEVOLUÇÃO MÁX. | L58: TETO DE DADOS | M58: MELHORIAS | P58: CLASSE 0
D59: 1 | E59: =DADOS_AM!$KV$25 | F59: =DADOS_AM!$KV$26 | G59: =DADOS_AM!$KV$27 | J59: =DADOS_AM!$KV$28 | K59: =DADOS_AM!$KV$29 | L59: =DADOS_AM!$KV$30 | M59: =DADOS_AM!$KV$31 | P59: =DADOS_AM!$KV$32
D61: =DADOS_AM!$KV$33
D64: 1 | G64: =DADOS_AM!$GP$2 | J64: 1 | M64: =DADOS_AM!$GP$3 | P64: 1 | S64: =DADOS_AM!$GP$4
D65: COMO É | J65: COMO É | P65: COMO É
D71: Projétil | E71: =DADOS_AM!$GU$2 | F71: =DADOS_AM!$GR$2 | G71: =DADOS_AM!$GT$2 | J71: Projétil | K71: =DADOS_AM!$GU$3 | L71: =DADOS_AM!$GR$3 | M71: =DADOS_AM!$GT$3 | P71: Projétil | Q71: =DADOS_AM!$GU$4 | R71: =DADOS_AM!$GR$4 | S71: =DADOS_AM!$GT$4
...

Sheet INVOCAÇÕES
D2: 呪術 | E2: INVOCAÇÕES | O2: =FICHA!AB2
E4: =DADOS!$F$1&" · as entidades, a montagem e a mesa" | O4: =FICHA!AB4
A8: CICLO MALDITO
D9: O CONJUNTO | H9: 1 | I9: 1 | J9: =DADOS_INVOC!$HG$2 | AA9: 7 | AB9: 7 | AC9: =DADOS_INVOC!$HG$8
H11: =DADOS_INVOC!$HH$2 | AA11: =DADOS_INVOC!$HH$8
D12: SEU NÍVEL | E12: MAESTRIA | F12: TRILHA | I12: NOME | O12: NÍVEL | P12: CLASSE | Q12: MAESTRIA | R12: ENTRADA | S12: RETORNO | U12: VIDA ATUAL | V12: VIDA MÁXIMA | W12: TEMPORÁRIA | X12: ± PERDA / GANHO | Y12: =DADOS_INVOC!$IB$2 | AB12: NOME | AH12: NÍVEL | AI12: CLASSE | AJ12: MAESTRIA | AK12: ENTRADA | AL12: RETORNO | AN12: VIDA ATUAL | AO12: VIDA MÁXIMA | AP12: TEMPORÁRIA | AQ12: ± PERDA / GANHO | AR12: =DADOS_INVOC!$IB$8
D13: =DADOS_INVOC!$DB$2 | E13: =DADOS_INVOC!$QU$2 | F13: =DADOS_INVOC!$QU$3 | O13: =DADOS_INVOC!$FO$2 | P13: =DADOS_INVOC!$FP$2 | Q13: =DADOS_INVOC!$HI$2 | R13: =DADOS_INVOC!$HJ$2 | S13: =DADOS_INVOC!$HK$2 | U13: =DADOS_INVOC!$GG$2 | V13: =DADOS_INVOC!$GF$2 | AH13: =DADOS_INVOC!$FO$8 | AI13: =DADOS_INVOC!$FP$8 | AJ13: =DADOS_INVOC!$HI$8 | AK13: =DADOS_INVOC!$HJ$8 | AL13: =DADOS_INVOC!$HK$8 | AN13: =DADOS_INVOC!$GG$8 | AO13: =DADOS_INVOC!$GF$8
I15: FOTO 式神 | U15: =IFERROR(SPARKLINE(DADOS_INVOC!$GH$2,{"charttype","bar";"max",MAX(1,DADOS_INVOC!$GF$2);"color1",DADOS_INVOC!$DB$12}),"") | AB15: FOTO 式神 | AN15: =IFERROR(SPARKLINE(DADOS_INVOC!$GH$8,{"charttype","bar";"max",MAX(1,DADOS_INVOC!$GF$8);"color1",DADOS_INVOC!$DB$12}),"")
D16: DEFESA USA | E16: ATIVAS, NO MÁXIMO | F16: CORPOS MANTIDOS | O16: =DADOS_INVOC!$HL$2 | AH16: =DADOS_INVOC!$HL$8
D17: Essência | E17: =DADOS_INVOC!$DB$8 | F17: =DADOS_INVOC!$DB$9 | O17: FOR | P17: DES | Q17: CON | R17: INT | S17: ESS | U17: ALMA | V17: INTEGRIDADE ATUAL | W17: INTEGRIDADE MÁXIMA | X17: ESTÁGIO | AH17: FOR | AI17: DES | AJ17: CON | AK17: INT | AL17: ESS | AN17: ALMA | AO17: INTEGRIDADE ATUAL | AP17: INTEGRIDADE MÁXIMA | AQ17: ESTÁGIO
O18: =DADOS_INVOC!$FR$2 | P18: =DADOS_INVOC!$FS$2 | Q18: =DADOS_INVOC!$FT$2 | R18: =DADOS_INVOC!$FU$2 | S18: =DADOS_INVOC!$FV$2 | U18: Com alma | V18: =DADOS_INVOC!$GJ$2 | W18: =DADOS_INVOC!$GL$2 | X18: =DADOS_INVOC!$GM$2 | AH18: =DADOS_INVOC!$FR$8 | AI18: =DADOS_INVOC!$FS$8 | AJ18: =DADOS_INVOC!$FT$8 | AK18: =DADOS_INVOC!$FU$8 | AL18: =DADOS_INVOC!$FV$8 | AN18: Com alma | AO18: =DADOS_INVOC!$GJ$8 | AP18: =DADOS_INVOC!$GL$8 | AQ18: =DADOS_INVOC!$GM$8
D20: =DADOS_INVOC!$QU$4 | O20: 0 | P20: 0 | Q20: 0 | R20: 0 | S20: 0 | AH20: 0 | AI20: 0 | AJ20: 0 | AK20: 0 | AL20: 0
D21: =DADOS_INVOC!$JK$2 | O21: 0 | P21: 0 | Q21: 0 | R21: 0 | S21: 0 | U21: CONDIÇÕES E USOS GASTOS | AH21: 0 | AI21: 0 | AJ21: 0 | AK21: 0 | AL21: 0 | AN21: CONDIÇÕES E USOS GASTOS
D22: =DADOS_INVOC!$JK$3
D23: =DADOS_INVOC!$JK$4 | O23: ATAQUE | P23: CD | Q23: DEFESA | R23: VIDA MÁXIMA | S23: DESLOCAMENTO | AH23: ATAQUE | AI23: CD | AJ23: DEFESA | AK23: VIDA MÁXIMA | AL23: DESLOCAMENTO
D24: =DADOS_INVOC!$JK$5 | O24: =DADOS_INVOC!$HM$2 | P24: =DADOS_INVOC!$HN$2 | Q24: =DADOS_INVOC!$GD$2 | R24: =DADOS_INVOC!$GF$2 | S24: =DADOS_INVOC!$HO$2 | AH24: =DADOS_INVOC!$HM$8 | AI24: =DADOS_INVOC!$HN$8 | AJ24: =DADOS_INVOC!$GD$8 | AK24: =DADOS_INVOC!$GF$8 | AL24: =DADOS_INVOC!$HO$8
D25: =DADOS_INVOC!$JK$6
D26: =DADOS_INVOC!$JK$7 | O26: 0 | P26: 0 | Q26: 0 | R26: 0 | S26: 0 | U26: ANOTAÇÕES | AH26: 0 | AI26: 0 | AJ26: 0 | AK26: 0 | AL26: 0 | AN26: ANOTAÇÕES
D27: =DADOS_INVOC!$JK$8
D28: =DADOS_INVOC!$JK$9 | O28: FÍSICO | P28: VIGOR | Q28: INTELECTO | R28: ESPÍRITO | S28: TR TREINADO | AH28: FÍSICO | AI28: VIGOR | AJ28: INTELECTO | AK28: ESPÍRITO | AL28: TR TREINADO
D29: =DADOS_INVOC!$JK$10 | O29: =DADOS_INVOC!$HP$2 | P29: =DADOS_INVOC!$HQ$2 | Q29: =DADOS_INVOC!$HR$2 | R29: =DADOS_INVOC!$HS$2 | AH29: =DADOS_INVOC!$HP$8 | AI29: =DADOS_INVOC!$HQ$8 | AJ29: =DADOS_INVOC!$HR$8 | AK29: =DADOS_INVOC!$HS$8
D30: =DADOS_INVOC!$JK$11
D31: =DADOS_INVOC!$JK$12 | O31: 0 | P31: 0 | Q31: 0 | R31: 0 | AH31: 0 | AI31: 0 | AJ31: 0 | AK31: 0
D32: =DADOS_INVOC!$JK$13 | U32: =DADOS_INVOC!$IC$2 | Y32: VOL. | AN32: =DADOS_INVOC!$IC$8 | AR32: VOL.
A33: INVOCAÇÕES | O33: ATRIBUTO DE ACERTO | R33: FÍSICO USA | U33: MÃO 1 | AH33: ATRIBUTO DE ACERTO | AK33: FÍSICO USA | AN33: MÃO 1
R34: Força | U34: MÃO 2 | AK34: Força | AN34: MÃO 2
U35: VESTE | AN35: VESTE
U36: GUARDADO · SÓ COM A CARACTERÍSTICA DE TRANSPORTE | Y36: VOL. | AN36: GUARDADO · SÓ COM A CARACTERÍSTICA DE TRANSPORTE | AR36: VOL.
O37: =DADOS_INVOC!$HT$2 | AH37: =DADOS_INVOC!$HT$8
R38: =DADOS_INVOC!$HU$2 | AK38: =DADOS_INVOC!$HU$8
R39: =DADOS_INVOC!$HV$2 | AK39: =DADOS_INVOC!$HV$8
R40: =DADOS_INVOC!$HW$2 | AK40: =DADOS_INVOC!$HW$8
R41: =DADOS_INVOC!$HX$2 | AK41: =DADOS_INVOC!$HX$8
I42: TIPO | L42: OFÍCIO COMPATÍVEL | R42: =DADOS_INVOC!$HY$2 | AB42: TIPO | AE42: OFÍCIO COMPATÍVEL | AK42: =DADOS_INVOC!$HY$8
I43: Shikigami de técnica | R43: =DADOS_INVOC!$HZ$2 | AB43: Shikigami de técnica | AK43: =DADOS_INVOC!$HZ$8
R44: =DADOS_INVOC!$IA$2 | U44: CORPO, SENTIDOS E COMUNICAÇÃO | AK44: =DADOS_INVOC!$IA$8 | AN44: CORPO, SENTIDOS E COMUNICAÇÃO
I46: AQUISIÇÃO | K46: OBTIDA NO NÍVEL | L46: TALISMÃ | O46: =DADOS_INVOC!$ID$2 | AB46: AQUISIÇÃO | AD46: OBTIDA NO NÍVEL | AE46: TALISMÃ | AH46: =DADOS_INVOC!$ID$8
I47: Espaço conhecido | L47: Sem carga | O47: =IF(DADOS_INVOC!$RA$2>=1,"LIVRE","ABERTA") | P47: =IF(DADOS_INVOC!$RA$2>=2,"LIVRE","ABERTA") | Q47: =IF(DADOS_INVOC!$RA$2>=7,"LIVRE","ABERTA") | R47: =IF(DADOS_INVOC!$RA$2>=8,"LIVRE","ABERTA") | S47: =IF(DADOS_INVOC!$RA$2>=9,"LIVRE","ABERTA") | AB47: Espaço conhecido | AE47: Sem carga | AH47: =IF(DADOS_INVOC!$RA$8>=1,"LIVRE","ABERTA") | AI47: =IF(DADOS_INVOC!$RA$8>=2,"LIVRE","ABERTA") | AJ47: =IF(DADOS_INVOC!$RA$8>=7,"LIVRE","ABERTA") | AK47: =IF(DADOS_INVOC!$RA$8>=8,"LIVRE","ABERTA") | AL47: =IF(DADOS_INVOC!$RA$8>=9,"LIVRE","ABERTA")
O49: =IF(DADOS_INVOC!$RA$2>=3,"LIVRE 6","FAMÍLIA 6") | P49: =IF(DADOS_INVOC!$RA$2>=4,"LIVRE 7","FAMÍLIA 7") | Q49: =IF(DADOS_INVOC!$RA$2>=5,"LIVRE 8","FAMÍLIA 8") | R49: =IF(DADOS_INVOC!$RA$2>=6,"LIVRE 9","FAMÍLIA 9") | AH49: =IF(DADOS_INVOC!$RA$8>=3,"LIVRE 6","FAMÍLIA 6") | AI49: =IF(DADOS_INVOC!$RA$8>=4,"LIVRE 7","FAMÍLIA 7") | AJ49: =IF(DADOS_INVOC!$RA$8>=5,"LIVRE 8","FAMÍLIA 8") | AK49: =IF(DADOS_INVOC!$RA$8>=6,"LIVRE 9","FAMÍLIA 9")
I50: AUTONOMIA | K50: Autônoma | AB50: AUTONOMIA | AD50: Autônoma
...

Sheet FICHA PESSOAL
D2: 呪術 | H2: FICHA PESSOAL | AB2: =IF(OR(CARTEIRA!$O$9="",CARTEIRA!$O$9="Coloque o nome do personagem aqui"),"",CARTEIRA!$O$9)
H4: =DADOS!$F$1&" · pertences e histórico do portador" | AB4: =FICHA!AB4
A8: CICLO MALDITO | D8: DOSSIÊ | AW8: MISSÕES E XP | BI8: MAIS MISSÕES
D10: =CARTEIRA!$C$8 | Q10: NOME | AB10: GRAU | AI10: IDADE | AO10: ALTURA | AW10: XP TOTAL | BC10: =IF(DADOS!$CZ$48>=30,"NÍVEL MÁXIMO","FALTA PARA O NÍVEL "&(DADOS!$CZ$48+1))
Q11: =FICHA!AB2 | AB11: Grau 4 | AW11: =DADOS!$CZ$47 | BC11: =IF(DADOS!$CZ$49&""="","—",MAX(0,DADOS!$CZ$49-DADOS!$CZ$47)) | BE11: =IFERROR(SPARKLINE(MAX(0,DADOS!$CZ$47-DADOS!$CZ$50),{"charttype","bar";"max",MAX(1,N(DADOS!$CZ$49)-DADOS!$CZ$50);"color1",DADOS!$CZ$51}),"")
Q14: OLHOS | Y14: CABELO | AG14: PELE | AO14: GÊNERO | AW14: MISSÃO | AX14: XP | AY14: ADICIONAL | AZ14: DESCONTO | BA14: TOTAL | BC14: MISSÃO | BD14: XP | BE14: ADICIONAL | BF14: DESCONTO | BG14: TOTAL | BI14: MISSÃO | BJ14: XP | BK14: ADICIONAL | BL14: DESCONTO | BM14: TOTAL | BO14: MISSÃO | BP14: XP | BQ14: ADICIONAL | BR14: DESCONTO | BS14: TOTAL
BA15: =IF($AX15="","",IFERROR(IF(ROUND(VLOOKUP($AX15,DADOS!$CL$5:$CM$10,2,FALSE)*IF($AY15="",1,VLOOKUP($AY15,DADOS!$CO$5:$CP$7,2,FALSE))*IF($AZ15="",1,VLOOKUP($AZ15,DADOS!$CR$5:$CS$15,2,FALSE)),4)>0,MAX(1,FLOOR(ROUND(VLOOKUP($AX15,DADOS!$CL$5:$CM$10,2,FALSE)*IF($AY15="",1,VLOOKUP($AY15,DADOS!$CO$5:$CP$7,2,FALSE))*IF($AZ15="",1,VLOOKUP($AZ15,DADOS!$CR$5:$CS$15,2,FALSE)),4),1)),0),"")) | BG15: =IF($BD15="","",IFERROR(IF(ROUND(VLOOKUP($BD15,DADOS!$CL$5:$CM$10,2,FALSE)*IF($BE15="",1,VLOOKUP($BE15,DADOS!$CO$5:$CP$7,2,FALSE))*IF($BF15="",1,VLOOKUP($BF15,DADOS!$CR$5:$CS$15,2,FALSE)),4)>0,MAX(1,FLOOR(ROUND(VLOOKUP($BD15,DADOS!$CL$5:$CM$10,2,FALSE)*IF($BE15="",1,VLOOKUP($BE15,DADOS!$CO$5:$CP$7,2,FALSE))*IF($BF15="",1,VLOOKUP($BF15,DADOS!$CR$5:$CS$15,2,FALSE)),4),1)),0),"")) | BM15: =IF($BJ15="","",IFERROR(IF(ROUND(VLOOKUP($BJ15,DADOS!$CL$5:$CM$10,2,FALSE)*IF($BK15="",1,VLOOKUP($BK15,DADOS!$CO$5:$CP$7,2,FALSE))*IF($BL15="",1,VLOOKUP($BL15,DADOS!$CR$5:$CS$15,2,FALSE)),4)>0,MAX(1,FLOOR(ROUND(VLOOKUP($BJ15,DADOS!$CL$5:$CM$10,2,FALSE)*IF($BK15="",1,VLOOKUP($BK15,DADOS!$CO$5:$CP$7,2,FALSE))*IF($BL15="",1,VLOOKUP($BL15,DADOS!$CR$5:$CS$15,2,FALSE)),4),1)),0),"")) | BS15: =IF($BP15="","",IFERROR(IF(ROUND(VLOOKUP($BP15,DADOS!$CL$5:$CM$10,2,FALSE)*IF($BQ15="",1,VLOOKUP($BQ15,DADOS!$CO$5:$CP$7,2,FALSE))*IF($BR15="",1,VLOOKUP($BR15,DADOS!$CR$5:$CS$15,2,FALSE)),4)>0,MAX(1,FLOOR(ROUND(VLOOKUP($BP15,DADOS!$CL$5:$CM$10,2,FALSE)*IF($BQ15="",1,VLOOKUP($BQ15,DADOS!$CO$5:$CP$7,2,FALSE))*IF($BR15="",1,VLOOKUP($BR15,DADOS!$CR$5:$CS$15,2,FALSE)),4),1)),0),""))
BA16: =IF($AX16="","",IFERROR(IF(ROUND(VLOOKUP($AX16,DADOS!$CL$5:$CM$10,2,FALSE)*IF($AY16="",1,VLOOKUP($AY16,DADOS!$CO$5:$CP$7,2,FALSE))*IF($AZ16="",1,VLOOKUP($AZ16,DADOS!$CR$5:$CS$15,2,FALSE)),4)>0,MAX(1,FLOOR(ROUND(VLOOKUP($AX16,DADOS!$CL$5:$CM$10,2,FALSE)*IF($AY16="",1,VLOOKUP($AY16,DADOS!$CO$5:$CP$7,2,FALSE))*IF($AZ16="",1,VLOOKUP($AZ16,DADOS!$CR$5:$CS$15,2,FALSE)),4),1)),0),"")) | BG16: =IF($BD16="","",IFERROR(IF(ROUND(VLOOKUP($BD16,DADOS!$CL$5:$CM$10,2,FALSE)*IF($BE16="",1,VLOOKUP($BE16,DADOS!$CO$5:$CP$7,2,FALSE))*IF($BF16="",1,VLOOKUP($BF16,DADOS!$CR$5:$CS$15,2,FALSE)),4)>0,MAX(1,FLOOR(ROUND(VLOOKUP($BD16,DADOS!$CL$5:$CM$10,2,FALSE)*IF($BE16="",1,VLOOKUP($BE16,DADOS!$CO$5:$CP$7,2,FALSE))*IF($BF16="",1,VLOOKUP($BF16,DADOS!$CR$5:$CS$15,2,FALSE)),4),1)),0),"")) | BM16: =IF($BJ16="","",IFERROR(IF(ROUND(VLOOKUP($BJ16,DADOS!$CL$5:$CM$10,2,FALSE)*IF($BK16="",1,VLOOKUP($BK16,DADOS!$CO$5:$CP$7,2,FALSE))*IF($BL16="",1,VLOOKUP($BL16,DADOS!$CR$5:$CS$15,2,FALSE)),4)>0,MAX(1,FLOOR(ROUND(VLOOKUP($BJ16,DADOS!$CL$5:$CM$10,2,FALSE)*IF($BK16="",1,VLOOKUP($BK16,DADOS!$CO$5:$CP$7,2,FALSE))*IF($BL16="",1,VLOOKUP($BL16,DADOS!$CR$5:$CS$15,2,FALSE)),4),1)),0),"")) | BS16: =IF($BP16="","",IFERROR(IF(ROUND(VLOOKUP($BP16,DADOS!$CL$5:$CM$10,2,FALSE)*IF($BQ16="",1,VLOOKUP($BQ16,DADOS!$CO$5:$CP$7,2,FALSE))*IF($BR16="",1,VLOOKUP($BR16,DADOS!$CR$5:$CS$15,2,FALSE)),4)>0,MAX(1,FLOOR(ROUND(VLOOKUP($BP16,DADOS!$CL$5:$CM$10,2,FALSE)*IF($BQ16="",1,VLOOKUP($BQ16,DADOS!$CO$5:$CP$7,2,FALSE))*IF($BR16="",1,VLOOKUP($BR16,DADOS!$CR$5:$CS$15,2,FALSE)),4),1)),0),""))
BA17: =IF($AX17="","",IFERROR(IF(ROUND(VLOOKUP($AX17,DADOS!$CL$5:$CM$10,2,FALSE)*IF($AY17="",1,VLOOKUP($AY17,DADOS!$CO$5:$CP$7,2,FALSE))*IF($AZ17="",1,VLOOKUP($AZ17,DADOS!$CR$5:$CS$15,2,FALSE)),4)>0,MAX(1,FLOOR(ROUND(VLOOKUP($AX17,DADOS!$CL$5:$CM$10,2,FALSE)*IF($AY17="",1,VLOOKUP($AY17,DADOS!$CO$5:$CP$7,2,FALSE))*IF($AZ17="",1,VLOOKUP($AZ17,DADOS!$CR$5:$CS$15,2,FALSE)),4),1)),0),"")) | BG17: =IF($BD17="","",IFERROR(IF(ROUND(VLOOKUP($BD17,DADOS!$CL$5:$CM$10,2,FALSE)*IF($BE17="",1,VLOOKUP($BE17,DADOS!$CO$5:$CP$7,2,FALSE))*IF($BF17="",1,VLOOKUP($BF17,DADOS!$CR$5:$CS$15,2,FALSE)),4)>0,MAX(1,FLOOR(ROUND(VLOOKUP($BD17,DADOS!$CL$5:$CM$10,2,FALSE)*IF($BE17="",1,VLOOKUP($BE17,DADOS!$CO$5:$CP$7,2,FALSE))*IF($BF17="",1,VLOOKUP($BF17,DADOS!$CR$5:$CS$15,2,FALSE)),4),1)),0),"")) | BM17: =IF($BJ17="","",IFERROR(IF(ROUND(VLOOKUP($BJ17,DADOS!$CL$5:$CM$10,2,FALSE)*IF($BK17="",1,VLOOKUP($BK17,DADOS!$CO$5:$CP$7,2,FALSE))*IF($BL17="",1,VLOOKUP($BL17,DADOS!$CR$5:$CS$15,2,FALSE)),4)>0,MAX(1,FLOOR(ROUND(VLOOKUP($BJ17,DADOS!$CL$5:$CM$10,2,FALSE)*IF($BK17="",1,VLOOKUP($BK17,DADOS!$CO$5:$CP$7,2,FALSE))*IF($BL17="",1,VLOOKUP($BL17,DADOS!$CR$5:$CS$15,2,FALSE)),4),1)),0),"")) | BS17: =IF($BP17="","",IFERROR(IF(ROUND(VLOOKUP($BP17,DADOS!$CL$5:$CM$10,2,FALSE)*IF($BQ17="",1,VLOOKUP($BQ17,DADOS!$CO$5:$CP$7,2,FALSE))*IF($BR17="",1,VLOOKUP($BR17,DADOS!$CR$5:$CS$15,2,FALSE)),4)>0,MAX(1,FLOOR(ROUND(VLOOKUP($BP17,DADOS!$CL$5:$CM$10,2,FALSE)*IF($BQ17="",1,VLOOKUP($BQ17,DADOS!$CO$5:$CP$7,2,FALSE))*IF($BR17="",1,VLOOKUP($BR17,DADOS!$CR$5:$CS$15,2,FALSE)),4),1)),0),""))
Q18: APARÊNCIA | AI18: CICATRIZES | BA18: =IF($AX18="","",IFERROR(IF(ROUND(VLOOKUP($AX18,DADOS!$CL$5:$CM$10,2,FALSE)*IF($AY18="",1,VLOOKUP($AY18,DADOS!$CO$5:$CP$7,2,FALSE))*IF($AZ18="",1,VLOOKUP($AZ18,DADOS!$CR$5:$CS$15,2,FALSE)),4)>0,MAX(1,FLOOR(ROUND(VLOOKUP($AX18,DADOS!$CL$5:$CM$10,2,FALSE)*IF($AY18="",1,VLOOKUP($AY18,DADOS!$CO$5:$CP$7,2,FALSE))*IF($AZ18="",1,VLOOKUP($AZ18,DADOS!$CR$5:$CS$15,2,FALSE)),4),1)),0),"")) | BG18: =IF($BD18="","",IFERROR(IF(ROUND(VLOOKUP($BD18,DADOS!$CL$5:$CM$10,2,FALSE)*IF($BE18="",1,VLOOKUP($BE18,DADOS!$CO$5:$CP$7,2,FALSE))*IF($BF18="",1,VLOOKUP($BF18,DADOS!$CR$5:$CS$15,2,FALSE)),4)>0,MAX(1,FLOOR(ROUND(VLOOKUP($BD18,DADOS!$CL$5:$CM$10,2,FALSE)*IF($BE18="",1,VLOOKUP($BE18,DADOS!$CO$5:$CP$7,2,FALSE))*IF($BF18="",1,VLOOKUP($BF18,DADOS!$CR$5:$CS$15,2,FALSE)),4),1)),0),"")) | BM18: =IF($BJ18="","",IFERROR(IF(ROUND(VLOOKUP($BJ18,DADOS!$CL$5:$CM$10,2,FALSE)*IF($BK18="",1,VLOOKUP($BK18,DADOS!$CO$5:$CP$7,2,FALSE))*IF($BL18="",1,VLOOKUP($BL18,DADOS!$CR$5:$CS$15,2,FALSE)),4)>0,MAX(1,FLOOR(ROUND(VLOOKUP($BJ18,DADOS!$CL$5:$CM$10,2,FALSE)*IF($BK18="",1,VLOOKUP($BK18,DADOS!$CO$5:$CP$7,2,FALSE))*IF($BL18="",1,VLOOKUP($BL18,DADOS!$CR$5:$CS$15,2,FALSE)),4),1)),0),"")) | BS18: =IF($BP18="","",IFERROR(IF(ROUND(VLOOKUP($BP18,DADOS!$CL$5:$CM$10,2,FALSE)*IF($BQ18="",1,VLOOKUP($BQ18,DADOS!$CO$5:$CP$7,2,FALSE))*IF($BR18="",1,VLOOKUP($BR18,DADOS!$CR$5:$CS$15,2,FALSE)),4)>0,MAX(1,FLOOR(ROUND(VLOOKUP($BP18,DADOS!$CL$5:$CM$10,2,FALSE)*IF($BQ18="",1,VLOOKUP($BQ18,DADOS!$CO$5:$CP$7,2,FALSE))*IF($BR18="",1,VLOOKUP($BR18,DADOS!$CR$5:$CS$15,2,FALSE)),4),1)),0),""))
BA19: =IF($AX19="","",IFERROR(IF(ROUND(VLOOKUP($AX19,DADOS!$CL$5:$CM$10,2,FALSE)*IF($AY19="",1,VLOOKUP($AY19,DADOS!$CO$5:$CP$7,2,FALSE))*IF($AZ19="",1,VLOOKUP($AZ19,DADOS!$CR$5:$CS$15,2,FALSE)),4)>0,MAX(1,FLOOR(ROUND(VLOOKUP($AX19,DADOS!$CL$5:$CM$10,2,FALSE)*IF($AY19="",1,VLOOKUP($AY19,DADOS!$CO$5:$CP$7,2,FALSE))*IF($AZ19="",1,VLOOKUP($AZ19,DADOS!$CR$5:$CS$15,2,FALSE)),4),1)),0),"")) | BG19: =IF($BD19="","",IFERROR(IF(ROUND(VLOOKUP($BD19,DADOS!$CL$5:$CM$10,2,FALSE)*IF($BE19="",1,VLOOKUP($BE19,DADOS!$CO$5:$CP$7,2,FALSE))*IF($BF19="",1,VLOOKUP($BF19,DADOS!$CR$5:$CS$15,2,FALSE)),4)>0,MAX(1,FLOOR(ROUND(VLOOKUP($BD19,DADOS!$CL$5:$CM$10,2,FALSE)*IF($BE19="",1,VLOOKUP($BE19,DADOS!$CO$5:$CP$7,2,FALSE))*IF($BF19="",1,VLOOKUP($BF19,DADOS!$CR$5:$CS$15,2,FALSE)),4),1)),0),"")) | BM19: =IF($BJ19="","",IFERROR(IF(ROUND(VLOOKUP($BJ19,DADOS!$CL$5:$CM$10,2,FALSE)*IF($BK19="",1,VLOOKUP($BK19,DADOS!$CO$5:$CP$7,2,FALSE))*IF($BL19="",1,VLOOKUP($BL19,DADOS!$CR$5:$CS$15,2,FALSE)),4)>0,MAX(1,FLOOR(ROUND(VLOOKUP($BJ19,DADOS!$CL$5:$CM$10,2,FALSE)*IF($BK19="",1,VLOOKUP($BK19,DADOS!$CO$5:$CP$7,2,FALSE))*IF($BL19="",1,VLOOKUP($BL19,DADOS!$CR$5:$CS$15,2,FALSE)),4),1)),0),"")) | BS19: =IF($BP19="","",IFERROR(IF(ROUND(VLOOKUP($BP19,DADOS!$CL$5:$CM$10,2,FALSE)*IF($BQ19="",1,VLOOKUP($BQ19,DADOS!$CO$5:$CP$7,2,FALSE))*IF($BR19="",1,VLOOKUP($BR19,DADOS!$CR$5:$CS$15,2,FALSE)),4)>0,MAX(1,FLOOR(ROUND(VLOOKUP($BP19,DADOS!$CL$5:$CM$10,2,FALSE)*IF($BQ19="",1,VLOOKUP($BQ19,DADOS!$CO$5:$CP$7,2,FALSE))*IF($BR19="",1,VLOOKUP($BR19,DADOS!$CR$5:$CS$15,2,FALSE)),4),1)),0),""))
BA20: =IF($AX20="","",IFERROR(IF(ROUND(VLOOKUP($AX20,DADOS!$CL$5:$CM$10,2,FALSE)*IF($AY20="",1,VLOOKUP($AY20,DADOS!$CO$5:$CP$7,2,FALSE))*IF($AZ20="",1,VLOOKUP($AZ20,DADOS!$CR$5:$CS$15,2,FALSE)),4)>0,MAX(1,FLOOR(ROUND(VLOOKUP($AX20,DADOS!$CL$5:$CM$10,2,FALSE)*IF($AY20="",1,VLOOKUP($AY20,DADOS!$CO$5:$CP$7,2,FALSE))*IF($AZ20="",1,VLOOKUP($AZ20,DADOS!$CR$5:$CS$15,2,FALSE)),4),1)),0),"")) | BG20: =IF($BD20="","",IFERROR(IF(ROUND(VLOOKUP($BD20,DADOS!$CL$5:$CM$10,2,FALSE)*IF($BE20="",1,VLOOKUP($BE20,DADOS!$CO$5:$CP$7,2,FALSE))*IF($BF20="",1,VLOOKUP($BF20,DADOS!$CR$5:$CS$15,2,FALSE)),4)>0,MAX(1,FLOOR(ROUND(VLOOKUP($BD20,DADOS!$CL$5:$CM$10,2,FALSE)*IF($BE20="",1,VLOOKUP($BE20,DADOS!$CO$5:$CP$7,2,FALSE))*IF($BF20="",1,VLOOKUP($BF20,DADOS!$CR$5:$CS$15,2,FALSE)),4),1)),0),"")) | BM20: =IF($BJ20="","",IFERROR(IF(ROUND(VLOOKUP($BJ20,DADOS!$CL$5:$CM$10,2,FALSE)*IF($BK20="",1,VLOOKUP($BK20,DADOS!$CO$5:$CP$7,2,FALSE))*IF($BL20="",1,VLOOKUP($BL20,DADOS!$CR$5:$CS$15,2,FALSE)),4)>0,MAX(1,FLOOR(ROUND(VLOOKUP($BJ20,DADOS!$CL$5:$CM$10,2,FALSE)*IF($BK20="",1,VLOOKUP($BK20,DADOS!$CO$5:$CP$7,2,FALSE))*IF($BL20="",1,VLOOKUP($BL20,DADOS!$CR$5:$CS$15,2,FALSE)),4),1)),0),"")) | BS20: =IF($BP20="","",IFERROR(IF(ROUND(VLOOKUP($BP20,DADOS!$CL$5:$CM$10,2,FALSE)*IF($BQ20="",1,VLOOKUP($BQ20,DADOS!$CO$5:$CP$7,2,FALSE))*IF($BR20="",1,VLOOKUP($BR20,DADOS!$CR$5:$CS$15,2,FALSE)),4)>0,MAX(1,FLOOR(ROUND(VLOOKUP($BP20,DADOS!$CL$5:$CM$10,2,FALSE)*IF($BQ20="",1,VLOOKUP($BQ20,DADOS!$CO$5:$CP$7,2,FALSE))*IF($BR20="",1,VLOOKUP($BR20,DADOS!$CR$5:$CS$15,2,FALSE)),4),1)),0),""))
BA21: =IF($AX21="","",IFERROR(IF(ROUND(VLOOKUP($AX21,DADOS!$CL$5:$CM$10,2,FALSE)*IF($AY21="",1,VLOOKUP($AY21,DADOS!$CO$5:$CP$7,2,FALSE))*IF($AZ21="",1,VLOOKUP($AZ21,DADOS!$CR$5:$CS$15,2,FALSE)),4)>0,MAX(1,FLOOR(ROUND(VLOOKUP($AX21,DADOS!$CL$5:$CM$10,2,FALSE)*IF($AY21="",1,VLOOKUP($AY21,DADOS!$CO$5:$CP$7,2,FALSE))*IF($AZ21="",1,VLOOKUP($AZ21,DADOS!$CR$5:$CS$15,2,FALSE)),4),1)),0),"")) | BG21: =IF($BD21="","",IFERROR(IF(ROUND(VLOOKUP($BD21,DADOS!$CL$5:$CM$10,2,FALSE)*IF($BE21="",1,VLOOKUP($BE21,DADOS!$CO$5:$CP$7,2,FALSE))*IF($BF21="",1,VLOOKUP($BF21,DADOS!$CR$5:$CS$15,2,FALSE)),4)>0,MAX(1,FLOOR(ROUND(VLOOKUP($BD21,DADOS!$CL$5:$CM$10,2,FALSE)*IF($BE21="",1,VLOOKUP($BE21,DADOS!$CO$5:$CP$7,2,FALSE))*IF($BF21="",1,VLOOKUP($BF21,DADOS!$CR$5:$CS$15,2,FALSE)),4),1)),0),"")) | BM21: =IF($BJ21="","",IFERROR(IF(ROUND(VLOOKUP($BJ21,DADOS!$CL$5:$CM$10,2,FALSE)*IF($BK21="",1,VLOOKUP($BK21,DADOS!$CO$5:$CP$7,2,FALSE))*IF($BL21="",1,VLOOKUP($BL21,DADOS!$CR$5:$CS$15,2,FALSE)),4)>0,MAX(1,FLOOR(ROUND(VLOOKUP($BJ21,DADOS!$CL$5:$CM$10,2,FALSE)*IF($BK21="",1,VLOOKUP($BK21,DADOS!$CO$5:$CP$7,2,FALSE))*IF($BL21="",1,VLOOKUP($BL21,DADOS!$CR$5:$CS$15,2,FALSE)),4),1)),0),"")) | BS21: =IF($BP21="","",IFERROR(IF(ROUND(VLOOKUP($BP21,DADOS!$CL$5:$CM$10,2,FALSE)*IF($BQ21="",1,VLOOKUP($BQ21,DADOS!$CO$5:$CP$7,2,FALSE))*IF($BR21="",1,VLOOKUP($BR21,DADOS!$CR$5:$CS$15,2,FALSE)),4)>0,MAX(1,FLOOR(ROUND(VLOOKUP($BP21,DADOS!$CL$5:$CM$10,2,FALSE)*IF($BQ21="",1,VLOOKUP($BQ21,DADOS!$CO$5:$CP$7,2,FALSE))*IF($BR21="",1,VLOOKUP($BR21,DADOS!$CR$5:$CS$15,2,FALSE)),4),1)),0),""))
Q22: TRAÇO · UMA FRASE DA SUA HISTÓRIA | BA22: =IF($AX22="","",IFERROR(IF(ROUND(VLOOKUP($AX22,DADOS!$CL$5:$CM$10,2,FALSE)*IF($AY22="",1,VLOOKUP($AY22,DADOS!$CO$5:$CP$7,2,FALSE))*IF($AZ22="",1,VLOOKUP($AZ22,DADOS!$CR$5:$CS$15,2,FALSE)),4)>0,MAX(1,FLOOR(ROUND(VLOOKUP($AX22,DADOS!$CL$5:$CM$10,2,FALSE)*IF($AY22="",1,VLOOKUP($AY22,DADOS!$CO$5:$CP$7,2,FALSE))*IF($AZ22="",1,VLOOKUP($AZ22,DADOS!$CR$5:$CS$15,2,FALSE)),4),1)),0),"")) | BG22: =IF($BD22="","",IFERROR(IF(ROUND(VLOOKUP($BD22,DADOS!$CL$5:$CM$10,2,FALSE)*IF($BE22="",1,VLOOKUP($BE22,DADOS!$CO$5:$CP$7,2,FALSE))*IF($BF22="",1,VLOOKUP($BF22,DADOS!$CR$5:$CS$15,2,FALSE)),4)>0,MAX(1,FLOOR(ROUND(VLOOKUP($BD22,DADOS!$CL$5:$CM$10,2,FALSE)*IF($BE22="",1,VLOOKUP($BE22,DADOS!$CO$5:$CP$7,2,FALSE))*IF($BF22="",1,VLOOKUP($BF22,DADOS!$CR$5:$CS$15,2,FALSE)),4),1)),0),"")) | BM22: =IF($BJ22="","",IFERROR(IF(ROUND(VLOOKUP($BJ22,DADOS!$CL$5:$CM$10,2,FALSE)*IF($BK22="",1,VLOOKUP($BK22,DADOS!$CO$5:$CP$7,2,FALSE))*IF($BL22="",1,VLOOKUP($BL22,DADOS!$CR$5:$CS$15,2,FALSE)),4)>0,MAX(1,FLOOR(ROUND(VLOOKUP($BJ22,DADOS!$CL$5:$CM$10,2,FALSE)*IF($BK22="",1,VLOOKUP($BK22,DADOS!$CO$5:$CP$7,2,FALSE))*IF($BL22="",1,VLOOKUP($BL22,DADOS!$CR$5:$CS$15,2,FALSE)),4),1)),0),"")) | BS22: =IF($BP22="","",IFERROR(IF(ROUND(VLOOKUP($BP22,DADOS!$CL$5:$CM$10,2,FALSE)*IF($BQ22="",1,VLOOKUP($BQ22,DADOS!$CO$5:$CP$7,2,FALSE))*IF($BR22="",1,VLOOKUP($BR22,DADOS!$CR$5:$CS$15,2,FALSE)),4)>0,MAX(1,FLOOR(ROUND(VLOOKUP($BP22,DADOS!$CL$5:$CM$10,2,FALSE)*IF($BQ22="",1,VLOOKUP($BQ22,DADOS!$CO$5:$CP$7,2,FALSE))*IF($BR22="",1,VLOOKUP($BR22,DADOS!$CR$5:$CS$15,2,FALSE)),4),1)),0),""))
BA23: =IF($AX23="","",IFERROR(IF(ROUND(VLOOKUP($AX23,DADOS!$CL$5:$CM$10,2,FALSE)*IF($AY23="",1,VLOOKUP($AY23,DADOS!$CO$5:$CP$7,2,FALSE))*IF($AZ23="",1,VLOOKUP($AZ23,DADOS!$CR$5:$CS$15,2,FALSE)),4)>0,MAX(1,FLOOR(ROUND(VLOOKUP($AX23,DADOS!$CL$5:$CM$10,2,FALSE)*IF($AY23="",1,VLOOKUP($AY23,DADOS!$CO$5:$CP$7,2,FALSE))*IF($AZ23="",1,VLOOKUP($AZ23,DADOS!$CR$5:$CS$15,2,FALSE)),4),1)),0),"")) | BG23: =IF($BD23="","",IFERROR(IF(ROUND(VLOOKUP($BD23,DADOS!$CL$5:$CM$10,2,FALSE)*IF($BE23="",1,VLOOKUP($BE23,DADOS!$CO$5:$CP$7,2,FALSE))*IF($BF23="",1,VLOOKUP($BF23,DADOS!$CR$5:$CS$15,2,FALSE)),4)>0,MAX(1,FLOOR(ROUND(VLOOKUP($BD23,DADOS!$CL$5:$CM$10,2,FALSE)*IF($BE23="",1,VLOOKUP($BE23,DADOS!$CO$5:$CP$7,2,FALSE))*IF($BF23="",1,VLOOKUP($BF23,DADOS!$CR$5:$CS$15,2,FALSE)),4),1)),0),"")) | BM23: =IF($BJ23="","",IFERROR(IF(ROUND(VLOOKUP($BJ23,DADOS!$CL$5:$CM$10,2,FALSE)*IF($BK23="",1,VLOOKUP($BK23,DADOS!$CO$5:$CP$7,2,FALSE))*IF($BL23="",1,VLOOKUP($BL23,DADOS!$CR$5:$CS$15,2,FALSE)),4)>0,MAX(1,FLOOR(ROUND(VLOOKUP($BJ23,DADOS!$CL$5:$CM$10,2,FALSE)*IF($BK23="",1,VLOOKUP($BK23,DADOS!$CO$5:$CP$7,2,FALSE))*IF($BL23="",1,VLOOKUP($BL23,DADOS!$CR$5:$CS$15,2,FALSE)),4),1)),0),"")) | BS23: =IF($BP23="","",IFERROR(IF(ROUND(VLOOKUP($BP23,DADOS!$CL$5:$CM$10,2,FALSE)*IF($BQ23="",1,VLOOKUP($BQ23,DADOS!$CO$5:$CP$7,2,FALSE))*IF($BR23="",1,VLOOKUP($BR23,DADOS!$CR$5:$CS$15,2,FALSE)),4)>0,MAX(1,FLOOR(ROUND(VLOOKUP($BP23,DADOS!$CL$5:$CM$10,2,FALSE)*IF($BQ23="",1,VLOOKUP($BQ23,DADOS!$CO$5:$CP$7,2,FALSE))*IF($BR23="",1,VLOOKUP($BR23,DADOS!$CR$5:$CS$15,2,FALSE)),4),1)),0),""))
BA24: =IF($AX24="","",IFERROR(IF(ROUND(VLOOKUP($AX24,DADOS!$CL$5:$CM$10,2,FALSE)*IF($AY24="",1,VLOOKUP($AY24,DADOS!$CO$5:$CP$7,2,FALSE))*IF($AZ24="",1,VLOOKUP($AZ24,DADOS!$CR$5:$CS$15,2,FALSE)),4)>0,MAX(1,FLOOR(ROUND(VLOOKUP($AX24,DADOS!$CL$5:$CM$10,2,FALSE)*IF($AY24="",1,VLOOKUP($AY24,DADOS!$CO$5:$CP$7,2,FALSE))*IF($AZ24="",1,VLOOKUP($AZ24,DADOS!$CR$5:$CS$15,2,FALSE)),4),1)),0),"")) | BG24: =IF($BD24="","",IFERROR(IF(ROUND(VLOOKUP($BD24,DADOS!$CL$5:$CM$10,2,FALSE)*IF($BE24="",1,VLOOKUP($BE24,DADOS!$CO$5:$CP$7,2,FALSE))*IF($BF24="",1,VLOOKUP($BF24,DADOS!$CR$5:$CS$15,2,FALSE)),4)>0,MAX(1,FLOOR(ROUND(VLOOKUP($BD24,DADOS!$CL$5:$CM$10,2,FALSE)*IF($BE24="",1,VLOOKUP($BE24,DADOS!$CO$5:$CP$7,2,FALSE))*IF($BF24="",1,VLOOKUP($BF24,DADOS!$CR$5:$CS$15,2,FALSE)),4),1)),0),"")) | BM24: =IF($BJ24="","",IFERROR(IF(ROUND(VLOOKUP($BJ24,DADOS!$CL$5:$CM$10,2,FALSE)*IF($BK24="",1,VLOOKUP($BK24,DADOS!$CO$5:$CP$7,2,FALSE))*IF($BL24="",1,VLOOKUP($BL24,DADOS!$CR$5:$CS$15,2,FALSE)),4)>0,MAX(1,FLOOR(ROUND(VLOOKUP($BJ24,DADOS!$CL$5:$CM$10,2,FALSE)*IF($BK24="",1,VLOOKUP($BK24,DADOS!$CO$5:$CP$7,2,FALSE))*IF($BL24="",1,VLOOKUP($BL24,DADOS!$CR$5:$CS$15,2,FALSE)),4),1)),0),"")) | BS24: =IF($BP24="","",IFERROR(IF(ROUND(VLOOKUP($BP24,DADOS!$CL$5:$CM$10,2,FALSE)*IF($BQ24="",1,VLOOKUP($BQ24,DADOS!$CO$5:$CP$7,2,FALSE))*IF($BR24="",1,VLOOKUP($BR24,DADOS!$CR$5:$CS$15,2,FALSE)),4)>0,MAX(1,FLOOR(ROUND(VLOOKUP($BP24,DADOS!$CL$5:$CM$10,2,FALSE)*IF($BQ24="",1,VLOOKUP($BQ24,DADOS!$CO$5:$CP$7,2,FALSE))*IF($BR24="",1,VLOOKUP($BR24,DADOS!$CR$5:$CS$15,2,FALSE)),4),1)),0),""))
BA25: =IF($AX25="","",IFERROR(IF(ROUND(VLOOKUP($AX25,DADOS!$CL$5:$CM$10,2,FALSE)*IF($AY25="",1,VLOOKUP($AY25,DADOS!$CO$5:$CP$7,2,FALSE))*IF($AZ25="",1,VLOOKUP($AZ25,DADOS!$CR$5:$CS$15,2,FALSE)),4)>0,MAX(1,FLOOR(ROUND(VLOOKUP($AX25,DADOS!$CL$5:$CM$10,2,FALSE)*IF($AY25="",1,VLOOKUP($AY25,DADOS!$CO$5:$CP$7,2,FALSE))*IF($AZ25="",1,VLOOKUP($AZ25,DADOS!$CR$5:$CS$15,2,FALSE)),4),1)),0),"")) | BG25: =IF($BD25="","",IFERROR(IF(ROUND(VLOOKUP($BD25,DADOS!$CL$5:$CM$10,2,FALSE)*IF($BE25="",1,VLOOKUP($BE25,DADOS!$CO$5:$CP$7,2,FALSE))*IF($BF25="",1,VLOOKUP($BF25,DADOS!$CR$5:$CS$15,2,FALSE)),4)>0,MAX(1,FLOOR(ROUND(VLOOKUP($BD25,DADOS!$CL$5:$CM$10,2,FALSE)*IF($BE25="",1,VLOOKUP($BE25,DADOS!$CO$5:$CP$7,2,FALSE))*IF($BF25="",1,VLOOKUP($BF25,DADOS!$CR$5:$CS$15,2,FALSE)),4),1)),0),"")) | BM25: =IF($BJ25="","",IFERROR(IF(ROUND(VLOOKUP($BJ25,DADOS!$CL$5:$CM$10,2,FALSE)*IF($BK25="",1,VLOOKUP($BK25,DADOS!$CO$5:$CP$7,2,FALSE))*IF($BL25="",1,VLOOKUP($BL25,DADOS!$CR$5:$CS$15,2,FALSE)),4)>0,MAX(1,FLOOR(ROUND(VLOOKUP($BJ25,DADOS!$CL$5:$CM$10,2,FALSE)*IF($BK25="",1,VLOOKUP($BK25,DADOS!$CO$5:$CP$7,2,FALSE))*IF($BL25="",1,VLOOKUP($BL25,DADOS!$CR$5:$CS$15,2,FALSE)),4),1)),0),"")) | BS25: =IF($BP25="","",IFERROR(IF(ROUND(VLOOKUP($BP25,DADOS!$CL$5:$CM$10,2,FALSE)*IF($BQ25="",1,VLOOKUP($BQ25,DADOS!$CO$5:$CP$7,2,FALSE))*IF($BR25="",1,VLOOKUP($BR25,DADOS!$CR$5:$CS$15,2,FALSE)),4)>0,MAX(1,FLOOR(ROUND(VLOOKUP($BP25,DADOS!$CL$5:$CM$10,2,FALSE)*IF($BQ25="",1,VLOOKUP($BQ25,DADOS!$CO$5:$CP$7,2,FALSE))*IF($BR25="",1,VLOOKUP($BR25,DADOS!$CR$5:$CS$15,2,FALSE)),4),1)),0),""))
Q26: HISTÓRIA | BA26: =IF($AX26="","",IFERROR(IF(ROUND(VLOOKUP($AX26,DADOS!$CL$5:$CM$10,2,FALSE)*IF($AY26="",1,VLOOKUP($AY26,DADOS!$CO$5:$CP$7,2,FALSE))*IF($AZ26="",1,VLOOKUP($AZ26,DADOS!$CR$5:$CS$15,2,FALSE)),4)>0,MAX(1,FLOOR(ROUND(VLOOKUP($AX26,DADOS!$CL$5:$CM$10,2,FALSE)*IF($AY26="",1,VLOOKUP($AY26,DADOS!$CO$5:$CP$7,2,FALSE))*IF($AZ26="",1,VLOOKUP($AZ26,DADOS!$CR$5:$CS$15,2,FALSE)),4),1)),0),"")) | BG26: =IF($BD26="","",IFERROR(IF(ROUND(VLOOKUP($BD26,DADOS!$CL$5:$CM$10,2,FALSE)*IF($BE26="",1,VLOOKUP($BE26,DADOS!$CO$5:$CP$7,2,FALSE))*IF($BF26="",1,VLOOKUP($BF26,DADOS!$CR$5:$CS$15,2,FALSE)),4)>0,MAX(1,FLOOR(ROUND(VLOOKUP($BD26,DADOS!$CL$5:$CM$10,2,FALSE)*IF($BE26="",1,VLOOKUP($BE26,DADOS!$CO$5:$CP$7,2,FALSE))*IF($BF26="",1,VLOOKUP($BF26,DADOS!$CR$5:$CS$15,2,FALSE)),4),1)),0),"")) | BM26: =IF($BJ26="","",IFERROR(IF(ROUND(VLOOKUP($BJ26,DADOS!$CL$5:$CM$10,2,FALSE)*IF($BK26="",1,VLOOKUP($BK26,DADOS!$CO$5:$CP$7,2,FALSE))*IF($BL26="",1,VLOOKUP($BL26,DADOS!$CR$5:$CS$15,2,FALSE)),4)>0,MAX(1,FLOOR(ROUND(VLOOKUP($BJ26,DADOS!$CL$5:$CM$10,2,FALSE)*IF($BK26="",1,VLOOKUP($BK26,DADOS!$CO$5:$CP$7,2,FALSE))*IF($BL26="",1,VLOOKUP($BL26,DADOS!$CR$5:$CS$15,2,FALSE)),4),1)),0),"")) | BS26: =IF($BP26="","",IFERROR(IF(ROUND(VLOOKUP($BP26,DADOS!$CL$5:$CM$10,2,FALSE)*IF($BQ26="",1,VLOOKUP($BQ26,DADOS!$CO$5:$CP$7,2,FALSE))*IF($BR26="",1,VLOOKUP($BR26,DADOS!$CR$5:$CS$15,2,FALSE)),4)>0,MAX(1,FLOOR(ROUND(VLOOKUP($BP26,DADOS!$CL$5:$CM$10,2,FALSE)*IF($BQ26="",1,VLOOKUP($BQ26,DADOS!$CO$5:$CP$7,2,FALSE))*IF($BR26="",1,VLOOKUP($BR26,DADOS!$CR$5:$CS$15,2,FALSE)),4),1)),0),""))
BA27: =IF($AX27="","",IFERROR(IF(ROUND(VLOOKUP($AX27,DADOS!$CL$5:$CM$10,2,FALSE)*IF($AY27="",1,VLOOKUP($AY27,DADOS!$CO$5:$CP$7,2,FALSE))*IF($AZ27="",1,VLOOKUP($AZ27,DADOS!$CR$5:$CS$15,2,FALSE)),4)>0,MAX(1,FLOOR(ROUND(VLOOKUP($AX27,DADOS!$CL$5:$CM$10,2,FALSE)*IF($AY27="",1,VLOOKUP($AY27,DADOS!$CO$5:$CP$7,2,FALSE))*IF($AZ27="",1,VLOOKUP($AZ27,DADOS!$CR$5:$CS$15,2,FALSE)),4),1)),0),"")) | BG27: =IF($BD27="","",IFERROR(IF(ROUND(VLOOKUP($BD27,DADOS!$CL$5:$CM$10,2,FALSE)*IF($BE27="",1,VLOOKUP($BE27,DADOS!$CO$5:$CP$7,2,FALSE))*IF($BF27="",1,VLOOKUP($BF27,DADOS!$CR$5:$CS$15,2,FALSE)),4)>0,MAX(1,FLOOR(ROUND(VLOOKUP($BD27,DADOS!$CL$5:$CM$10,2,FALSE)*IF($BE27="",1,VLOOKUP($BE27,DADOS!$CO$5:$CP$7,2,FALSE))*IF($BF27="",1,VLOOKUP($BF27,DADOS!$CR$5:$CS$15,2,FALSE)),4),1)),0),"")) | BM27: =IF($BJ27="","",IFERROR(IF(ROUND(VLOOKUP($BJ27,DADOS!$CL$5:$CM$10,2,FALSE)*IF($BK27="",1,VLOOKUP($BK27,DADOS!$CO$5:$CP$7,2,FALSE))*IF($BL27="",1,VLOOKUP($BL27,DADOS!$CR$5:$CS$15,2,FALSE)),4)>0,MAX(1,FLOOR(ROUND(VLOOKUP($BJ27,DADOS!$CL$5:$CM$10,2,FALSE)*IF($BK27="",1,VLOOKUP($BK27,DADOS!$CO$5:$CP$7,2,FALSE))*IF($BL27="",1,VLOOKUP($BL27,DADOS!$CR$5:$CS$15,2,FALSE)),4),1)),0),"")) | BS27: =IF($BP27="","",IFERROR(IF(ROUND(VLOOKUP($BP27,DADOS!$CL$5:$CM$10,2,FALSE)*IF($BQ27="",1,VLOOKUP($BQ27,DADOS!$CO$5:$CP$7,2,FALSE))*IF($BR27="",1,VLOOKUP($BR27,DADOS!$CR$5:$CS$15,2,FALSE)),4)>0,MAX(1,FLOOR(ROUND(VLOOKUP($BP27,DADOS!$CL$5:$CM$10,2,FALSE)*IF($BQ27="",1,VLOOKUP($BQ27,DADOS!$CO$5:$CP$7,2,FALSE))*IF($BR27="",1,VLOOKUP($BR27,DADOS!$CR$5:$CS$15,2,FALSE)),4),1)),0),""))
BA28: =IF($AX28="","",IFERROR(IF(ROUND(VLOOKUP($AX28,DADOS!$CL$5:$CM$10,2,FALSE)*IF($AY28="",1,VLOOKUP($AY28,DADOS!$CO$5:$CP$7,2,FALSE))*IF($AZ28="",1,VLOOKUP($AZ28,DADOS!$CR$5:$CS$15,2,FALSE)),4)>0,MAX(1,FLOOR(ROUND(VLOOKUP($AX28,DADOS!$CL$5:$CM$10,2,FALSE)*IF($AY28="",1,VLOOKUP($AY28,DADOS!$CO$5:$CP$7,2,FALSE))*IF($AZ28="",1,VLOOKUP($AZ28,DADOS!$CR$5:$CS$15,2,FALSE)),4),1)),0),"")) | BG28: =IF($BD28="","",IFERROR(IF(ROUND(VLOOKUP($BD28,DADOS!$CL$5:$CM$10,2,FALSE)*IF($BE28="",1,VLOOKUP($BE28,DADOS!$CO$5:$CP$7,2,FALSE))*IF($BF28="",1,VLOOKUP($BF28,DADOS!$CR$5:$CS$15,2,FALSE)),4)>0,MAX(1,FLOOR(ROUND(VLOOKUP($BD28,DADOS!$CL$5:$CM$10,2,FALSE)*IF($BE28="",1,VLOOKUP($BE28,DADOS!$CO$5:$CP$7,2,FALSE))*IF($BF28="",1,VLOOKUP($BF28,DADOS!$CR$5:$CS$15,2,FALSE)),4),1)),0),"")) | BM28: =IF($BJ28="","",IFERROR(IF(ROUND(VLOOKUP($BJ28,DADOS!$CL$5:$CM$10,2,FALSE)*IF($BK28="",1,VLOOKUP($BK28,DADOS!$CO$5:$CP$7,2,FALSE))*IF($BL28="",1,VLOOKUP($BL28,DADOS!$CR$5:$CS$15,2,FALSE)),4)>0,MAX(1,FLOOR(ROUND(VLOOKUP($BJ28,DADOS!$CL$5:$CM$10,2,FALSE)*IF($BK28="",1,VLOOKUP($BK28,DADOS!$CO$5:$CP$7,2,FALSE))*IF($BL28="",1,VLOOKUP($BL28,DADOS!$CR$5:$CS$15,2,FALSE)),4),1)),0),"")) | BS28: =IF($BP28="","",IFERROR(IF(ROUND(VLOOKUP($BP28,DADOS!$CL$5:$CM$10,2,FALSE)*IF($BQ28="",1,VLOOKUP($BQ28,DADOS!$CO$5:$CP$7,2,FALSE))*IF($BR28="",1,VLOOKUP($BR28,DADOS!$CR$5:$CS$15,2,FALSE)),4)>0,MAX(1,FLOOR(ROUND(VLOOKUP($BP28,DADOS!$CL$5:$CM$10,2,FALSE)*IF($BQ28="",1,VLOOKUP($BQ28,DADOS!$CO$5:$CP$7,2,FALSE))*IF($BR28="",1,VLOOKUP($BR28,DADOS!$CR$5:$CS$15,2,FALSE)),4),1)),0),""))
BA29: =IF($AX29="","",IFERROR(IF(ROUND(VLOOKUP($AX29,DADOS!$CL$5:$CM$10,2,FALSE)*IF($AY29="",1,VLOOKUP($AY29,DADOS!$CO$5:$CP$7,2,FALSE))*IF($AZ29="",1,VLOOKUP($AZ29,DADOS!$CR$5:$CS$15,2,FALSE)),4)>0,MAX(1,FLOOR(ROUND(VLOOKUP($AX29,DADOS!$CL$5:$CM$10,2,FALSE)*IF($AY29="",1,VLOOKUP($AY29,DADOS!$CO$5:$CP$7,2,FALSE))*IF($AZ29="",1,VLOOKUP($AZ29,DADOS!$CR$5:$CS$15,2,FALSE)),4),1)),0),"")) | BG29: =IF($BD29="","",IFERROR(IF(ROUND(VLOOKUP($BD29,DADOS!$CL$5:$CM$10,2,FALSE)*IF($BE29="",1,VLOOKUP($BE29,DADOS!$CO$5:$CP$7,2,FALSE))*IF($BF29="",1,VLOOKUP($BF29,DADOS!$CR$5:$CS$15,2,FALSE)),4)>0,MAX(1,FLOOR(ROUND(VLOOKUP($BD29,DADOS!$CL$5:$CM$10,2,FALSE)*IF($BE29="",1,VLOOKUP($BE29,DADOS!$CO$5:$CP$7,2,FALSE))*IF($BF29="",1,VLOOKUP($BF29,DADOS!$CR$5:$CS$15,2,FALSE)),4),1)),0),"")) | BM29: =IF($BJ29="","",IFERROR(IF(ROUND(VLOOKUP($BJ29,DADOS!$CL$5:$CM$10,2,FALSE)*IF($BK29="",1,VLOOKUP($BK29,DADOS!$CO$5:$CP$7,2,FALSE))*IF($BL29="",1,VLOOKUP($BL29,DADOS!$CR$5:$CS$15,2,FALSE)),4)>0,MAX(1,FLOOR(ROUND(VLOOKUP($BJ29,DADOS!$CL$5:$CM$10,2,FALSE)*IF($BK29="",1,VLOOKUP($BK29,DADOS!$CO$5:$CP$7,2,FALSE))*IF($BL29="",1,VLOOKUP($BL29,DADOS!$CR$5:$CS$15,2,FALSE)),4),1)),0),"")) | BS29: =IF($BP29="","",IFERROR(IF(ROUND(VLOOKUP($BP29,DADOS!$CL$5:$CM$10,2,FALSE)*IF($BQ29="",1,VLOOKUP($BQ29,DADOS!$CO$5:$CP$7,2,FALSE))*IF($BR29="",1,VLOOKUP($BR29,DADOS!$CR$5:$CS$15,2,FALSE)),4)>0,MAX(1,FLOOR(ROUND(VLOOKUP($BP29,DADOS!$CL$5:$CM$10,2,FALSE)*IF($BQ29="",1,VLOOKUP($BQ29,DADOS!$CO$5:$CP$7,2,FALSE))*IF($BR29="",1,VLOOKUP($BR29,DADOS!$CR$5:$CS$15,2,FALSE)),4),1)),0),""))
D30: PERSONALIDADE | BA30: =IF($AX30="","",IFERROR(IF(ROUND(VLOOKUP($AX30,DADOS!$CL$5:$CM$10,2,FALSE)*IF($AY30="",1,VLOOKUP($AY30,DADOS!$CO$5:$CP$7,2,FALSE))*IF($AZ30="",1,VLOOKUP($AZ30,DADOS!$CR$5:$CS$15,2,FALSE)),4)>0,MAX(1,FLOOR(ROUND(VLOOKUP($AX30,DADOS!$CL$5:$CM$10,2,FALSE)*IF($AY30="",1,VLOOKUP($AY30,DADOS!$CO$5:$CP$7,2,FALSE))*IF($AZ30="",1,VLOOKUP($AZ30,DADOS!$CR$5:$CS$15,2,FALSE)),4),1)),0),"")) | BG30: =IF($BD30="","",IFERROR(IF(ROUND(VLOOKUP($BD30,DADOS!$CL$5:$CM$10,2,FALSE)*IF($BE30="",1,VLOOKUP($BE30,DADOS!$CO$5:$CP$7,2,FALSE))*IF($BF30="",1,VLOOKUP($BF30,DADOS!$CR$5:$CS$15,2,FALSE)),4)>0,MAX(1,FLOOR(ROUND(VLOOKUP($BD30,DADOS!$CL$5:$CM$10,2,FALSE)*IF($BE30="",1,VLOOKUP($BE30,DADOS!$CO$5:$CP$7,2,FALSE))*IF($BF30="",1,VLOOKUP($BF30,DADOS!$CR$5:$CS$15,2,FALSE)),4),1)),0),"")) | BM30: =IF($BJ30="","",IFERROR(IF(ROUND(VLOOKUP($BJ30,DADOS!$CL$5:$CM$10,2,FALSE)*IF($BK30="",1,VLOOKUP($BK30,DADOS!$CO$5:$CP$7,2,FALSE))*IF($BL30="",1,VLOOKUP($BL30,DADOS!$CR$5:$CS$15,2,FALSE)),4)>0,MAX(1,FLOOR(ROUND(VLOOKUP($BJ30,DADOS!$CL$5:$CM$10,2,FALSE)*IF($BK30="",1,VLOOKUP($BK30,DADOS!$CO$5:$CP$7,2,FALSE))*IF($BL30="",1,VLOOKUP($BL30,DADOS!$CR$5:$CS$15,2,FALSE)),4),1)),0),"")) | BS30: =IF($BP30="","",IFERROR(IF(ROUND(VLOOKUP($BP30,DADOS!$CL$5:$CM$10,2,FALSE)*IF($BQ30="",1,VLOOKUP($BQ30,DADOS!$CO$5:$CP$7,2,FALSE))*IF($BR30="",1,VLOOKUP($BR30,DADOS!$CR$5:$CS$15,2,FALSE)),4)>0,MAX(1,FLOOR(ROUND(VLOOKUP($BP30,DADOS!$CL$5:$CM$10,2,FALSE)*IF($BQ30="",1,VLOOKUP($BQ30,DADOS!$CO$5:$CP$7,2,FALSE))*IF($BR30="",1,VLOOKUP($BR30,DADOS!$CR$5:$CS$15,2,FALSE)),4),1)),0),""))
BA31: =IF($AX31="","",IFERROR(IF(ROUND(VLOOKUP($AX31,DADOS!$CL$5:$CM$10,2,FALSE)*IF($AY31="",1,VLOOKUP($AY31,DADOS!$CO$5:$CP$7,2,FALSE))*IF($AZ31="",1,VLOOKUP($AZ31,DADOS!$CR$5:$CS$15,2,FALSE)),4)>0,MAX(1,FLOOR(ROUND(VLOOKUP($AX31,DADOS!$CL$5:$CM$10,2,FALSE)*IF($AY31="",1,VLOOKUP($AY31,DADOS!$CO$5:$CP$7,2,FALSE))*IF($AZ31="",1,VLOOKUP($AZ31,DADOS!$CR$5:$CS$15,2,FALSE)),4),1)),0),"")) | BG31: =IF($BD31="","",IFERROR(IF(ROUND(VLOOKUP($BD31,DADOS!$CL$5:$CM$10,2,FALSE)*IF($BE31="",1,VLOOKUP($BE31,DADOS!$CO$5:$CP$7,2,FALSE))*IF($BF31="",1,VLOOKUP($BF31,DADOS!$CR$5:$CS$15,2,FALSE)),4)>0,MAX(1,FLOOR(ROUND(VLOOKUP($BD31,DADOS!$CL$5:$CM$10,2,FALSE)*IF($BE31="",1,VLOOKUP($BE31,DADOS!$CO$5:$CP$7,2,FALSE))*IF($BF31="",1,VLOOKUP($BF31,DADOS!$CR$5:$CS$15,2,FALSE)),4),1)),0),"")) | BM31: =IF($BJ31="","",IFERROR(IF(ROUND(VLOOKUP($BJ31,DADOS!$CL$5:$CM$10,2,FALSE)*IF($BK31="",1,VLOOKUP($BK31,DADOS!$CO$5:$CP$7,2,FALSE))*IF($BL31="",1,VLOOKUP($BL31,DADOS!$CR$5:$CS$15,2,FALSE)),4)>0,MAX(1,FLOOR(ROUND(VLOOKUP($BJ31,DADOS!$CL$5:$CM$10,2,FALSE)*IF($BK31="",1,VLOOKUP($BK31,DADOS!$CO$5:$CP$7,2,FALSE))*IF($BL31="",1,VLOOKUP($BL31,DADOS!$CR$5:$CS$15,2,FALSE)),4),1)),0),"")) | BS31: =IF($BP31="","",IFERROR(IF(ROUND(VLOOKUP($BP31,DADOS!$CL$5:$CM$10,2,FALSE)*IF($BQ31="",1,VLOOKUP($BQ31,DADOS!$CO$5:$CP$7,2,FALSE))*IF($BR31="",1,VLOOKUP($BR31,DADOS!$CR$5:$CS$15,2,FALSE)),4)>0,MAX(1,FLOOR(ROUND(VLOOKUP($BP31,DADOS!$CL$5:$CM$10,2,FALSE)*IF($BQ31="",1,VLOOKUP($BQ31,DADOS!$CO$5:$CP$7,2,FALSE))*IF($BR31="",1,VLOOKUP($BR31,DADOS!$CR$5:$CS$15,2,FALSE)),4),1)),0),""))
