Workbook
Name PALETA_ESCOLHIDA: CARTEIRA!$C$27:$M$28
Name PALETA_AVISO: CARTEIRA!$C$29:$M$29
Name PALETA_ROTULO: CARTEIRA!$C$26:$I$26

Sheet CARTEIRA
C2: 呪術廻戦 | L2: =UPPER(DADOS!$F$1) -> PROJETO M | AH2: ="Nº M-"&SUBSTITUTE(DADOS!$B$1,".","")&"-"&IF(FICHA!D3="","····",UPPER(LEFT(FICHA!D3,4))) -> Nº M-0246-····
L3: Carteira de registro · Documento oficial | AH3: ="Emitida "&TEXT(TODAY(),"dd.mm.yyyy") -> Emitida 19.09.2026
O8: PORTADOR
O9: Coloque o nome do personagem aqui
O17: CAMINHO | Z17: TRILHA | AK17: ORIGEM
O18: =IF(OR(FICHA!D11="",FICHA!D11="Escolha seu Caminho"),"—",FICHA!D11) -> — | Z18: =IF(OR(FICHA!N11="",FICHA!N11="Escolha sua Trilha"),"—",FICHA!N11) -> — | AK18: =IF(FICHA!X11="","—",FICHA!X11) -> Latente
O21: NÍVEL | Z21: SERVIDOR USADO | AK21: REGISTRADO POR
O22: =IF(FICHA!AH11="","—",FICHA!AH11) -> 2 | AK22: Nick do jogador
C26: PALETA | O26: =IF(DADOS!$AK$32=1,"TÉCNICA MARCIAL DECLARADA",IF(DADOS!$AK$31=1,"ESTILO DECLARADO","TÉCNICA AMALDIÇOADA DECLARADA")) -> TÉCNICA AMALDIÇOADA DECLARADA
C27: Mizuki · Escuro
C29: Aguarde de 30 a 40 segundos para ver o tema inteiro — depende do tema.
AK34: SELO REGISTRADO
AH38: =IF(OR(FICHA!D11="",FICHA!D11="Escolha seu Caminho"),"—",UPPER(LEFT(FICHA!D11,3))&"-"&TEXT(FICHA!AH11,"00")) -> —

Sheet FICHA
D2: =UPPER(DADOS!$F$1) -> PROJETO M | AH2: CATÁLOGO
D3: =IF(OR(CARTEIRA!$O$9="",CARTEIRA!$O$9="Coloque o nome do personagem aqui"),"",CARTEIRA!$O$9) | AH3: =IF(DADOS!$B$1=DADOS!$D$1,"v"&DADOS!$B$1&" · em dia","⚠ v"&DADOS!$B$1&" · a atual é a v"&DADOS!$D$1) -> v0.246 · em dia
A8: PROJETO M | D8: 1 | G8: PERFIL AMALDIÇOADO
D10: CAMINHO | N10: TRILHA | X10: ORIGEM | AH10: NÍVEL | AN10: XP
D11: Escolha seu Caminho | N11: Escolha sua Trilha | X11: Latente | AH11: 2 | AN11: 0
Z14: Pontos Disponíveis | AK14: ="Pontos de Marco de Corpo Disponíveis - "&IF(DADOS!$AK$11>DADOS!$AK$10,DADOS!$AK$11-DADOS!$AK$10&" a mais",DADOS!$AK$10-DADOS!$AK$11&" de "&DADOS!$AK$10) -> Pontos de Marco de Corpo Disponíveis - 0 de 0
D15: 2 | G15: VALORES | Z15: =IF(DADOS!$AK$7>DADOS!$AK$6,DADOS!$AK$7-DADOS!$AK$6&" a mais",IF(DADOS!$AK$8>6,"Um atributo passou de 6",IF(AND(DADOS!$AK$5=0,DADOS!$AK$9>3),"Na criação, nenhum acima de 3",DADOS!$AK$6-DADOS!$AK$7&" de "&DADOS!$AK$6))) -> 9 de 9 | AK15: 0 | AM15: 0 | AO15: 0 | AQ15: 0 | AS15: 0
AK16: FOR | AM16: DEX | AO16: CON | AQ16: INT | AS16: ESS
D18: FOR | L18: DES | T18: CON | AB18: INT | AJ18: ESS
D19: =IFERROR(VALUE($D$21&""),0)+IFERROR(VALUE($AK$15&""),0) -> 0 | L19: =IFERROR(VALUE($L$21&""),0)+IFERROR(VALUE($AM$15&""),0) -> 0 | T19: =IFERROR(VALUE($T$21&""),0)+IFERROR(VALUE($AO$15&""),0) -> 0 | AB19: =IFERROR(VALUE($AB$21&""),0)+IFERROR(VALUE($AQ$15&""),0) -> 0 | AJ19: =IFERROR(VALUE($AJ$21&""),0)+IFERROR(VALUE($AS$15&""),0) -> 0
D21: 0 | L21: 0 | T21: 0 | AB21: 0 | AJ21: 0
D22: Força | L22: Destreza | T22: Constituição | AB22: Inteligência | AJ22: Essência
D25: VIDA - Atual/Máxima | AF25: TEMPORÁRIO | AM25: ± PERDA &/ou GANHO
D26: =J26 | J26: =IFERROR(IF($D$11="","",(VLOOKUP($D$11,DADOS!$N$5:$U$9,3,FALSE)+$T$19)+(VLOOKUP($D$11,DADOS!$N$5:$U$9,4,FALSE)+$T$19)*($AH$11-1)),"") | P26: =IFERROR(__xludf.DUMMYFUNCTION("IFERROR(SPARKLINE($D$26,{""charttype"",""bar"";""max"",$J$26;""color1"",IF(N($J$26)=0,""#E8DCD4"",IF($D$26/$J$26<=0.25,""#C2334D"",IF($D$26/$J$26<=0.5,""#D89B3A"",""#E8DCD4"")))}),"""")"),"") | AF26: 0
D29: ENERGIA - Atual/Máxima | AF29: TEMPORÁRIO | AM29: ± PERDA &/ou GANHO
D30: =J30 | J30: =IFERROR(IF($D$11="","",VLOOKUP($D$11,DADOS!$N$5:$U$9,5,FALSE)*$AH$11),"") | P30: =IFERROR(__xludf.DUMMYFUNCTION("IFERROR(SPARKLINE($D$30,{""charttype"",""bar"";""max"",$J$30;""color1"",IF(N($J$30)=0,""#E8DCD4"",IF($D$30/$J$30<=0.25,""#C2334D"",IF($D$30/$J$30<=0.5,""#D89B3A"",""#E8DCD4"")))}),"""")"),"") | AF30: 0
A33: FICHA DE REGISTRO | D33: INTEGRIDADE - Atual/Máxima | AF33: TEMPORÁRIO | AM33: ± PERDA &/ou GANHO
D34: =J34 -> 25 | J34: =20+(AJ19+5)*($AH$11-1) -> 25 | P34: =IFERROR(__xludf.DUMMYFUNCTION("IFERROR(SPARKLINE($D$34,{""charttype"",""bar"";""max"",$J$34;""color1"",IF(N($J$34)=0,""#E8DCD4"",IF($D$34/$J$34<=0.25,""#C2334D"",IF($D$34/$J$34<=0.5,""#D89B3A"",""#E8DCD4"")))}),"""")"),"") | AF34: 0
D37: =IF($D$34=""," ",IF($D$34<=0,"Estágio 4 · Você não é mais você mesmo",IF($D$34<=$J$34/4,"Estágio 3 · Desvantagem em ataques e TRs",IF($D$34<=$J$34/2,"Estágio 2 · Metade do deslocamento, +1 PE por Classe",IF($D$34<=$J$34*3/4,"Estágio 1 · Desvantagem em perícias","Alma Inteira"))))) -> Alma Inteira
Z39: BLOQUEAR | AK39: Marco Escolhido | AO39: Refino | AQ39: Corpo | AS39: Leque
D40: 3 | G40: REGISTRO | Z40: ="2d10 + " & D43-11 -> 2d10 + 0 | AK40: =IF(DADOS!$AK$12>DADOS!$AK$5,DADOS!$AK$12-DADOS!$AK$5&" a mais",IF(DADOS!$AK$5=0,"Escolha 1 a cada 4 Nv",DADOS!$AK$5-DADOS!$AK$12&" de "&DADOS!$AK$5&" para escolher")) -> Escolha 1 a cada 4 Nv | AO40: 0 | AQ40: 0 | AS40: 0
D42: DEFESA | L42: Buff/Debuff | O42: PROTEÇÃO | Z42: EQUIPAMENTO | AK42: INICIATIVA | AS42: Buff/Debuff
D43: =10+IF($Z$43="",$L$19,MIN($L$19,IFERROR(VALUE(VLOOKUP($Z$43,DADOS!$AE$5:$AH$31,3,FALSE)&""),$L$19)))+$O$43+IFERROR(VALUE($L$43&""),0) -> 11 | L43: 0 | O43: =IF($Z$43="",FLOOR(MIN(10,$O$57+MIN($O$57-1,IFERROR(VALUE($AO$40&""),0)))/3,1)+1,IF(VLOOKUP($Z$43,DADOS!$AE$5:$AH$31,4,FALSE)="sim",0,FLOOR(MIN(10,$O$57+MIN($O$57-1,IFERROR(VALUE($AO$40&""),0)))/3,1)+1)+VLOOKUP($Z$43,DADOS!$AE$5:$AH$31,2,FALSE)) -> 1 | AK43: ="d20 + "&($L$19+IFERROR(VALUE($AS$43&""),0)) -> d20 + 0 | AS43: 0
D46: CD DE FEITIÇO | L46: Buff/Debuff | O46: CONJURAÇÃO | W46: Buff/Debuff | Z46: CORPO A CORPO | AH46: Buff/Debuff | AK46: À DISTÂNCIA | AS46: Buff/Debuff
D47: =8+D51+IFS(Z51="FORÇA",$D$19, Z51="DESTREZA",$L$19, Z51="CONSTITUIÇÃO",$T$19, Z51="INTELIGÊNCIA",$AB$19, Z51="ESSÊNCIA",$AJ$19)+IFERROR(VALUE($L$47&""),0) -> 9 | L47: 0 | O47: ="d20 + "&(D51+IFS(Z51="FORÇA",$D$19, Z51="DESTREZA",$L$19, Z51="CONSTITUIÇÃO",$T$19, Z51="INTELIGÊNCIA",$AB$19, Z51="ESSÊNCIA",$AJ$19)+IFERROR(VALUE($W$47&""),0)) -> d20 + 1 | W47: 0 | Z47: ="d20 + "&(D51+IFS(AK51="FORÇA",$D$19, AK51="DESTREZA",$L$19, AK51="CONSTITUIÇÃO",$T$19, AK51="INTELIGÊNCIA",$AB$19, AK51="ESSÊNCIA",$AJ$19)+IFERROR(VALUE($AH$47&""),0)) -> d20 + 1 | AH47: 0 | AK47: ="d20 + "&(D51+IFS(AE54="FORÇA",$D$19, AE54="DESTREZA",$L$19, AE54="CONSTITUIÇÃO",$T$19, AE54="INTELIGÊNCIA",$AB$19, AE54="ESSÊNCIA",$AJ$19)+IFERROR(VALUE($AS$47&""),0)) -> d20 + 1 | AS47: 0
D50: MAESTRIA | O50: DESLOCAMENTO | W50: Buff/Debuff | Z50: ATRIBUTO DE CONJURAÇÃO | AK50: ATRIBUTO DE ATAQUE - CORPO A CORPO
D51: =(1+COUNTIF(DADOS!$X$5:$X$7,"<="&$AH$11)) -> 1 | O51: =(9+IFERROR(VALUE($W$51&""),0))&" m" -> 9 m | W51: 0 | Z51: ESSÊNCIA | AK51: FORÇA
AE53: ATRIBUTO DE ATAQUE - À DISTÂNCIA
D54: 4 | G54: PROGRESSÃO | AE54: DESTREZA
D56: ESPAÇOS DE FEITIÇO | O56: REFINO DE GRAÇA | Z56: CLASSE MÁXIMA | AK56: CLASSE 0
D57: =2+INT($AH$11/2)+COUNTIF(DADOS!$W$5:$W$11,"<="&$AH$11)+IFERROR(VALUE($AS$40&""),0) -> 3 | O57: =(1+COUNTIF(DADOS!$W$5:$W$11,"<="&$AH$11)) -> 1 | Z57: =COUNTIF(DADOS!$Y$5:$Y$11,"<="&$AH$11) -> 1 | AK57: =2+COUNTIF(DADOS!$Z$5:$Z$7,"<="&$AH$11) -> 2
D60: 5 | G60: PERÍCIAS
T62: Trein | U62: Espec | AH62: Extra | AK62: TREINAMENTO EM ARMAS
D63: Trein | E63: Espec | R63: Extra | T63: FALSE | U63: FALSE | V63: Sobrevivência | AD63: Int | AF63: =$AB$19 + IF(U63, $D$51 + INT($D$51 / 2), IF(T63, $D$51, 0)) + AH63 -> 0 | AK63: =IF(FICHA!$D$11="Escolha seu Caminho","—",IF(OR(FICHA!$D$11="Bastião",FICHA!$D$11="Vanguarda"),"Treinado em Todas as Armas","Treinado em Arma de Fogo e Balestra")) -> —
D64: FALSE | E64: FALSE | F64: Atletismo | N64: For | P64: =$D$19 + IF(E64, $D$51 + INT($D$51 / 2), IF(D64, $D$51, 0)) + R64 -> 0 | T64: FALSE | U64: FALSE | V64: Natureza | AD64: Int | AF64: =$AB$19 + IF(U64, $D$51 + INT($D$51 / 2), IF(T64, $D$51, 0)) + AH64 -> 0
D65: FALSE | E65: FALSE | F65: Acrobacia | N65: Des | P65: =$L$19 + IF(E65, $D$51 + INT($D$51 / 2), IF(D65, $D$51, 0)) + R65 -> 0 | T65: FALSE | U65: FALSE | V65: Lidar com Animais | AD65: Int | AF65: =$AB$19 + IF(U65, $D$51 + INT($D$51 / 2), IF(T65, $D$51, 0)) + AH65 -> 0 | AK65: Não trocou
D66: FALSE | E66: FALSE | F66: Furtividade | N66: Des | P66: =$L$19 + IF(E66, $D$51 + INT($D$51 / 2), IF(D66, $D$51, 0)) + R66 -> 0 | T66: FALSE | U66: FALSE | V66: Tecnologia | AD66: Int | AF66: =$AB$19 + IF(U66, $D$51 + INT($D$51 / 2), IF(T66, $D$51, 0)) + AH66 -> 0
D67: FALSE | E67: FALSE | F67: Pontaria | N67: Des | P67: =$L$19 + IF(E67, $D$51 + INT($D$51 / 2), IF(D67, $D$51, 0)) + R67 -> 0 | T67: FALSE | U67: FALSE | V67: Medicina | AD67: Int | AF67: =$AB$19 + IF(U67, $D$51 + INT($D$51 / 2), IF(T67, $D$51, 0)) + AH67 -> 0 | AK67: =IF(AK65="Não trocou","Anotações e Equipamentos","Treinamentos Extras") -> Anotações e Equipamentos
D68: FALSE | E68: FALSE | F68: Prestidigitação | N68: Des | P68: =$L$19 + IF(E68, $D$51 + INT($D$51 / 2), IF(D68, $D$51, 0)) + R68 -> 0 | T68: FALSE | U68: FALSE | V68: Sentir Energia | AD68: Ess | AF68: =$AJ$19 + IF(U68, $D$51 + INT($D$51 / 2), IF(T68, $D$51, 0)) + AH68 -> 0
D69: FALSE | E69: FALSE | F69: Investigação | N69: Int | P69: =$AB$19 + IF(E69, $D$51 + INT($D$51 / 2), IF(D69, $D$51, 0)) + R69 -> 0 | T69: FALSE | U69: FALSE | V69: Percepção | AD69: Ess | AF69: =$AJ$19 + IF(U69, $D$51 + INT($D$51 / 2), IF(T69, $D$51, 0)) + AH69 -> 0
...

Sheet DADOS
A1: VERSÃO DO CATÁLOGO | B1: 0.246 | C1: versão corrente (puxada da central) | D1: 0.246 | E1: NOME DO SISTEMA | F1: Projeto M
A2: cole aqui o IMPORTRANGE da central em D1 quando ela existir; enquanto não existir, D1 fica igual a B1 e o aviso some
A3: Caminhos | B3: Perícias | C3: Ofícios | D3: Famílias | E3: Formas | F3: Melhorias | G3: Restrições | H3: Condições | I3: Origens | J3: Testes | K3: Atributos | L3: Trilhas | N3: tabela dos Caminhos
A4: Bastião | B4: Atletismo | C4: Condução | D4: Alcance | E4: Projétil | F4: Longe | G4: Corpo a Corpo | H4: Lento | I4: Latente | J4: Físico | K4: Força | L4: Muro | N4: Caminho | O4: dado | P4: vida inicial | Q4: vida por nível | R4: PE por nível | S4: perícia fixa 1 | T4: perícia fixa 2 | W4: marcos | X4: maestria | Y4: classe | Z4: classe 0 | AB4: perícia | AC4: atributo | AE4: equipamento | AF4: proteção | AG4: teto de destreza | AH4: desliga a passiva | AJ4: contas da ficha | AK4: valor | AM4: menu de Caminho | AN4: Trilha | AO4: Caminho da Trilha | AP4: menu de Trilha | AQ4: nível | AR4: xp acumulado | BA4: campo | BB4: célula
A5: Vanguarda | B5: Acrobacia | C5: Arrombamento | D5: Área | E5: Toque | F5: Muito Longe | G5: Atrasar | H5: Incapacitado | I5: Receptáculo | J5: Vigor | K5: Destreza | L5: Punho | N5: Bastião | O5: d12 | P5: 12 | Q5: 7 | R5: 4 | S5: Atletismo | T5: Intimidação | W5: 6 | X5: 10 | Y5: 1 | Z5: 5 | AB5: Atletismo | AC5: Força | AE5: Traje 1 | AF5: 1 | AG5: — | AH5: sim | AJ5: marcos que já passou | AK5: =COUNTIF(DADOS!$W$5:$W$11,"<="&FICHA!$AH$11) -> 0 | AM5: Escolha seu Caminho | AN5: =$L$4 -> Muro | AO5: Bastião | AP5: Escolha sua Trilha | AQ5: 2 | AR5: 0 | BA5: nome | BB5: =ADDRESS(ROW(FICHA!D3),COLUMN(FICHA!D3),4) -> D3
A6: Guia | B6: Furtividade | C6: Herbalismo | D6: Mira | E6: Explosão | F6: Sem Ver | G6: Parado | H6: Derrubado | I6: Descendente | J6: Intelecto | K6: Constituição | L6: Brasa | N6: Vanguarda | O6: d8 | P6: 8 | Q6: 5 | R6: 5 | S6: Acrobacia | T6: Percepção | W6: 10 | X6: 18 | Y6: 5 | Z6: 11 | AB6: Acrobacia | AC6: Destreza | AE6: Traje 2 | AF6: 2 | AG6: — | AH6: sim | AJ6: pontos de atributo | AK6: =9+DADOS!$AK$5 -> 9 | AM6: =$A$4 -> Bastião | AN6: =$L$5 -> Punho | AO6: Bastião | AP6: =IFERROR(__xludf.DUMMYFUNCTION("IFERROR(FILTER($AN$5:$AN$19,$AO$5:$AO$19=FICHA!$D$11),"""")"),"") | AQ6: 3 | AR6: 200 | BA6: caminho | BB6: =ADDRESS(ROW(FICHA!D11),COLUMN(FICHA!D11),4) -> D11
A7: Emanador | B7: Pontaria | C7: Forja | D7: Controle | E7: Aura | F7: Passo | G7: Gesto | H7: Agarrado | I7: Reencarnado | J7: Espírito | K7: Inteligência | L7: Estocada | N7: Guia | O7: d8 | P7: 8 | Q7: 5 | R7: 5 | S7: Persuasão | T7: Medicina | W7: 14 | X7: 26 | Y7: 9 | Z7: 17 | AB7: Furtividade | AC7: Destreza | AE7: Traje 3 | AF7: 3 | AG7: — | AH7: sim | AJ7: pontos distribuídos | AK7: =IFERROR(VALUE(FICHA!$D$21&""),0)+IFERROR(VALUE(FICHA!$L$21&""),0)+IFERROR(VALUE(FICHA!$T$21&""),0)+IFERROR(VALUE(FICHA!$AB$21&""),0)+IFERROR(VALUE(FICHA!$AJ$21&""),0) -> 0 | AM7: =$A$5 -> Vanguarda | AN7: =$L$6 -> Brasa | AO7: Bastião | AQ7: 4 | AR7: 500 | BA7: trilha | BB7: =ADDRESS(ROW(FICHA!N11),COLUMN(FICHA!N11),4) -> N11
A8: Evocador | B8: Prestidigitação | C8: Caligrafia | D8: Auxiliares | E8: Cone | F8: Empurrão | G8: Sangra | H8: Desarmado | I8: Feto | K8: Essência | L8: Batedor | N8: Evocador | O8: d6 | P8: 6 | Q8: 4 | R8: 6 | S8: Religião | T8: Lidar com Animais | W8: 18 | Y8: 13 | AB8: Pontaria | AC8: Destreza | AE8: Revestimento 1 | AF8: 4 | AG8: 0 | AH8: sim | AJ8: maior atributo | AK8: =MAX(FICHA!$D$19,FICHA!$L$19,FICHA!$T$19,FICHA!$AB$19,FICHA!$AJ$19) -> 0 | AM8: =$A$6 -> Guia | AN8: =$L$7 -> Estocada | AO8: Vanguarda | AQ8: 5 | AR8: 800 | BA8: origem | BB8: =ADDRESS(ROW(FICHA!X11),COLUMN(FICHA!X11),4) -> X11
B9: Investigação | C9: Burocracia | D9: Castigo | E9: Linha | F9: Troca | G9: Recuo | H9: Surdo | I9: Restrição Celestial · corpo pela técnica | L9: Executor | N9: Emanador | O9: d6 | P9: 6 | Q9: 4 | R9: 6 | S9: Ocultismo | T9: Investigação | W9: 22 | Y9: 17 | AB9: Prestidigitação | AC9: Destreza | AE9: Revestimento 2 | AF9: 5 | AG9: 0 | AH9: sim | AJ9: maior atributo pequeno | AK9: =MAX(IFERROR(VALUE(FICHA!$D$21&""),0),IFERROR(VALUE(FICHA!$L$21&""),0),IFERROR(VALUE(FICHA!$T$21&""),0),IFERROR(VALUE(FICHA!$AB$21&""),0),IFERROR(VALUE(FICHA!$AJ$21&""),0)) -> 0 | AM9: =$A$7 -> Emanador | AN9: =$L$8 -> Batedor | AO9: Vanguarda | AQ9: 6 | AR9: 1300 | BA9: nivel | BB9: =ADDRESS(ROW(FICHA!AH11),COLUMN(FICHA!AH11),4) -> AH11
B10: Intuição | C10: Entalhador | D10: Tempo | E10: Cura | F10: Perseguir | G10: Carregar | H10: Calado | I10: Latente · Sem Técnica | L10: Elo | W10: 26 | Y10: 21 | AB10: Investigação | AC10: Inteligência | AE10: Revestimento 3 | AF10: 6 | AG10: 0 | AH10: sim | AJ10: marcos de Corpo | AK10: =IFERROR(VALUE(FICHA!$AQ$40&""),0) -> 0 | AM10: =$A$8 -> Evocador | AN10: =$L$9 -> Executor | AO10: Vanguarda | AQ10: 7 | AR10: 1800 | BA10: xp | BB10: =ADDRESS(ROW(FICHA!AN11),COLUMN(FICHA!AN11),4) -> AN11
B11: Ocultismo | C11: Alfaiate | D11: Marca | E11: Apoio | F11: Maior | G11: Tudo ou Nada | H11: Enfeitiçado | I11: Receptáculo · Sem Técnica | L11: Sutura | W11: 30 | Y11: 26 | AB11: Intuição | AC11: Inteligência | AE11: Broquel | AF11: 1 | AG11: 5 | AH11: não | AJ11: pontos de Corpo usados | AK11: =IFERROR(VALUE(FICHA!$AK$15&""),0)+IFERROR(VALUE(FICHA!$AM$15&""),0)+IFERROR(VALUE(FICHA!$AO$15&""),0)+IFERROR(VALUE(FICHA!$AQ$15&""),0)+IFERROR(VALUE(FICHA!$AS$15&""),0) -> 0 | AN11: =$L$10 -> Elo | AO11: Guia | AQ11: 8 | AR11: 2300 | BA11: atr_Força | BB11: =ADDRESS(ROW(FICHA!D19),COLUMN(FICHA!D19),4) -> D19
B12: Religião | C12: Culinária | D12: Amparo | E12: Onda | F12: Muito Maior | G12: Uma Vez | H12: Impedido | I12: Descendente · Sem Técnica | L12: Perímetro | AB12: Ocultismo | AC12: Inteligência | AE12: Médio | AF12: 2 | AG12: 3 | AH12: não | AJ12: marcos escolhidos | AK12: =IFERROR(VALUE(FICHA!$AO$40&""),0)+IFERROR(VALUE(FICHA!$AQ$40&""),0)+IFERROR(VALUE(FICHA!$AS$40&""),0) -> 0 | AN12: =$L$11 -> Sutura | AO12: Guia | AQ12: 9 | AR12: 3000 | BA12: atr_Destreza | BB12: =ADDRESS(ROW(FICHA!L19),COLUMN(FICHA!L19),4) -> L19
B13: História | C13: Instrumento | E13: Efeito | F13: Escolher | G13: Condicional | H13: Cego | I13: Reencarnado · Sem Técnica | L13: Torrente | AB13: Religião | AC13: Inteligência | AE13: Torre | AF13: 3 | AG13: 1 | AH13: não | AJ13: perícias treinadas | AK13: =COUNTIF(FICHA!$D$64:$D$74,TRUE)+COUNTIF(FICHA!$T$63:$T$74,TRUE) -> 0 | AN13: =$L$12 -> Perímetro | AO13: Guia | AQ13: 10 | AR13: 3700 | BA13: atr_Constituição | BB13: =ADDRESS(ROW(FICHA!T19),COLUMN(FICHA!T19),4) -> T19
B14: Hierarquia | C14: Jogatina | F14: Fica | G14: Fraqueza | H14: Amedrontado | I14: Feto · Sem Técnica | L14: Explosivo | AB14: História | AC14: Inteligência | AE14: Traje 1 + Broquel | AF14: 2 | AG14: 5 | AH14: sim | AJ14: ofícios treinados | AK14: =COUNTIF(FICHA!$D$79:$D$84,TRUE)+COUNTIF(FICHA!$Q$79:$Q$83,TRUE) -> 0 | AN14: =$L$13 -> Torrente | AO14: Emanador | AQ14: 11 | AR14: 4400 | BA14: atr_Inteligência | BB14: =ADDRESS(ROW(FICHA!AB19),COLUMN(FICHA!AB19),4) -> AB19
B15: Medicina | F15: Mais Um | G15: Frágil | H15: Envenenado | I15: Corpo Amaldiçoado | L15: Arremate | AB15: Hierarquia | AC15: Inteligência | AE15: Traje 1 + Médio | AF15: 3 | AG15: 3 | AH15: sim | AJ15: especializações | AK15: =COUNTIF(FICHA!$E$64:$E$74,TRUE)+COUNTIF(FICHA!$E$79:$E$84,TRUE)+COUNTIF(FICHA!$R$79:$R$83,TRUE)+COUNTIF(FICHA!$U$63:$U$74,TRUE) -> 0 | AN15: =$L$14 -> Explosivo | AO15: Emanador | AQ15: 12 | AR15: 5300 | BA15: atr_Essência | BB15: =ADDRESS(ROW(FICHA!AJ19),COLUMN(FICHA!AJ19),4) -> AJ19
B16: Sobrevivência | F16: Rajada | G16: Barulho | H16: Atordoado | I16: Restrição Celestial · sem energia | L16: Servo | AB16: Medicina | AC16: Inteligência | AE16: Traje 1 + Torre | AF16: 4 | AG16: 1 | AH16: sim | AJ16: Corpo que sobra | AK16: =DADOS!$AK$10-DADOS!$AK$15 -> 0 | AN16: =$L$15 -> Arremate | AO16: Emanador | AQ16: 13 | AR16: 6200 | BA16: atr_base_Força | BB16: =ADDRESS(ROW(FICHA!D21),COLUMN(FICHA!D21),4) -> D21
B17: Natureza | F17: Salto | G17: Assinatura | L17: Matilha | AB17: Sobrevivência | AC17: Inteligência | AE17: Traje 2 + Broquel | AF17: 3 | AG17: 5 | AH17: sim | AJ17: rota do ofício | AK17: =IF((MAX(0,DADOS!$AK$13-9)+MAX(0,DADOS!$AK$14-2))<=DADOS!$AK$16,1,IF((MAX(0,DADOS!$AK$13-10)+MAX(0,DADOS!$AK$14-0))<=DADOS!$AK$16,2,IF((MAX(0,DADOS!$AK$13-9)+MAX(0,DADOS!$AK$14-2))<=(MAX(0,DADOS!$AK$13-10)+MAX(0,DADOS!$AK$14-0)),1,2))) -> 1 | AN17: =$L$16 -> Servo | AO17: Evocador | AQ17: 14 | AR17: 7100 | BA17: atr_base_Destreza | BB17: =ADDRESS(ROW(FICHA!L21),COLUMN(FICHA!L21),4) -> L21
B18: Lidar com Animais | F18: Contorno | G18: Aquecer | L18: Coro | AB18: Natureza | AC18: Inteligência | AE18: Traje 2 + Médio | AF18: 4 | AG18: 3 | AH18: sim | AJ18: perícias por arma | AK18: =IF(OR(FICHA!$D$11="Guia",FICHA!$D$11="Emanador",FICHA!$D$11="Evocador"),IF(FICHA!$AK$65="2 armas (-4 pericias)",4,IF(FICHA!$AK$65="1 arma (-2 pericias)",2,0)),0) -> 0 | AN18: =$L$17 -> Matilha | AO18: Evocador | AQ18: 15 | AR18: 8200 | BA18: atr_base_Constituição | BB18: =ADDRESS(ROW(FICHA!T21),COLUMN(FICHA!T21),4) -> T21
B19: Tecnologia | F19: Precisão | G19: Dívida | AB19: Lidar com Animais | AC19: Inteligência | AE19: Traje 2 + Torre | AF19: 5 | AG19: 1 | AH19: sim | AJ19: perícias da rota | AK19: =IF(DADOS!$AK$17=1,9,10)-DADOS!$AK$18 -> 9 | AN19: =$L$18 -> Coro | AO19: Evocador | AQ19: 16 | AR19: 9300 | BA19: atr_base_Inteligência | BB19: =ADDRESS(ROW(FICHA!AB21),COLUMN(FICHA!AB21),4) -> AB21
B20: Sentir Energia | F20: Certeiro | G20: Peso Morto | AB20: Tecnologia | AC20: Inteligência | AE20: Traje 3 + Broquel | AF20: 4 | AG20: 5 | AH20: sim | AJ20: ofícios da rota | AK20: =IF(DADOS!$AK$17=1,2,0) -> 2 | AQ20: 17 | AR20: 10400 | BA20: atr_base_Essência | BB20: =ADDRESS(ROW(FICHA!AJ21),COLUMN(FICHA!AJ21),4) -> AJ21
B21: Percepção | F21: Inescapável | G21: Sem Volta | AB21: Sentir Energia | AC21: Essência | AE21: Traje 3 + Médio | AF21: 5 | AG21: 3 | AH21: sim | AJ21: Corpo nas perícias | AK21: =MAX(0,DADOS!$AK$13-DADOS!$AK$19) -> 0 | AQ21: 18 | AR21: 11700 | BA21: vida | BB21: =ADDRESS(ROW(FICHA!D26),COLUMN(FICHA!D26),4) -> D26
B22: Persuasão | F22: Fura | G22: Restrição Própria | AB22: Percepção | AC22: Essência | AE22: Traje 3 + Torre | AF22: 6 | AG22: 1 | AH22: sim | AJ22: Corpo nos ofícios | AK22: =MAX(0,DADOS!$AK$14-DADOS!$AK$20) -> 0 | AQ22: 19 | AR22: 13000 | BA22: vida_max | BB22: =ADDRESS(ROW(FICHA!J26),COLUMN(FICHA!J26),4) -> J26
B23: Enganação | F23: Corrói | AB23: Persuasão | AC23: Essência | AE23: Revestimento 1 + Broquel | AF23: 5 | AG23: 0 | AH23: sim | AJ23: Corpo por escolher | AK23: =DADOS!$AK$16-DADOS!$AK$21-DADOS!$AK$22 -> 0 | AQ23: 20 | AR23: 14300 | BA23: vida_temp | BB23: =ADDRESS(ROW(FICHA!AF26),COLUMN(FICHA!AF26),4) -> AF26
B24: Intimidação | F24: Sem Cobertura | AB24: Enganação | AC24: Essência | AE24: Revestimento 1 + Médio | AF24: 6 | AG24: 0 | AH24: sim | AJ24: treinos a mais | AK24: =MAX(0,-DADOS!$AK$23) -> 0 | AQ24: 21 | AR24: 15800 | BA24: vida_delta | BB24: =ADDRESS(ROW(FICHA!AM26),COLUMN(FICHA!AM26),4) -> AM26
B25: Atuação | F25: De Novo | AB25: Intimidação | AC25: Essência | AE25: Revestimento 1 + Torre | AF25: 7 | AG25: 0 | AH25: sim | AJ25: perícias que faltam | AK25: =MAX(0,DADOS!$AK$19-DADOS!$AK$13) -> 9 | AQ25: 22 | AR25: 17300 | BA25: energia | BB25: =ADDRESS(ROW(FICHA!D30),COLUMN(FICHA!D30),4) -> D30
B26: Provocar | F26: Toca a Alma | AB26: Atuação | AC26: Essência | AE26: Revestimento 2 + Broquel | AF26: 6 | AG26: 0 | AH26: sim | AJ26: ofícios que faltam | AK26: =MAX(0,DADOS!$AK$20-DADOS!$AK$14) -> 2 | AQ26: 23 | AR26: 18800 | BA26: energia_max | BB26: =ADDRESS(ROW(FICHA!J30),COLUMN(FICHA!J30),4) -> J30
F27: Terreno | AB27: Provocar | AC27: Essência | AE27: Revestimento 2 + Médio | AF27: 7 | AG27: 0 | AH27: sim | AJ27: perícias que faltam sem ofício | AK27: =MAX(0,10-DADOS!$AK$13) -> 10 | AQ27: 24 | AR27: 20500 | BA27: energia_temp | BB27: =ADDRESS(ROW(FICHA!AF30),COLUMN(FICHA!AF30),4) -> AF30
F28: Anteparo | AE28: Revestimento 2 + Torre | AF28: 8 | AG28: 0 | AH28: sim | AJ28: Corpo por escolher sem ofício | AK28: =DADOS!$AK$16-MAX(0,DADOS!$AK$13-10)-MAX(0,DADOS!$AK$14-0) -> 0 | AQ28: 25 | AR28: 22200 | BA28: energia_delta | BB28: =ADDRESS(ROW(FICHA!AM30),COLUMN(FICHA!AM30),4) -> AM30
F29: Prende | AE29: Revestimento 3 + Broquel | AF29: 7 | AG29: 0 | AH29: sim | AJ29: testes treinados | AK29: =COUNTIF(FICHA!$AF$79:$AF$82,TRUE) -> 0 | AQ29: 26 | AR29: 23900 | BA29: integridade | BB29: =ADDRESS(ROW(FICHA!D34),COLUMN(FICHA!D34),4) -> D34
F30: Cerca | AE30: Revestimento 3 + Médio | AF30: 8 | AG30: 0 | AH30: sim | AJ30: sem energia | AK30: =IF(FICHA!$X$11="Restrição Celestial · sem energia",1,0) -> 0 | AQ30: 27 | AR30: 25600 | BA30: integridade_max | BB30: =ADDRESS(ROW(FICHA!J34),COLUMN(FICHA!J34),4) -> J34
F31: Puxa | AE31: Revestimento 3 + Torre | AF31: 9 | AG31: 0 | AH31: sim | AJ31: sem técnica | AK31: =IF(ISNUMBER(SEARCH(" · Sem Técnica",FICHA!$X$11)),1,0) -> 0 | AQ31: 28 | AR31: 27300 | BA31: integridade_temp | BB31: =ADDRESS(ROW(FICHA!AF34),COLUMN(FICHA!AF34),4) -> AF34
F32: Desarma o Feitiço | AJ32: técnica marcial | AK32: =IF(OR(FICHA!$X$11="Corpo Amaldiçoado",FICHA!$X$11="Restrição Celestial · sem energia"),1,0) -> 0 | AQ32: 29 | AR32: 29000 | BA32: integridade_delta | BB32: =ADDRESS(ROW(FICHA!AM34),COLUMN(FICHA!AM34),4) -> AM34
F33: Impulso | AJ33: refino escolhido | AK33: =MIN(IFERROR(VALUE(FICHA!$AO$40&""),0),DADOS!$AK$5) -> 0 | AQ33: 30 | AR33: 30700 | BA33: estagio_alma | BB33: =ADDRESS(ROW(FICHA!D37),COLUMN(FICHA!D37),4) -> D37
F34: Trava | AJ34: refino atual | AK34: =MIN(10,FICHA!$O$57+DADOS!$AK$33) -> 1 | BA34: defesa | BB34: =ADDRESS(ROW(FICHA!D43),COLUMN(FICHA!D43),4) -> D43
F35: Abre Ferida | AJ35: aptidões a mais no teto | AK35: =MAX(0,DADOS!$AK$33-MAX(0,CEILING((10-DADOS!$AK$5+DADOS!$AK$33)/2,1)-1))*(2-1) -> 0 | BA35: proteção | BB35: =ADDRESS(ROW(FICHA!O43),COLUMN(FICHA!O43),4) -> O43
F36: Sobrecarga | AJ36: máximo de aptidões | AK36: =2+1*DADOS!$AK$31+DADOS!$AK$33+DADOS!$AK$35 -> 2 | BA36: equipamento | BB36: =ADDRESS(ROW(FICHA!Z43),COLUMN(FICHA!Z43),4) -> Z43
F37: Firmeza | AJ37: aptidões anotadas | AK37: =COUNTIF(FICHA!$V$124:$V$135,"?*") -> 2 | BA37: iniciativa | BB37: =ADDRESS(ROW(FICHA!AK43),COLUMN(FICHA!AK43),4) -> AK43
F38: Guarda | AJ38: escolhas de Leque | AK38: =IFERROR(VALUE(FICHA!$AS$40&""),0) -> 0 | BA38: cd de feitiço | BB38: =ADDRESS(ROW(FICHA!D47),COLUMN(FICHA!D47),4) -> D47
F39: Pressa | AJ39: Passivas do Leque anotadas | AK39: =COUNTIF(FICHA!$AF$139:$AF$144,"?*") -> 0 | BA39: conjuração | BB39: =ADDRESS(ROW(FICHA!O47),COLUMN(FICHA!O47),4) -> O47
F40: Enfraquece | BA40: corpo a corpo | BB40: =ADDRESS(ROW(FICHA!Z47),COLUMN(FICHA!Z47),4) -> Z47
...

Sheet GLOSSÁRIO
B1: O GLOSSÁRIO — o que cada coisa da ficha quer dizer | W1: Capítulo 1 · 2 · 13
B4: ATRIBUTOS | M4: O número é o modificador. Escala de 0 a 6, sem tabela de conversão.
E5: ATRIBUTO | K5: O QUE GOVERNA
E6: Força | K6: Quanto o seu corpo aguenta e impõe, na base do músculo. Governa: ataque corpo a corpo, agarrar, quebrar, carregar
E7: Destreza | K7: Sua velocidade e precisão — o corpo respondendo rápido, a mira certa. Governa: ataque à distância, Defesa, iniciativa, furtividade
E8: Constituição | K8: Sua resistência bruta a dano e a desgaste. Governa: pontos de vida
E9: Inteligência | K9: O que você sabe e deduz — o raciocínio frio. Governa: conhecimento, investigação, reconhecer uma técnica pelo catálogo
E10: Essência | K10: Sua sensibilidade à energia amaldiçoada e às pessoas — o que você sente, não o que você calcula. Governa: perceber energia amaldiçoada, trato social, hierarquia, negociar Pactos
B12: PERÍCIAS | M12: 9 de 23 na criação — ou 10, trocando os dois ofícios da Origem.
B13: ATRIBUTO | E13: NOME | K13: O QUE FAZ
B14: Acrobacia | E14: Destreza | K14: Mede seu equilíbrio e o controle fino do próprio corpo em movimento. Exemplo: equilíbrio, cair sem se machucar, escapar de um agarrão, passar por espaço 3 apertado.
B15: Atletismo | E15: Força | K15: Mede seu corpo em esforço físico direto. Exemplo: correr, escalar, nadar, saltar, carregar alguém que não consegue andar.
B16: Atuação | E16: Essência | K16: Mede sua capacidade de performar ou sustentar um papel diante de alguém. Exemplo: representar, cantar, tocar para uma plateia, sustentar um personagem que não é você.
B17: Enganação | E17: Essência | K17: Mede sua capacidade de mentir de um jeito convincente. Exemplo: mentir, blefar, se passar por outro.
B18: Furtividade | E18: Destreza | K18: Mede sua capacidade de passar despercebido. Exemplo: mover-se sem ser visto nem ouvido.
B19: Hierarquia | E19: Inteligência | K19: Mede seu conhecimento da política entre clãs e feiticeiros — quem manda em quem. Exemplo: os clãs, a política, quem manda em quem e quem deve o quê a quem. Diz o que você pode pedir, a quem, e o que vai custar.
B20: História | E20: Inteligência | K20: Mede sua memória do que já aconteceu e de quem estava lá. Exemplo: o que aconteceu e quem estava lá, no mundo comum e no registro das famílias.
B21: Intimidação | E21: Essência | K21: Mede sua capacidade de fazer alguém recuar pela ameaça ou pela presença. Exemplo: ameaçar, dominar pela presença, fazer alguém recuar.
B22: Intuição | E22: Inteligência | K22: Mede sua leitura racional do comportamento alheio — dedução sobre gente. Exemplo: ler a pessoa pelo que ela faz: a inconsistência na história, o detalhe que não fecha, a motivação atrás do pedido. É dedução sobre gente, e por isso é Inteligência.
B23: Investigação | E23: Inteligência | K23: Mede sua capacidade de vasculhar um lugar e ligar pistas soltas. Exemplo: vasculhar, deduzir, ligar duas pistas que ninguém tinha ligado.
B24: Lidar com Animais | E24: Inteligência | K24: Mede sua capacidade de acalmar, montar ou conduzir um animal. Exemplo: acalmar, montar, conduzir, mandar num bicho. Vale para o que não é bicho mas se comporta como um.
... B36: Tecnologia | E36: Inteligência | K36: Mede seu domínio de equipamento e sistema moderno. Exemplo: computador, câmera, rede, equipamento moderno.
B38: OFÍCIOS | M38: 2 de 11 na criação. O atributo é do mestre, na hora — não é fixo.
E39: NOME | K39: O QUE FAZ
E40: Alfaiate | K40: Mede sua capacidade de cortar, costurar e remendar tecido. Exemplo: tecido, corte, remendo. O uniforme que aguenta energia amaldiçoada sai daqui, e o traje sob medida também.
E41: Arrombamento | K41: Mede sua capacidade de vencer uma trava sem ter a chave. Exemplo: tranca, alarme, cofre, janela que não devia abrir.
E42: Burocracia | K42: Mede seu domínio da máquina administrativa jujutsu por dentro. Exemplo: a máquina jujutsu por dentro: relatório, requisição, quem assina o quê, como se pede uma janela e como se encobre o que não devia ter sido visto.
E43: Caligrafia | K43: Mede sua capacidade de produzir documento escrito, oficial ou falsificado. Exemplo: talismã, papel de barreira, documento oficial. E documento oficial que não é oficial.
E44: Condução | K44: Mede sua capacidade de operar um veículo. Exemplo: carro, moto, van, o que estiver na garagem.
E45: Culinária | K45: Mede sua capacidade de cozinhar de verdade. Exemplo: cozinhar de verdade, para gente ou para o que aceitar comida.
E46: Entalhador | K46: Mede sua capacidade de moldar madeira, pedra ou osso. Exemplo: madeira, pedra, osso. Fazer o corpo que vai receber alguma coisa.
E47: Forja | K47: Mede sua capacidade de fabricar, afiar e manter arma e ferramenta. Exemplo: fazer, afiar e manter arma, e cuidar de ferramenta amaldiçoada sem estragar o que tem dentro.
E48: Herbalismo | K48: Mede seu conhecimento prático de planta, aplicado a cura e a veneno. Exemplo: planta que cura, planta que mata, chá, unguento, e o que dá para fazer no mato quando não tem hospital.
E49: Instrumento | K49: Mede sua capacidade de tocar um instrumento musical. Exemplo: um instrumento, escolhido no treino.
E50: Jogatina | K50: Mede sua capacidade de jogar um jogo de aposta e ler quem está na mesa. Exemplo: carta, dado, aposta, e ler a mesa enquanto joga.
B52: CONCEITOS
E53: TERMO | K53: O QUE SIGNIFICA
E54: Treino | K54: Ter a perícia ou o ofício marcado na ficha. O mestre põe uma CD; com Destreza 3 e maestria 1, uma Furtividade treinada rola d20 + 4, sem treino d20 + 3 (capítulo 2).
E55: Maestria | K55: O bônus que mede o tempo de estrada do personagem: começa em 1 e sobe um ponto a cada oito níveis. Entra em toda rolagem de ataque, na CD dos seus feitiços, e no que você treinou (capítulo 1).
E56: Refino | K56: O eixo de controle da ficha: é o refino que compra as suas Aptidões. Poder é quanto você tem — Refino é quanto você não desperdiça (capítulo 13).

Sheet INVOCAÇÃO
D1: A FICHA DA INVOCAÇÃO | AF1: Capítulo 16 · Projeto - M
D4: 1 | G4: O DONO
D6: NÍVEL DO DONO | O6: ESSÊNCIA DO DONO | Z6: INTELIGÊNCIA DO DONO | AK6: MAESTRIA
D7: =FICHA!AH11 -> 2 | O7: =FICHA!AJ19 -> 0 | Z7: =FICHA!AB19 -> 0 | AK7: =(1+COUNTIF(DADOS_INV!$AH$3:$AH$5,"<="&$D$7)) -> 1
A8: INVOCAÇÃO
D10: MARCOS | O10: MAIOR CLASSE
D11: =COUNTIF(DADOS_INV!$AG$3:$AG$9,"<="&$D$7) -> 0 | O11: =COUNTIF(DADOS_INV!$AI$3:$AI$9,"<="&$D$7) -> 1
D16: 2 | G16: A INVOCAÇÃO
D18: NOME | Z18: TIPO | AK18: TRILHA
Z19: Técnica | AK19: Servo
D21: SINTONIA
D22: Presa
D27: 3 | G27: OS ATRIBUTOS DELA
D29: FOR | L29: DES | T29: CON | AB29: INT | AJ29: ESS
A30: PROJETO - M | D30: 0 | L30: 0 | T30: 0 | AB30: 0 | AJ30: 0
D32: Força | L32: Destreza | T32: Constituição | AB32: Inteligência | AJ32: Essência
D34: PONTOS GASTOS | O34: DISPONÍVEIS | Z34: CONFERÊNCIA
D35: =$D$30+$L$30+$T$30+$AB$30+$AJ$30 -> 0 | O35: =(9+$D$11) -> 9 | Z35: =IF($D$30+$L$30+$T$30+$AB$30+$AJ$30>(9+$D$11),"Estourou o total",IF(MAX($D$30,$L$30,$T$30,$AB$30,$AJ$30)>6,"Estourou o teto de 6",IF($D$30+$L$30+$T$30+$AB$30+$AJ$30<(9+$D$11),"Sobrou ponto","Ok"))) -> Sobrou ponto
D37: Distribua 9 pontos, nenhum acima de 3. A cada marco ela ganha 1 ponto, até o teto de 6. É a mesma regra da sua ficha.
D40: 4 | G40: ACERTO, DEFESA E TESTES DE RESISTÊNCIA
D42: ATRIBUTO DO ACERTO | O42: ACERTO | Z42: DEFESA USA, DO DONO | AK42: DEFESA
D43: Força | O43: {=IF($D$43="","",INDEX(DADOS_INV!$AK$3:$AK$7,MATCH($D$43,DADOS_INV!$C$2:$C$6,0))+$AK$7)} -> 1 | Z43: Inteligência | AK43: =10+$L$30+FLOOR(IF($Z$43="Essência",$O$7,$Z$7)/2,1) -> 10
D45: CRÍTICO COM | O45: QUAL TR ELA TREINA | Z45: O FÍSICO DELA USA
D46: =IF($D$22="Presa","19 ou 20","20") -> 19 ou 20 | O46: Físico | Z46: Força
D48: TESTES DE RESISTÊNCIA · ela treina um, e você escolhe qual no campo acima
D49: TESTE | K49: Extra | L49: USA | Q49: d20 + | Z49: TESTE | AG49: Extra | AH49: USA | AM49: d20 +
D50: Físico | L50: For ou Des | Q50: {=IFERROR(INDEX(DADOS_INV!$AK$3:$AK$7,MATCH($Z$46,DADOS_INV!$C$2:$C$6,0))+IF($O$46="Físico",$AK$7,0)+N($K$50),"")} -> 1 | Z50: Vigor | AH50: Con | AM50: {=IFERROR(INDEX(DADOS_INV!$AK$3:$AK$7,MATCH("Constituição",DADOS_INV!$C$2:$C$6,0))+IF($O$46="Vigor",$AK$7,0)+N($AG$50),"")} -> 0
D51: Intelecto | L51: Int | Q51: {=IFERROR(INDEX(DADOS_INV!$AK$3:$AK$7,MATCH("Inteligência",DADOS_INV!$C$2:$C$6,0))+IF($O$46="Intelecto",$AK$7,0)+N($K$51),"")} -> 0 | Z51: Espírito | AH51: Ess | AM51: {=IFERROR(INDEX(DADOS_INV!$AK$3:$AK$7,MATCH("Essência",DADOS_INV!$C$2:$C$6,0))+IF($O$46="Espírito",$AK$7,0)+N($AG$51),"")} -> 0
D56: 5 | G56: VIDA E MORTE
D58: VIDA MÁXIMA | O58: VIDA AGORA | Z58: CORPOS EM CAMPO | AK58: ÁREA BATE ×
D59: =IF($Z$19="","",IF(IFERROR(VLOOKUP($AK$19,DADOS_INV!$N$3:$R$5,4,FALSE),"cru")="forte",FLOOR(2.5*(IFERROR(VLOOKUP($Z$19,DADOS_INV!$K$3:$L$6,2,FALSE),0)+2*$D$7)+$T$30*$D$7,1),(IFERROR(VLOOKUP($Z$19,DADOS_INV!$K$3:$L$6,2,FALSE),0)+(2+$T$30)*$D$7))+IF($D$22="Parrudo",5*$AK$7,0)) -> 15 | O59: =D59 -> 15 | Z59: =IFERROR(VLOOKUP($AK$19,DADOS_INV!$N$3:$R$5,2,FALSE),"") -> 1 | AK59: =IFERROR(VLOOKUP($AK$19,DADOS_INV!$N$3:$R$5,5,FALSE),"") -> 1
D62: A BARRA | O62: =IFERROR(__xludf.DUMMYFUNCTION("IFERROR(SPARKLINE({MAX(0,MIN(N($O$59),N($D$59))),MAX(0,N($D$59)-MAX(0,N($O$59)))},{""charttype"",""bar"";""color1"",IF(IFERROR(N($O$59)/N($D$59),0)<=0.25,""#C2334D"",IF(IFERROR(N($O$59)/N($D$59),0)<=0.5,""#D89B3A"",""#E8DCD4""));""color2"",""#998ba2""}),"&"""&""""&""""&"""""")"),"")
D64: RÉGUA DA MORTE | O64: METADE DELA | Z64: VOLTA COM
D65: =IF($Z$19="","",5*(IFERROR(VLOOKUP($Z$19,DADOS_INV!$K$3:$L$6,2,FALSE),0)+(2+$T$30)*$D$7)) -> 30 | O65: =IF($Z$19="","",5*(IFERROR(VLOOKUP($Z$19,DADOS_INV!$K$3:$L$6,2,FALSE),0)+(2+$T$30)*$D$7)/2) -> 15 | Z65: =IF($Z$19="","",FLOOR($D$59/2,1)) -> 7
D67: MORRE DE VEZ
D68: Quando o dano que passar de zero for maior que a metade da régua, ou quando um golpe só causar a régua inteira. Fora desses dois casos ela só cai, e você reinvoca.
D70: No zero ela sai do campo. Ela não fica Inconsciente e não ganha Sequela nem Cicatriz. Reinvocar custa os PE de novo, e ela volta com metade da vida; a vida cheia volta no descanso longo.
D73: 6 | G73: O ORÇAMENTO
D75: ORÇAMENTO
D76: =FLOOR((8+4*$D$11)*IFERROR(VLOOKUP($AK$19,DADOS_INV!$N$3:$R$5,3,FALSE),1),1) -> 12
...

Sheet CATÁLOGO
D1: O CATÁLOGO — o que dá para comprar | AF1: Capítulo 16
D4: TRAÇO | U4: O corpo dela. Vale sempre, sem gastar ação.
D5: PONTOS | H5: NOME | P5: O QUE FAZ
D6: 2 | H6: Escalada | P6: Sobe parede e teto sem teste
D7: 2 | H7: Nado | P7: Move na água sem penalidade. Rio, cisterna, tanque alagado de estação
D8: 3 | H8: Fala | P8: Ela fala, e dá para conversar com ela
D9: 5 | H9: Faro | P9: Rastreia por cheiro e por energia. Pega rastro velho de horas
D10: 5 | H10: Vigia | P10: O que ela vê e ouve, você vê e ouve também
D11: 7 | H11: Miúdo | P11: Ocupa espaço menor e passa por vão. Duto, grade de bueiro, folga embaixo da porta
D12: 8 | H12: Voo | P12: O deslocamento dela passa a ser de voo também
D13: 8 | H13: Montaria | P13: Carrega uma pessoa ou mais, dependendo do tamanho
D14: 8 | H14: Fisgada | P14: Prende à distância. Ela alcança, engancha, e quem ia fugir para de conseguir
D15: 8 | H15: Emboscada | P15: Surge do chão, fora do alcance de visão
D16: 8 | H16: Jorro | P16: Ataca em linha ou em área
D17: 8 | H17: Graúdo | P17: Ocupa espaço maior e barra passagem
D18: 8 | H18: Remoto | P18: Funciona além dos 18 metros da amarra. Dentro da cena, para qualquer um; fora da cena, com requisito
D21: COMANDO | U21: O que ela faz quando você gasta a Ação Padrão comandando.
D22: PONTOS | H22: NOME | P22: O QUE FAZ
D23: 0 | H23: Investir | P23: O ataque. Toda invocação tem
D24: 4 | H24: Agarrar | P24: Prende o alvo
D25: 4 | H25: Arrastar | P25: Move o alvo, ou se move levando ele. Tira alguém de cima de uma beirada, ou põe
D26: 4 | H26: Buscar | P26: Pega um objeto, ou rastreia de forma ativa
D27: 4 | H27: Cavar | P27: Abre buraco, desenterra, revira o terreno. Faz rota onde não havia rota
D28: 8 | H28: Interpor | P28: Se põe entre você e o golpe. O corpo dela recebe o que ia em você
D29: 8 | H29: Chamariz | P29: O alvo tem de vir para cima dela. Você escolhe em quem a coisa está prestando atenção
D32: INVENTAR O SEU | U32: Escreva o efeito, ache na régua o preço, e leve para o mestre aprovar
D33: Régua de TRAÇO
D34: 2 | H34: Muda como ela anda, e só ela
D35: 3 | H35: Muda o que ela comunica
D36: 5 | H36: Muda o que ela percebe
D37: 7 | H37: Muda que espaço ela ocupa, a um passo de mexer no tabuleiro
D38: 8 | H38: Encosta em outra criatura ou no ambiente: carrega, prende, empurra, barra, alcança além do alcance, aparece onde não dava
D40: Régua de COMANDO
D41: 0 | H41: É o ataque
D42: 4 | H42: Faz uma coisa com um alvo ou um objeto
D43: 8 | H43: Protege você, ou nega a ação de outro
D45: O QUE O ORÇAMENTO NÃO COMPRA
D46: Dado de dano | R46: O teto de uma Rotina já governa a saída. Um Traço que dê +1d6 não existe
D47: Qualquer coisa que cresça com refino | R47: Refino cresce muito mais rápido que a ficha dela, e ela passaria de você
D48: Atributo | R48: Os cinco já saem do arranjo dela, e comprar de novo é pagar duas vezes
...

Sheet DADOS_INV
A1: tipos | B1: trilhas | C1: atributos | D1: trs | E1: sintonia | F1: defesa_de | G1: fisico_de | H1: traco | I1: comando | K1: tab_tipos | N1: tab_trilhas | T1: tab_traco | W1: tab_comando | Z1: tab_investir | AD1: tab_trs | AP1: degrau_traco | AS1: degrau_comando | AU1: degrau_traco | AX1: degrau_comando
A2: talismã | B2: Servo | C2: Força | D2: Físico | E2: — | F2: Essência | G2: Força | H2: — | I2: — | K2: tipo | L2: base | N2: trilha | O2: corpos | P2: mult | Q2: corpo | R2: area | T2: traço | U2: pontos | W2: comando | X2: pontos | Z2: de | AA2: uma | AB2: matilha | AD2: tr | AE2: atributo | AG2: e_marcos | AH2: e_maestria | AI2: e_classe | AK2: espelho | AM2: campo | AN2: célula | AP2: — | AS2: — | AU2: — | AX2: —
A3: corpo amaldiçoado | B3: Matilha | C3: Destreza | D3: Vigor | E3: Presa | F3: Inteligência | G3: Destreza | H3: Escalada | I3: Investir | K3: talismã | L3: 1 | N3: Servo | O3: 1 | P3: 1.5 | Q3: forte | R3: 1 | T3: — | U3: 0 | W3: — | X3: 0 | Z3: 2 | AA3: 1d6 | AB3: 2 | AD3: Físico | AE3: Força | AG3: 6 | AH3: 10 | AI3: 1 | AK3: ='INVOCAÇÃO'!$D$30 -> 0 | AM3: nivel | AN3: D7 | AP3: 2 | AS3: 0 | AU3: 2 | AX3: 0
A4: técnica | B4: Coro | C4: Constituição | D4: Intelecto | E4: Parrudo | H4: Nado | I4: Agarrar | K4: corpo amaldiçoado | L4: 1 | N4: Matilha | O4: 5 | P4: 1 | Q4: forte | R4: 1.5 | T4: Escalada | U4: 2 | W4: Investir | X4: 0 | Z4: 5 | AA4: 4d6 | AB4: 1d6 | AD4: Vigor | AE4: Constituição | AG4: 10 | AH4: 18 | AI4: 5 | AK4: ='INVOCAÇÃO'!$L$30 -> 0 | AM4: ess_dono | AN4: O7 | AP4: 3 | AS4: 4 | AU4: 3 | AX4: 4
A5: maldição domada | C5: Inteligência | D5: Espírito | E5: Voz | H5: Fala | I5: Arrastar | K5: técnica | L5: 2 | N5: Coro | O5: 1 | P5: 1 | Q5: cru | R5: 1 | T5: Nado | U5: 2 | W5: Agarrar | X5: 4 | Z5: 9 | AA5: 6d6 | AB5: 2d6 | AD5: Intelecto | AE5: Inteligência | AG5: 14 | AH5: 26 | AI5: 9 | AK5: ='INVOCAÇÃO'!$T$30 -> 0 | AM5: int_dono | AN5: Z7 | AP5: 5 | AS5: 8 | AU5: 5 | AX5: 8
C6: Essência | H6: Faro | I6: Buscar | K6: maldição domada | L6: 3 | T6: Fala | U6: 3 | W6: Arrastar | X6: 4 | Z6: 13 | AA6: 8d6 | AB6: 3d6 | AD6: Espírito | AE6: Essência | AG6: 18 | AI6: 13 | AK6: ='INVOCAÇÃO'!$AB$30 -> 0 | AM6: maestria | AN6: AK7 | AP6: 7 | AU6: 7
H7: Vigia | I7: Cavar | T7: Faro | U7: 5 | W7: Buscar | X7: 4 | Z7: 17 | AA7: 10d6 | AB7: 4d6 | AG7: 22 | AI7: 17 | AK7: ='INVOCAÇÃO'!$AJ$30 -> 0 | AM7: marcos | AN7: D11 | AP7: 8 | AU7: 8
H8: Miúdo | I8: Interpor | T8: Vigia | U8: 5 | W8: Cavar | X8: 4 | Z8: 21 | AA8: 13d6 | AB8: 5d6 | AG8: 26 | AI8: 21 | AM8: classe | AN8: O11
H9: Voo | I9: Chamariz | T9: Miúdo | U9: 7 | W9: Interpor | X9: 8 | Z9: 26 | AA9: 15d6 | AB9: 6d6 | AG9: 30 | AI9: 26 | AM9: nome | AN9: D19
H10: Montaria | T10: Voo | U10: 8 | W10: Chamariz | X10: 8 | AM10: tipo | AN10: Z19
H11: Fisgada | T11: Montaria | U11: 8 | AM11: trilha | AN11: AK19
H12: Emboscada | T12: Fisgada | U12: 8 | AM12: sintonia | AN12: D22
H13: Jorro | T13: Emboscada | U13: 8 | AM13: pontos_atributo | AN13: D35
H14: Graúdo | T14: Jorro | U14: 8 | AM14: pontos_disp | AN14: O35
H15: Remoto | T15: Graúdo | U15: 8 | AM15: aviso_atributo | AN15: Z35
T16: Remoto | U16: 8 | AM16: atr_acerto | AN16: D43
AM17: acerto | AN17: O43
AM18: defesa_de | AN18: Z43
AM19: defesa | AN19: AK43
AM20: critico | AN20: D46
AM21: tr_treinado | AN21: O46
AM22: fisico_de | AN22: Z46
AM23: tr_Físico | AN23: Q50
AM24: tr_extra_Físico | AN24: K50
AM25: tr_Vigor | AN25: AM50
AM26: tr_extra_Vigor | AN26: AG50
AM27: tr_Intelecto | AN27: Q51
AM28: tr_extra_Intelecto | AN28: K51
... AM77: comando_6 | AN77: Z85
