Workbook

Sheet CARTEIRA
C2: 呪術廻戦 | L2: ERA DA REVOLUÇÃO | AH2: ="Nº M-"&SUBSTITUTE(DADOS!$B$1,".","")&"-"&IF(FICHA!D3="","····",UPPER(LEFT(FICHA!D3,4))) -> Nº M-104-ERA
L3: Carteira de registro · Documento oficial | AH3: ="Emitida "&TEXT(TODAY(),"dd.mm.yyyy") -> Emitida 09.09.2026
O8: PORTADOR
O9: =IF(FICHA!D2="","—",FICHA!D2) -> ERA DA REVOLUÇÃO
O17: CAMINHO | Z17: TRILHA | AK17: ORIGEM
O18: =IF(FICHA!D11="","—",FICHA!D11) -> Bastião | Z18: =IF(FICHA!N11="","—",FICHA!N11) -> Muro | AK18: =IF(FICHA!X11="","—",FICHA!X11) -> Latente
O21: NÍVEL | Z21: MESA DE ORIGEM | AK21: REGISTRADO POR
O22: =IF(FICHA!AH11="","—",FICHA!AH11) -> 2
O26: TÉCNICA DECLARADA
AK34: SELO REGISTRADO
AH38: =IF(FICHA!D11="","—",UPPER(LEFT(FICHA!D11,3))&"-"&TEXT(FICHA!AH11,"00")) -> BAS-02

Sheet FICHA
D2: ERA DA REVOLUÇÃO | AH2: CATÁLOGO
D3: =IF(CARTEIRA!O9="","",CARTEIRA!O9) -> ERA DA REVOLUÇÃO | AH3: =IF(DADOS!$B$1=DADOS!$D$1,"v"&DADOS!$B$1&" · em dia","⚠ v"&DADOS!$B$1&" · a atual é a v"&DADOS!$D$1) -> v104 · em dia
A8: PROJETO M | D8: 1 | G8: PERFIL AMALDIÇOADO
D10: CAMINHO | N10: TRILHA | X10: ORIGEM | AH10: NÍVEL | AN10: XP
D11: Bastião | N11: Muro | X11: Latente | AH11: 2 | AN11: 0
D14: 2 | G14: VALORES
D16: FOR | L16: DES | T16: CON | AB16: INT | AJ16: ESS
D17: 0 | L17: 0 | T17: 0 | AB17: 0 | AJ17: 0
D19: Força | L19: Destreza | T19: Constituição | AB19: Inteligência | AJ19: Essência
D22: VIDA - Atual/Máxima | AF22: TEMPORÁRIO | AM22: ± PERDA &/ou GANHO
D23: =J23 -> 19 | J23: =IF($D$11="","",(VLOOKUP($D$11,DADOS!$N$5:$U$9,3,FALSE)+$T$17)+(VLOOKUP($D$11,DADOS!$N$5:$U$9,4,FALSE)+$T$17)*($AH$11-1)) -> 19 | P23: =IFERROR(__xludf.DUMMYFUNCTION("IFERROR(SPARKLINE($D$23,{""charttype"",""bar"";""max"",$J$23;""color1"",IF(N($J$23)=0,""#E8DCD4"",IF($D$23/$J$23<=0.25,""#C2334D"",IF($D$23/$J$23<=0.5,""#D89B3A"",""#E8DCD4"")))}),"""") "),"") | AF23: 0 | AM23: 0
D26: ENERGIA - Atual/Máxima | AF26: TEMPORÁRIO | AM26: ± PERDA &/ou GANHO
D27: =J27 -> 8 | J27: =IF($D$11="","",VLOOKUP($D$11,DADOS!$N$5:$U$9,5,FALSE)*$AH$11) -> 8 | P27: =IFERROR(__xludf.DUMMYFUNCTION("IFERROR(SPARKLINE($D$27,{""charttype"",""bar"";""max"",$J$27;""color1"",IF(N($J$27)=0,""#E8DCD4"",IF($D$27/$J$27<=0.25,""#C2334D"",IF($D$27/$J$27<=0.5,""#D89B3A"",""#E8DCD4"")))}),"""") "),"") | AF27: 0 | AM27: 0
A30: FICHA DE REGISTRO | D30: INTEGRIDADE - Atual/Máxima | AF30: TEMPORÁRIO | AM30: ± PERDA &/ou GANHO
D31: =J31 -> 25 | J31: =20+(AJ17+5)*($AH$11-1) -> 25 | P31: =IFERROR(__xludf.DUMMYFUNCTION("IFERROR(SPARKLINE($D$31,{""charttype"",""bar"";""max"",$J$31;""color1"",IF(N($J$31)=0,""#E8DCD4"",IF($D$31/$J$31<=0.25,""#C2334D"",IF($D$31/$J$31<=0.5,""#D89B3A"",""#E8DCD4"")))}),"""") "),"") | AF31: 0 | AM31: 0
D34: =IF($D$31=""," ",IF($D$31<=0,"Estágio 4 · Você não é mais você mesmo",IF($D$31<=$J$31/4,"Estágio 3 · Desvantagem em ataques e TRs",IF($D$31<=$J$31/2,"Estágio 2 · Metade do deslocamento, +1 PE por Classe",IF($D$31<=$J$31*3/4,"Estágio 1 · Desvantagem em perícias","Alma Inteira"))))) -> Alma Inteira
Z36: BLOQUEAR
D37: 3 | G37: REGISTRO | Z37: ="2d10 + " & D40-11 -> 2d10 + 0
D39: DEFESA | O39: PROTEÇÃO | Z39: EQUIPAMENTO | AK39: INICIATIVA
D40: =10+$L$17+$O$40 -> 11 | O40: =IF($Z$40="",FLOOR((1+COUNTIF(DADOS!$W$5:$W$11,"<="&$AH$11))/3,1)+1,$Z$40) -> 1 | Z40: 1 | AK40: ="d20 + "&$L$17 -> d20 + 0
D43: CD DE FEITIÇO | O43: CONJURAÇÃO | Z43: CORPO A CORPO | AK43: À DISTÂNCIA
D44: =8+D48+IFS(Z48="FORÇA",$D$17, Z48="DESTREZA",$L$17, Z48="CONSTITUIÇÃO",$T$17, Z48="INTELIGÊNCIA",$AB$17, Z48="ESSÊNCIA",$AJ$17) -> 9 | O44: ="d20 + "&+D48+IFS(Z48="FORÇA",$D$17, Z48="DESTREZA",$L$17, Z48="CONSTITUIÇÃO",$T$17, Z48="INTELIGÊNCIA",$AB$17, Z48="ESSÊNCIA",$AJ$17) -> d20 + 1 | Z44: ="d20 + "&+D48+IFS(AK48="FORÇA",$D$17, AK48="DESTREZA",$L$17, AK48="CONSTITUIÇÃO",$T$17, AK48="INTELIGÊNCIA",$AB$17, AK48="ESSÊNCIA",$AJ$17) -> d20 + 1 | AK44: ="d20 + "&+D48+IFS(AE51="FORÇA",$D$17, AE51="DESTREZA",$L$17, AE51="CONSTITUIÇÃO",$T$17, AE51="INTELIGÊNCIA",$AB$17, AE51="ESSÊNCIA",$AJ$17) -> d20 + 1
D47: MAESTRIA | O47: DESLOCAMENTO | Z47: ATRIBUTO DE CONJURAÇÃO | AK47: ATRIBUTO DE ATAQUE - CORPO A CORPO
D48: =(1+COUNTIF(DADOS!$X$5:$X$7,"<="&$AH$11)) -> 1 | O48: 9 m | Z48: ESSÊNCIA | AK48: FORÇA
AE50: ATRIBUTO DE ATAQUE - À DISTÂNCIA
D51: 4 | G51: PROGRESSÃO | AE51: DESTREZA
D53: ESPAÇOS DE FEITIÇO | O53: REFINO DE GRAÇA | Z53: CLASSE MÁXIMA | AK53: CLASSE 0
D54: =2+INT($AH$11/2)+COUNTIF(DADOS!$W$5:$W$11,"<="&$AH$11) -> 3 | O54: =(1+COUNTIF(DADOS!$W$5:$W$11,"<="&$AH$11)) -> 1 | Z54: =COUNTIF(DADOS!$Y$5:$Y$11,"<="&$AH$11) -> 1 | AK54: =2+COUNTIF(DADOS!$Z$5:$Z$7,"<="&$AH$11) -> 2
D57: 5 | G57: PERÍCIAS
T58: Trein | U58: Espec | AH58: Extra
D59: Trein | E59: Espec | R59: Extra | T59: FALSE | U59: FALSE | V59: Sobrevivência | AD59: Int | AF59: =$AB$17 + IF(U59, $D$48 + INT($D$48 / 2), IF(T59, $D$48, 0)) + AH59 -> 0 | AK59: ANOTAÇÕES RÁPIDAS
D60: FALSE | E60: FALSE | F60: Atletismo | N60: For | P60: =$D$17 + IF(E60, $D$48 + INT($D$48 / 2), IF(D60, $D$48, 0)) + R60 -> 0 | T60: FALSE | U60: FALSE | V60: Natureza | AD60: Int | AF60: =$AB$17 + IF(U60, $D$48 + INT($D$48 / 2), IF(T60, $D$48, 0)) + AH60 -> 0
D61: FALSE | E61: FALSE | F61: Acrobacia | N61: Des | P61: =$L$17 + IF(E61, $D$48 + INT($D$48 / 2), IF(D61, $D$48, 0)) + R61 -> 0 | T61: FALSE | U61: FALSE | V61: Lidar com Animais | AD61: Int | AF61: =$AB$17 + IF(U61, $D$48 + INT($D$48 / 2), IF(T61, $D$48, 0)) + AH61 -> 0
D62: FALSE | E62: FALSE | F62: Furtividade | N62: Des | P62: =$L$17 + IF(E62, $D$48 + INT($D$48 / 2), IF(D62, $D$48, 0)) + R62 -> 0 | T62: FALSE | U62: FALSE | V62: Tecnologia | AD62: Int | AF62: =$AB$17 + IF(U62, $D$48 + INT($D$48 / 2), IF(T62, $D$48, 0)) + AH62 -> 0
D63: FALSE | E63: FALSE | F63: Pontaria | N63: Des | P63: =$L$17 + IF(E63, $D$48 + INT($D$48 / 2), IF(D63, $D$48, 0)) + R63 -> 0 | T63: FALSE | U63: FALSE | V63: Medicina | AD63: Int | AF63: =$AB$17 + IF(U63, $D$48 + INT($D$48 / 2), IF(T63, $D$48, 0)) + AH63 -> 0
D64: FALSE | E64: FALSE | F64: Prestidigitação | N64: Des | P64: =$L$17 + IF(E64, $D$48 + INT($D$48 / 2), IF(D64, $D$48, 0)) + R64 -> 0 | T64: FALSE | U64: FALSE | V64: Sentir Energia | AD64: Ess | AF64: =$AJ$17 + IF(U64, $D$48 + INT($D$48 / 2), IF(T64, $D$48, 0)) + AH64 -> 0
D65: FALSE | E65: FALSE | F65: Investigação | N65: Int | P65: =$AB$17 + IF(E65, $D$48 + INT($D$48 / 2), IF(D65, $D$48, 0)) + R65 -> 0 | T65: FALSE | U65: FALSE | V65: Percepção | AD65: Ess | AF65: =$AJ$17 + IF(U65, $D$48 + INT($D$48 / 2), IF(T65, $D$48, 0)) + AH65 -> 0
D66: FALSE | E66: FALSE | F66: Intuição | N66: Int | P66: =$AB$17 + IF(E66, $D$48 + INT($D$48 / 2), IF(D66, $D$48, 0)) + R66 -> 0 | T66: FALSE | U66: FALSE | V66: Persuasão | AD66: Ess | AF66: =$AJ$17 + IF(U66, $D$48 + INT($D$48 / 2), IF(T66, $D$48, 0)) + AH66 -> 0
D67: FALSE | E67: FALSE | F67: Ocultismo | N67: Int | P67: =$AB$17 + IF(E67, $D$48 + INT($D$48 / 2), IF(D67, $D$48, 0)) + R67 -> 0 | T67: FALSE | U67: FALSE | V67: Enganação | AD67: Ess | AF67: =$AJ$17 + IF(U67, $D$48 + INT($D$48 / 2), IF(T67, $D$48, 0)) + AH67 -> 0
D68: FALSE | E68: FALSE | F68: Religião | N68: Int | P68: =$AB$17 + IF(E68, $D$48 + INT($D$48 / 2), IF(D68, $D$48, 0)) + R68 -> 0 | T68: FALSE | U68: FALSE | V68: Intimidação | AD68: Ess | AF68: =$AJ$17 + IF(U68, $D$48 + INT($D$48 / 2), IF(T68, $D$48, 0)) + AH68 -> 0
...

Sheet DADOS
A1: VERSÃO DO CATÁLOGO | B1: 104 | C1: versão corrente (puxada da central) | D1: 104
A2: cole aqui o IMPORTRANGE da central em D1 quando ela existir; enquanto não existir, D1 fica igual a B1 e o aviso some
A3: Caminhos | B3: Perícias | C3: Ofícios | D3: Famílias | E3: Formas | F3: Melhorias | G3: Restrições | H3: Condições | I3: Origens | J3: Testes | K3: Atributos | L3: Trilhas | N3: tabela dos Caminhos
A4: Bastião | B4: Atletismo | C4: Condução | D4: Alcance | E4: Projétil | F4: Longe | G4: Corpo a Corpo | H4: Lento | I4: Latente | J4: Físico | K4: lista | L4: Muro | N4: Caminho | O4: dado | P4: vida inicial | Q4: vida por nível | R4: PE por nível | S4: perícia fixa 1 | T4: perícia fixa 2 | U4: ofício fixo | W4: marcos | X4: maestria | Y4: classe | Z4: classe 0 | AB4: perícia | AC4: atributo | BA4: campo | BB4: célula
A5: Vanguarda | B5: Acrobacia | C5: Arrombamento | D5: Área | E5: Toque | F5: Muito Longe | G5: Lento | H5: Incapacitado | I5: Receptáculo | J5: Vigor | K5: escala | L5: Punho | N5: Bastião | O5: d12 | P5: 12 | Q5: 7 | R5: 4 | S5: Atletismo | T5: Intimidação | U5: Forja | W5: 6 | X5: 10 | Y5: 1 | Z5: 5 | AB5: Atletismo | AC5: Força | BA5: nome | BB5: D3
A6: Guia | B6: Furtividade | C6: Herbalismo | D6: Mira | E6: Explosão | F6: Sem Ver | G6: Parado | H6: Derrubado | I6: Descendente | J6: Intelecto | K6: criacao | L6: Brasa | N6: Vanguarda | O6: d8 | P6: 8 | Q6: 5 | R6: 5 | S6: Acrobacia | T6: Percepção | U6: Arrombamento | W6: 10 | X6: 18 | Y6: 5 | Z6: 11 | AB6: Acrobacia | AC6: Destreza | BA6: caminho | BB6: D11
A7: Emanador | B7: Pontaria | C7: Forja | D7: Controle | E7: Aura | F7: Passo | G7: Gesto | H7: Agarrado | I7: Reencarnado | J7: Espírito | K7: nota | L7: Estocada | N7: Guia | O7: d8 | P7: 8 | Q7: 5 | R7: 5 | S7: Persuasão | T7: Medicina | U7: Herbalismo | W7: 14 | X7: 26 | Y7: 9 | Z7: 17 | AB7: Furtividade | AC7: Destreza | BA7: trilha | BB7: N11
A8: Evocador | B8: Prestidigitação | C8: Caligrafia | D8: Auxiliares | E8: Cone | F8: Empurrão | G8: Sangra | H8: Desarmado | I8: Feto | K8: pagina | L8: Batedor | N8: Evocador | O8: d6 | P8: 6 | Q8: 4 | R8: 6 | S8: Religião | T8: Lidar com Animais | U8: Entalhador | W8: 18 | Y8: 13 | AB8: Pontaria | AC8: Destreza | BA8: origem | BB8: X11
B9: Investigação | C9: Burocracia | D9: Castigo | E9: Linha | F9: Troca | G9: Recuo | H9: Surdo | I9: Corpo Amaldiçoado | L9: Executor | N9: Emanador | O9: d6 | P9: 6 | Q9: 4 | R9: 6 | S9: Ocultismo | T9: Investigação | U9: Caligrafia | W9: 22 | Y9: 17 | AB9: Prestidigitação | AC9: Destreza | BA9: nivel | BB9: AH11
B10: Intuição | C10: Entalhador | D10: Tempo | E10: Cura | F10: Perseguir | G10: Carregar | H10: Calado | I10: Restrição Celestial | L10: Elo | W10: 26 | Y10: 21 | AB10: Investigação | AC10: Inteligência | BA10: xp | BB10: AN11
B11: Ocultismo | C11: Alfaiate | D11: Marca | E11: Apoio | F11: Maior | G11: Tudo ou Nada | H11: Enfeitiçado | L11: Sutura | W11: 30 | Y11: 26 | AB11: Intuição | AC11: Inteligência | BA11: atr_Força | BB11: D17
B12: Religião | C12: Culinária | D12: Amparo | E12: Onda | F12: Muito Maior | G12: Uma Vez | H12: Petrificado | L12: Perímetro | AB12: Ocultismo | AC12: Inteligência | BA12: atr_Destreza | BB12: L17
B13: História | C13: Instrumento | E13: Efeito | F13: Escolher | G13: Condicional | H13: Impedido | L13: Torrente | AB13: Religião | AC13: Inteligência | BA13: atr_Constituição | BB13: T17
B14: Hierarquia | C14: Jogatina | F14: Fica | G14: Fraqueza | H14: Cego | L14: Explosivo | AB14: História | AC14: Inteligência | BA14: atr_Inteligência | BB14: AB17
B15: Medicina | F15: Mais Um | G15: Frágil | H15: Amedrontado | L15: Arremate | AB15: Hierarquia | AC15: Inteligência | BA15: atr_Essência | BB15: AJ17
B16: Sobrevivência | F16: Rajada | G16: Barulho | H16: Envenenado | L16: Servo | AB16: Medicina | AC16: Inteligência | BA16: vida | BB16: D23
B17: Natureza | F17: Salto | G17: Assinatura | H17: Atordoado | L17: Matilha | AB17: Sobrevivência | AC17: Inteligência | BA17: vida_max | BB17: J23
B18: Lidar com Animais | F18: Contorno | G18: Aquecer | L18: Coro | AB18: Natureza | AC18: Inteligência | BA18: vida_temp | BB18: AF23
B19: Tecnologia | F19: Precisão | G19: Dívida | AB19: Lidar com Animais | AC19: Inteligência | BA19: vida_delta | BB19: AM23
B20: Sentir Energia | F20: Certeiro | G20: Peso Morto | AB20: Tecnologia | AC20: Inteligência | BA20: energia | BB20: D27
B21: Percepção | F21: Inescapável | G21: Sem Volta | AB21: Sentir Energia | AC21: Essência | BA21: energia_max | BB21: J27
B22: Persuasão | F22: Fura | G22: Restrição Própria | AB22: Percepção | AC22: Essência | BA22: energia_temp | BB22: AF27
B23: Enganação | F23: Corrói | AB23: Persuasão | AC23: Essência | BA23: energia_delta | BB23: AM27
B24: Intimidação | F24: Sem Cobertura | AB24: Enganação | AC24: Essência | BA24: integridade | BB24: D31
B25: Atuação | F25: De Novo | AB25: Intimidação | AC25: Essência | BA25: integridade_max | BB25: J31
B26: Provocar | F26: Toca a Alma | AB26: Atuação | AC26: Essência | BA26: integridade_temp | BB26: AF31
F27: Terreno | AB27: Provocar | AC27: Essência | BA27: integridade_delta | BB27: AM31
F28: Anteparo | BA28: estagio_alma | BB28: D34
F29: Prende | BA29: defesa | BB29: D40
F30: Cerca | BA30: proteção | BB30: O40
F31: Puxa | BA31: equipamento | BB31: Z40
F32: Desarma o Feitiço | BA32: iniciativa | BB32: AK40
F33: Nível | BA33: cd de feitiço | BB33: D44
F34: Impulso | BA34: conjuração | BB34: O44
F35: Trava | BA35: corpo a corpo | BB35: Z44
F36: Abre Ferida | BA36: à distância | BB36: AK44
F37: Sobrecarga | BA37: maestria | BB37: D48
F38: Firmeza | BA38: deslocamento | BB38: O48
F39: Guarda | BA39: espaços de feitiço | BB39: D54
... F42: Ecoa | BA42: classe 0 grátis | BB42: AK54
...

Sheet INVOCAÇÃO
D1: A FICHA DA INVOCAÇÃO | AF1: capítulo 16 · Projeto - M
D4: 1 | G4: O DONO
D6: NÍVEL DO DONO | O6: ESSÊNCIA DO DONO | Z6: INTELIGÊNCIA DO DONO | AK6: MAESTRIA
D7: =FICHA!AH11 -> 2 | O7: =FICHA!AJ17 -> 0 | Z7: =FICHA!AB17 -> 0 | AK7: =(1+COUNTIF(DADOS_INV!$AH$3:$AH$5,"<="&$D$7)) -> 1
A8: INVOCAÇÃO
D10: MARCOS | O10: MAIOR CLASSE
D11: =COUNTIF(DADOS_INV!$AG$3:$AG$9,"<="&$D$7) -> 0 | O11: =COUNTIF(DADOS_INV!$AI$3:$AI$9,"<="&$D$7) -> 1
D16: 2 | G16: A INVOCAÇÃO
D18: NOME | Z18: TIPO | AK18: TRILHA
Z19: técnica | AK19: Servo
D21: SINTONIA
D22: Presa
D27: 3 | G27: OS ATRIBUTOS DELA
D29: FOR | L29: DES | T29: CON | AB29: INT | AJ29: ESS
A30: PROJETO - M | D30: 0 | L30: 0 | T30: 0 | AB30: 0 | AJ30: 0
D32: Força | L32: Destreza | T32: Constituição | AB32: Inteligência | AJ32: Essência
D34: PONTOS GASTOS | O34: DISPONÍVEIS | Z34: CONFERÊNCIA
D35: =$D$30+$L$30+$T$30+$AB$30+$AJ$30 -> 0 | O35: =(9+$D$11) -> 9 | Z35: =IF($D$30+$L$30+$T$30+$AB$30+$AJ$30>(9+$D$11),"estourou o total",IF(MAX($D$30,$L$30,$T$30,$AB$30,$AJ$30)>6,"estourou o teto de 6",IF($D$30+$L$30+$T$30+$AB$30+$AJ$30<(9+$D$11),"sobrou ponto","ok"))) -> sobrou ponto
D37: Distribua 9 pontos, nenhum acima de 3. A cada marco ela ganha 1 ponto, até o teto de 6. É a mesma regra da sua ficha.
D40: 4 | G40: ACERTO, DEFESA E TESTES DE RESISTÊNCIA
D42: ATRIBUTO DO ACERTO | O42: ACERTO | Z42: DEFESA USA, DO DONO | AK42: DEFESA
D43: Força | O43: {=IF($D$43="","",INDEX(DADOS_INV!$AK$3:$AK$7,MATCH($D$43,DADOS_INV!$C$2:$C$6,0))+$AK$7)} -> 1 | Z43: Inteligência | AK43: =10+$L$30+FLOOR(IF($Z$43="Essência",$O$7,$Z$7)/2,1) -> 10
D45: CRÍTICO COM | O45: QUAL TR ELA TREINA | Z45: O FÍSICO DELA USA
D46: =IF($D$22="Presa","19 ou 20","20") -> 19 ou 20 | O46: Físico | Z46: Força
D48: TESTES DE RESISTÊNCIA · ela treina um, e você escolhe qual no campo acima
D49: TESTE | K49: Extra | L49: USA | Q49: d20 + | Z49: TESTE | AG49: Extra | AH49: USA | AM49: d20 +
D50: Físico | L50: For ou Des | Q50: {=IFERROR(INDEX(DADOS_INV!$AK$3:$AK$7,MATCH($Z$46,DADOS_INV!$C$2:$C$6,0))+IF($O$46="Físico",$AK$7,0)+N($K$50),"")} -> 1 | Z50: Vigor | AH50: Con | AM50: {=IFERROR(INDEX(DADOS_INV!$AK$3:$AK$7,MATCH("Constituição",DADOS_INV!$C$2:$C$6,0))+IF($O$46="Vigor",$AK$7,0)+N($AG$50),"")} -> 0
D51: Intelecto | L51: Int | Q51: {=IFERROR(INDEX(DADOS_INV!$AK$3:$AK$7,MATCH("Inteligência",DADOS_INV!$C$2:$C$6,0))+IF($O$46="Intelecto",$AK$7,0)+N($K$51),"")} -> 0 | Z51: Espírito | AH51: Ess | AM51: {=IFERROR(INDEX(DADOS_INV!$AK$3:$AK$7,MATCH("Essência",DADOS_INV!$C$2:$C$6,0))+IF($O$46="Espírito",$AK$7,0)+N($AG$51),"")} -> 0
D56: 5 | G56: VIDA E MORTE
D58: VIDA MÁXIMA | O58: VIDA AGORA | Z58: CORPOS EM CAMPO | AK58: ÁREA BATE ×
D59: =IF($Z$19="","",IF(IFERROR(VLOOKUP($AK$19,DADOS_INV!$N$3:$R$5,4,FALSE),"cru")="forte",FLOOR(2.5*(IFERROR(VLOOKUP($Z$19,DADOS_INV!$K$3:$L$6,2,FALSE),0)+2*$D$7)+$T$30*$D$7,1),(IFERROR(VLOOKUP($Z$19,DADOS_INV!$K$3:$L$6,2,FALSE),0)+(2+$T$30)*$D$7))+IF($D$22="Parrudo",5*$AK$7,0)) -> 15 | O59: =D59 -> 15 | Z59: =IFERROR(VLOOKUP($AK$19,DADOS_INV!$N$3:$R$5,2,FALSE),"") -> 1 | AK59: =IFERROR(VLOOKUP($AK$19,DADOS_INV!$N$3:$R$5,5,FALSE),"") -> 1
D62: A BARRA | O62: =IFERROR(__xludf.DUMMYFUNCTION("IFERROR(SPARKLINE({MAX(0,MIN(N($O$59),N($D$59))),MAX(0,N($D$59)-MAX(0,N($O$59)))},{""charttype"",""bar"";""color1"",IF(IFERROR(N($O$59)/N($D$59),0)<=0.25,""#C2334D"",IF(IFERROR(N($O$59)/N($D$59),0)<=0.5,""#D89B3A"",""#E8DCD4""));""color2"",""#998ba2""}),"&""""")"),"")
D64: RÉGUA DA MORTE | O64: METADE DELA | Z64: VOLTA COM
D65: =IF($Z$19="","",5*(IFERROR(VLOOKUP($Z$19,DADOS_INV!$K$3:$L$6,2,FALSE),0)+(2+$T$30)*$D$7)) -> 30 | O65: =IF($Z$19="","",5*(IFERROR(VLOOKUP($Z$19,DADOS_INV!$K$3:$L$6,2,FALSE),0)+(2+$T$30)*$D$7)/2) -> 15 | Z65: =IF($Z$19="","",FLOOR($D$59/2,1)) -> 7
D67: MORRE DE VEZ
D68: quando o dano que passar de zero for maior que a metade da régua, ou quando um golpe só causar a régua inteira. Fora desses dois casos ela só cai, e você reinvoca.
D70: No zero ela sai do campo. Ela não fica Inconsciente e não ganha Sequela nem Cicatriz. Reinvocar custa os PE de novo, e ela volta com metade da vida; a vida cheia volta no descanso longo.
D73: 6 | G73: O ORÇAMENTO
D75: ORÇAMENTO
D76: =FLOOR((8+4*$D$11)*IFERROR(VLOOKUP($AK$19,DADOS_INV!$N$3:$R$5,3,FALSE),1),1) -> 12
...

Sheet CATÁLOGO
D1: O CATÁLOGO — o que dá para comprar | AF1: capítulo 16
D4: TRAÇO | U4: o corpo dela. Vale sempre, sem gastar ação.
D5: PONTOS | H5: NOME | P5: O QUE FAZ
D6: 2 | H6: Escalada | P6: sobe parede e teto sem teste
D7: 2 | H7: Nado | P7: move na água sem penalidade. Rio, cisterna, tanque alagado de estação
D8: 3 | H8: Fala | P8: ela fala, e dá para conversar com ela
D9: 5 | H9: Faro | P9: rastreia por cheiro e por energia. Pega rastro velho de horas
D10: 5 | H10: Vigia | P10: o que ela vê e ouve, você vê e ouve também
D11: 7 | H11: Miúdo | P11: ocupa espaço menor e passa por vão. Duto, grade de bueiro, folga embaixo da porta
D12: 8 | H12: Voo | P12: o deslocamento dela passa a ser de voo também
D13: 8 | H13: Montaria | P13: carrega uma pessoa ou mais, dependendo do tamanho
D14: 8 | H14: Fisgada | P14: prende à distância. Ela alcança, engancha, e quem ia fugir para de conseguir
D15: 8 | H15: Emboscada | P15: surge do chão, fora do alcance de visão
D16: 8 | H16: Jorro | P16: ataca em linha ou em área
D17: 8 | H17: Graúdo | P17: ocupa espaço maior e barra passagem
D18: 8 | H18: Remoto | P18: funciona além dos 18 metros da amarra. Dentro da cena, para qualquer um; fora da cena, com requisito
D21: COMANDO | U21: o que ela faz quando você gasta a Ação Padrão comandando.
D22: PONTOS | H22: NOME | P22: O QUE FAZ
D23: 0 | H23: Investir | P23: o ataque. Toda invocação tem
D24: 4 | H24: Agarrar | P24: prende o alvo
D25: 4 | H25: Arrastar | P25: move o alvo, ou se move levando ele. Tira alguém de cima de uma beirada, ou põe
D26: 4 | H26: Buscar | P26: pega um objeto, ou rastreia de forma ativa
D27: 4 | H27: Cavar | P27: abre buraco, desenterra, revira o terreno. Faz rota onde não havia rota
D28: 8 | H28: Interpor | P28: se põe entre você e o golpe. O corpo dela recebe o que ia em você
D29: 8 | H29: Chamariz | P29: o alvo tem de vir para cima dela. Você escolhe em quem a coisa está prestando atenção
D32: INVENTAR O SEU | U32: escreva o efeito, ache na régua o preço, e leve para o mestre aprovar
D33: régua de TRAÇO
D34: 2 | H34: muda como ela anda, e só ela
D35: 3 | H35: muda o que ela comunica
D36: 5 | H36: muda o que ela percebe
D37: 7 | H37: muda que espaço ela ocupa, a um passo de mexer no tabuleiro
D38: 8 | H38: encosta em outra criatura ou no ambiente: carrega, prende, empurra, barra, alcança além do alcance, aparece onde não dava
D40: régua de COMANDO
D41: 0 | H41: é o ataque
D42: 4 | H42: faz uma coisa com um alvo ou um objeto
D43: 8 | H43: protege você, ou nega a ação de outro
D45: O QUE O ORÇAMENTO NÃO COMPRA
D46: dado de dano | R46: o teto de uma Rotina já governa a saída. Um Traço que dê +1d6 não existe
D47: qualquer coisa que cresça com refino | R47: refino cresce muito mais rápido que a ficha dela, e ela passaria de você
D48: atributo | R48: os cinco já saem do arranjo dela, e comprar de novo é pagar duas vezes
...

Sheet DADOS_INV
A1: tipos | B1: trilhas | C1: atributos | D1: trs | E1: sintonia | F1: defesa_de | G1: fisico_de | H1: traco | I1: comando | K1: tab_tipos | N1: tab_trilhas | T1: tab_traco | W1: tab_comando | Z1: tab_investir | AD1: tab_trs | AP1: degrau_traco | AS1: degrau_comando | AU1: degrau_traco | AX1: degrau_comando
A2: talismã | B2: Servo | C2: Força | D2: Físico | E2: — | F2: Essência | G2: Força | H2: — | I2: — | K2: tipo | L2: base | N2: trilha | O2: corpos | P2: mult | Q2: corpo | R2: area | T2: traço | U2: pontos | W2: comando | X2: pontos | Z2: de | AA2: uma | AB2: matilha | AD2: tr | AE2: atributo | AG2: e_marcos | AH2: e_maestria | AI2: e_classe | AK2: espelho | AM2: campo | AN2: célula | AP2: — | AS2: — | AU2: — | AX2: —
A3: corpo amaldiçoado | B3: Matilha | C3: Destreza | D3: Vigor | E3: Presa | F3: Inteligência | G3: Destreza | H3: Escalada | I3: Investir | K3: talismã | L3: 1 | N3: Servo | O3: 1 | P3: 1.5 | Q3: forte | R3: 1 | T3: — | U3: 0 | W3: — | X3: 0 | Z3: 2 | AA3: 1d6 | AB3: 2 | AD3: Físico | AE3: Força | AG3: 6 | AH3: 10 | AI3: 1 | AK3: ='INVOCAÇÃO'!$D$30 -> 0 | AM3: nivel | AN3: D7 | AP3: 2 | AS3: 0 | AU3: 2 | AX3: 0
A4: técnica | B4: Coro | C4: Constituição | D4: Intelecto | E4: Parrudo | H4: Nado | I4: Agarrar | K4: corpo amaldiçoado | L4: 1 | N4: Matilha | O4: 5 | P4: 1 | Q4: forte | R4: 1.5 | T4: Escalada | U4: 2 | W4: Investir | X4: 0 | Z4: 5 | AA4: 4d6 | AB4: 1d6 | AD4: Vigor | AE4: Constituição | AG4: 10 | AH4: 18 | AI4: 5 | AK4: ='INVOCAÇÃO'!$L$30 -> 0 | AM4: ess_dono | AN4: O7 | AP4: 3 | AS4: 4 | AU4: 3 | AX4: 4
A5: maldição domada | C5: Inteligência | D5: Espírito | E5: Voz | H5: Fala | I5: Arrastar | K5: técnica | L5: 2 | N5: Coro | O5: 1 | P5: 1 | Q5: cru | R5: 1 | T5: Nado | U5: 2 | W5: Agarrar | X5: 4 | Z5: 9 | AA5: 6d6 | AB5: 2d6 | AD5: Intelecto | AE5: Inteligência | AG5: 14 | AH5: 26 | AI5: 9 | AK5: ='INVOCAÇÃO'!$T$30 -> 0 | AM5: int_dono | AN5: Z7 | AP5: 5 | AS5: 8 | AU5: 5 | AX5: 8
C6: Essência | H6: Faro | I6: Buscar | K6: maldição domada | L6: 3 | T6: Fala | U6: 3 | W6: Arrastar | X6: 4 | Z6: 13 | AA6: 8d6 | AB6: 3d6 | AD6: Espírito | AE6: Essência | AG6: 18 | AI6: 13 | AK6: ='INVOCAÇÃO'!$AB$30 -> 0 | AM6: maestria | AN6: AK7 | AP6: 7 | AU6: 7
H7: Vigia | I7: Cavar | T7: Faro | U7: 5 | W7: Buscar | X7: 4 | Z7: 17 | AA7: 10d6 | AB7: 4d6 | AG7: 22 | AI7: 17 | AK7: ='INVOCAÇÃO'!$AJ$30 -> 0 | AM7: marcos | AN7: D11 | AP7: 8 | AU7: 8
H8: Miúdo | I8: Interpor | T8: Vigia | U8: 5 | W8: Cavar | X8: 4 | Z8: 21 | AA8: 13d6 | AB8: 5d6 | AG8: 26 | AI8: 21 | AM8: classe | AN8: O11
H9: Voo | I9: Chamariz | T9: Miúdo | U9: 7 | W9: Interpor | X9: 8 | Z9: 26 | AA9: 15d6 | AB9: 6d6 | AG9: 30 | AI9: 26 | AM9: nome | AN9: D19
H10: Montaria | T10: Voo | U10: 8 | W10: Chamariz | X10: 8 | AM10: tipo | AN10: Z19
H11: Fisgada | T11: Montaria | U11: 8 | AM11: trilha | AN11: AK19
H12: Emboscada | T12: Fisgada | U12: 8 | AM12: sintonia | AN12: D22
H13: Jorro | T13: Emboscada | U13: 8 | AM13: pontos_atributo | AN13: D35
H14: Graúdo | T14: Jorro | U14: 8 | AM14: pontos_disp | AN14: O35
H15: Remoto | T15: Graúdo | U15: 8 | AM15: aviso_atributo | AN15: Z35
T16: Remoto | U16: 8 | AM16: atr_acerto | AN16: D43
AM17: acerto | AN17: O43
AM18: defesa_de | AN18: Z43
AM19: defesa | AN19: AK43
AM20: critico | AN20: D46
AM21: tr_treinado | AN21: O46
AM22: fisico_de | AN22: Z46
AM23: tr_Físico | AN23: Q50
AM24: tr_extra_Físico | AN24: K50
AM25: tr_Vigor | AN25: AM50
AM26: tr_extra_Vigor | AN26: AG50
AM27: tr_Intelecto | AN27: Q51
AM28: tr_extra_Intelecto | AN28: K51
... AM77: comando_6 | AN77: Z85
