Workbook

Sheet INVOCAÇÃO
D1: A FICHA DA INVOCAÇÃO | AF1: Capítulo 16 · Projeto - M
D4: 1 | G4: O DONO
D6: NÍVEL DO DONO | O6: ESSÊNCIA DO DONO | Z6: INTELIGÊNCIA DO DONO | AK6: MAESTRIA
D7: 2 | O7: 0 | Z7: 0 | AK7: =(1+COUNTIF(DADOS!$AH$3:$AH$5,"<="&$D$7))
A8: INVOCAÇÃO
D10: MARCOS | O10: MAIOR CLASSE
D11: =COUNTIF(DADOS!$AG$3:$AG$9,"<="&$D$7) | O11: =COUNTIF(DADOS!$AI$3:$AI$9,"<="&$D$7)
D13: Copie estes três da sua ficha. O resto desta seção a planilha calcula.
D16: 2 | G16: A INVOCAÇÃO
D18: NOME | Z18: TIPO | AK18: TRILHA
D21: SINTONIA | O21: O QUE A TRILHA DECIDE
D22: — | O22: Quantos corpos você põe em campo, quanta vida cada um tem, e o tamanho do orçamento
D24: A Sintonia é a escolha de nível 2 do Evocador. Presa: crítico com 19 ou 20. Parrudo: mais vida, 5 × a sua maestria. Voz: sobe a CD dos efeitos dela, e a seção 9 faz a conta.
D27: 3 | G27: OS ATRIBUTOS DELA
D29: FOR | L29: DES | T29: CON | AB29: INT | AJ29: ESS
A30: PROJETO - M | D30: 0 | L30: 0 | T30: 0 | AB30: 0 | AJ30: 0
D32: Força | L32: Destreza | T32: Constituição | AB32: Inteligência | AJ32: Essência
D34: PONTOS GASTOS | O34: DISPONÍVEIS | Z34: CONFERÊNCIA
D35: =$D$30+$L$30+$T$30+$AB$30+$AJ$30 | O35: =(9+$D$11) | Z35: =IF($D$30+$L$30+$T$30+$AB$30+$AJ$30>(9+$D$11),"Estourou o total",IF(MAX($D$30,$L$30,$T$30,$AB$30,$AJ$30)>6,"Estourou o teto de 6",IF($D$30+$L$30+$T$30+$AB$30+$AJ$30<(9+$D$11),"Sobrou ponto","Ok")))
D37: Distribua 9 pontos, nenhum acima de 3. A cada marco ela ganha 1 ponto, até o teto de 6. É a mesma regra da sua ficha.
D40: 4 | G40: ACERTO, DEFESA E TESTES DE RESISTÊNCIA
D42: ATRIBUTO DO ACERTO | O42: ACERTO | Z42: DEFESA USA, DO DONO | AK42: DEFESA
O43: =IF($D$43="","",INDEX(DADOS!$AK$3:$AK$7,MATCH($D$43,DADOS!$C$2:$C$6,0))+$AK$7) | AK43: =10+$L$30+FLOOR(IF($Z$43="Essência",$O$7,$Z$7)/2,1)
D45: CRÍTICO COM | O45: QUAL TR ELA TREINA | Z45: O FÍSICO DELA USA
D46: =IF($D$22="Presa","19 ou 20","20")
D48: TESTES DE RESISTÊNCIA · ela treina um, e você escolhe qual no campo acima
D49: TESTE | K49: Extra | L49: USA | R49: d20 + | Z49: TESTE | AG49: Extra | AH49: USA | AN49: d20 +
D50: Físico | L50: For ou Des | Q50: =IFERROR(INDEX(DADOS!$AK$3:$AK$7,MATCH($Z$46,DADOS!$C$2:$C$6,0))+IF($O$46="Físico",$AK$7,0)+N($K$50),"") | Z50: Vigor | AH50: Con | AM50: =IFERROR(INDEX(DADOS!$AK$3:$AK$7,MATCH("Constituição",DADOS!$C$2:$C$6,0))+IF($O$46="Vigor",$AK$7,0)+N($AG$50),"")
D51: Intelecto | L51: Int | Q51: =IFERROR(INDEX(DADOS!$AK$3:$AK$7,MATCH("Inteligência",DADOS!$C$2:$C$6,0))+IF($O$46="Intelecto",$AK$7,0)+N($K$51),"") | Z51: Espírito | AH51: Ess | AM51: =IFERROR(INDEX(DADOS!$AK$3:$AK$7,MATCH("Essência",DADOS!$C$2:$C$6,0))+IF($O$46="Espírito",$AK$7,0)+N($AG$51),"")
D53: Role d20 e some o número da coluna. O Extra é para bônus que a planilha não conhece; deixe vazio se não houver. A Defesa não se rola: o inimigo rola contra ela.
D56: 5 | G56: VIDA E MORTE
D58: VIDA MÁXIMA | O58: VIDA AGORA | Z58: CORPOS EM CAMPO | AK58: ÁREA BATE ×
D59: =IF($Z$19="","",FLOOR(IFERROR(VLOOKUP($AK$19,DADOS!$N$3:$R$5,4,FALSE),1)*(IFERROR(VLOOKUP($Z$19,DADOS!$K$3:$L$6,2,FALSE),0)+2*$D$7)+$T$30*$D$7,1)+IF($D$22="Parrudo",5*$AK$7,0)) | Z59: =IFERROR(VLOOKUP($AK$19,DADOS!$N$3:$R$5,2,FALSE),"") | AK59: =IFERROR(VLOOKUP($AK$19,DADOS!$N$3:$R$5,5,FALSE),"")
D62: A BARRA | O62: =IFERROR(SPARKLINE($O$59,{"charttype","bar";"max",$D$59;"color1",IF(N($D$59)=0,"#E8DCD4",IF($O$59/$D$59<=0.25,"#C2334D",IF($O$59/$D$59<=0.5,"#D89B3A","#E8DCD4")))}),"")
D64: RÉGUA DA MORTE | O64: METADE DELA | Z64: VOLTA COM
D65: =IF($Z$19="","",$D$59) | O65: =IF($Z$19="","",$D$59/2) | Z65: =IF($Z$19="","",FLOOR($D$59/2,1))
D67: MORRE DE VEZ
D68: Quando um golpe só causar a régua inteira, ou quando o dano que passar de zero for maior que a metade da régua. A régua é a vida máxima dela. Área nunca destrói: ela derruba como qualquer dano. Fora desses dois casos ela só cai, e você reinvoca.
D70: No zero ela sai do campo. Ela não fica Inconsciente e não ganha Sequela nem Cicatriz. Reinvocar custa os PE de novo, e ela volta com metade da vida; a vida cheia volta no descanso longo.
D73: 6 | G73: O ORÇAMENTO
...

Sheet CATÁLOGO
D1: O CATÁLOGO — o que dá para comprar | AF1: Capítulo 16
D4: TRAÇO | U4: O corpo dela. Vale sempre, sem gastar ação.
D5: PONTOS | H5: NOME | P5: O QUE FAZ
D6: 2 | H6: Escalada | P6: Sobe parede e teto sem teste
D7: 2 | H7: Nado | P7: Move na água sem penalidade. Rio, cisterna, tanque alagado de estação
D8: 3 | H8: Fala | P8: Ela fala, e dá para conversar com ela
D9: 5 | H9: Faro | P9: Rastreia por cheiro e por energia. Pega rastro velho de horas
D10: 5 | H10: Vigia | P10: O que ela vê e ouve, você vê e ouve também
D11: 7 | H11: Miúdo | P11: Ocupa espaço menor e passa por vão. Duto, grade de bueiro, folga embaixo da porta
D12: 8 | H12: Voo | P12: O deslocamento dela passa a ser de voo também
D13: 8 | H13: Montaria | P13: Carrega uma pessoa ou mais, dependendo do tamanho
D14: 8 | H14: Fisgada | P14: Prende à distância. Ela alcança, engancha, e quem ia fugir para de conseguir
D15: 8 | H15: Emboscada | P15: Surge do chão, fora do alcance de visão
D16: 8 | H16: Jorro | P16: Ataca e empurra em linha ou em área
D17: 8 | H17: Graúdo | P17: Ocupa espaço maior e barra passagem
D18: 8 | H18: Remoto | P18: Funciona além dos 18 metros da amarra. Dentro da cena, para qualquer um; fora da cena, com requisito
D21: COMANDO | U21: O que ela faz quando você gasta a Ação Padrão comandando.
D22: PONTOS | H22: NOME | P22: O QUE FAZ
D23: 0 | H23: Investir | P23: O ataque. Toda invocação tem
D24: 4 | H24: Agarrar | P24: Prende o alvo
D25: 4 | H25: Arrastar | P25: Move o alvo, ou se move levando ele. Tira alguém de cima de uma beirada, ou põe
D26: 4 | H26: Buscar | P26: Pega um objeto, ou rastreia de forma ativa
D27: 4 | H27: Cavar | P27: Abre buraco, desenterra, revira o terreno. Faz rota onde não havia rota
D28: 8 | H28: Interpor | P28: Se põe entre você e o golpe. O corpo dela recebe o que ia em você
D29: 8 | H29: Chamariz | P29: O alvo tem de vir para cima dela. Você escolhe em quem a coisa está prestando atenção
D32: INVENTAR O SEU | U32: Escreva o efeito, ache na régua o preço, e leve para o mestre aprovar
D33: Régua de TRAÇO
D34: 2 | H34: Muda como ela anda, e só ela
D35: 3 | H35: Muda o que ela comunica
D36: 5 | H36: Muda o que ela percebe
D37: 7 | H37: Muda que espaço ela ocupa, a um passo de mexer no tabuleiro
D38: 8 | H38: Encosta em outra criatura ou no ambiente: carrega, prende, empurra, barra, alcança além do alcance, aparece onde não dava
D40: Régua de COMANDO
D41: 0 | H41: É o ataque
D42: 4 | H42: Faz uma coisa com um alvo ou um objeto
D43: 8 | H43: Protege você, ou nega a ação de outro
D45: O QUE O ORÇAMENTO NÃO COMPRA
D46: Dado de dano | R46: O teto de uma Rotina já governa a saída. Um Traço que dê +1d6 não existe
D47: Qualquer coisa que cresça com refino | R47: Refino cresce muito mais rápido que a ficha dela, e ela passaria de você
D48: Atributo | R48: Os cinco já saem do arranjo dela, e comprar de novo é pagar duas vezes
...

Sheet DADOS
A1: tipos | B1: trilhas | C1: atributos | D1: trs | E1: sintonia | F1: defesa_de | G1: fisico_de | H1: traco | I1: comando | K1: tab_tipos | N1: tab_trilhas | T1: tab_traco | W1: tab_comando | Z1: tab_investir | AD1: tab_trs | AP1: degrau_traco | AQ1: degrau_comando
A2: talismã | B2: Servo | C2: Força | D2: Físico | E2: — | F2: Essência | G2: Força | H2: — | I2: — | K2: tipo | L2: base | N2: trilha | O2: corpos | P2: mult | Q2: corpo | R2: area | T2: traço | U2: pontos | W2: comando | X2: pontos | Z2: de | AA2: uma | AB2: matilha | AD2: tr | AE2: atributo | AG2: e_marcos | AH2: e_maestria | AI2: e_classe | AK2: espelho | AM2: campo | AN2: célula | AP2: — | AQ2: —
A3: corpo amaldiçoado | B3: Matilha | C3: Destreza | D3: Vigor | E3: Presa | F3: Inteligência | G3: Destreza | H3: Escalada | I3: Investir | K3: talismã | L3: 1 | N3: Servo | O3: 1 | P3: 1.5 | Q3: 2.5 | R3: 1 | T3: — | U3: 0 | W3: — | X3: 0 | Z3: 2 | AA3: 1d6 | AB3: 2 | AD3: Físico | AE3: Força | AG3: 6 | AH3: 10 | AI3: 1 | AK3: =INVOCAÇÃO!$D$30 | AM3: nivel | AN3: D7 | AP3: 2 | AQ3: 0
A4: técnica | B4: Coro | C4: Constituição | D4: Intelecto | E4: Parrudo | H4: Nado | I4: Agarrar | K4: corpo amaldiçoado | L4: 1 | N4: Matilha | O4: 5 | P4: 1 | Q4: 2.5 | R4: 1.5 | T4: Escalada | U4: 2 | W4: Investir | X4: 0 | Z4: 5 | AA4: 4d6 | AB4: 1d6 | AD4: Vigor | AE4: Constituição | AG4: 10 | AH4: 18 | AI4: 5 | AK4: =INVOCAÇÃO!$L$30 | AM4: ess_dono | AN4: O7 | AP4: 3 | AQ4: 4
A5: maldição domada | C5: Inteligência | D5: Espírito | E5: Voz | H5: Fala | I5: Arrastar | K5: técnica | L5: 2 | N5: Coro | O5: 1 | P5: 1 | Q5: 2 | R5: 1 | T5: Nado | U5: 2 | W5: Agarrar | X5: 4 | Z5: 9 | AA5: 6d6 | AB5: 2d6 | AD5: Intelecto | AE5: Inteligência | AG5: 14 | AH5: 26 | AI5: 9 | AK5: =INVOCAÇÃO!$T$30 | AM5: int_dono | AN5: Z7 | AP5: 5 | AQ5: 8
C6: Essência | H6: Faro | I6: Buscar | K6: maldição domada | L6: 3 | T6: Fala | U6: 3 | W6: Arrastar | X6: 4 | Z6: 13 | AA6: 8d6 | AB6: 3d6 | AD6: Espírito | AE6: Essência | AG6: 18 | AI6: 13 | AK6: =INVOCAÇÃO!$AB$30 | AM6: maestria | AN6: AK7 | AP6: 7
H7: Vigia | I7: Cavar | T7: Faro | U7: 5 | W7: Buscar | X7: 4 | Z7: 17 | AA7: 10d6 | AB7: 4d6 | AG7: 22 | AI7: 17 | AK7: =INVOCAÇÃO!$AJ$30 | AM7: marcos | AN7: D11 | AP7: 8
H8: Miúdo | I8: Interpor | T8: Vigia | U8: 5 | W8: Cavar | X8: 4 | Z8: 21 | AA8: 13d6 | AB8: 5d6 | AG8: 26 | AI8: 21 | AM8: classe | AN8: O11
H9: Voo | I9: Chamariz | T9: Miúdo | U9: 7 | W9: Interpor | X9: 8 | Z9: 26 | AA9: 15d6 | AB9: 6d6 | AG9: 30 | AI9: 26 | AM9: nome | AN9: D19
H10: Montaria | T10: Voo | U10: 8 | W10: Chamariz | X10: 8 | AM10: tipo | AN10: Z19
H11: Fisgada | T11: Montaria | U11: 8 | AM11: trilha | AN11: AK19
H12: Emboscada | T12: Fisgada | U12: 8 | AM12: sintonia | AN12: D22
H13: Jorro | T13: Emboscada | U13: 8 | AM13: pontos_atributo | AN13: D35
H14: Graúdo | T14: Jorro | U14: 8 | AM14: pontos_disp | AN14: O35
H15: Remoto | T15: Graúdo | U15: 8 | AM15: aviso_atributo | AN15: Z35
T16: Remoto | U16: 8 | AM16: atr_acerto | AN16: D43
AM17: acerto | AN17: O43
AM18: defesa_de | AN18: Z43
AM19: defesa | AN19: AK43
AM20: critico | AN20: D46
AM21: tr_treinado | AN21: O46
AM22: fisico_de | AN22: Z46
AM23: tr_Físico | AN23: Q50
AM24: tr_extra_Físico | AN24: K50
AM25: tr_Vigor | AN25: AM50
AM26: tr_extra_Vigor | AN26: AG50
AM27: tr_Intelecto | AN27: Q51
AM28: tr_extra_Intelecto | AN28: K51
... AM96: degrau_comando_6 | AN96: AK85
